W0323 19:27:38.117962       1 server.go:158] WARNING: all flags other than --config are deprecated. Please begin using a config file ASAP.
W0323 19:27:38.118089       1 server.go:515] Neither --kubeconfig nor --master was specified. Using default API client. This might not work.
I0323 19:27:38.121824       1 server.go:554] Version: v1.10.0-alpha.3.101+6dd368367c9136-dirty
I0323 19:27:38.122166       1 server.go:573] starting healthz server on 0.0.0.0:10251
I0323 19:27:38.922954       1 controller_utils.go:1019] Waiting for caches to sync for scheduler controller
I0323 19:27:39.023120       1 controller_utils.go:1026] Caches are synced for scheduler controller
I0323 19:31:32.602906       1 factory.go:1068] [tanle] Next Pod user1-0
I0323 19:31:32.603056       1 generic_scheduler.go:510] demand 0: =  {%!s(float64=5392.731535756154) %!s(float64=3.221225472e+09) %!s(float64=0.23446658851113714)}
I0323 19:31:32.603091       1 generic_scheduler.go:510] demand 1: =  {%!s(float64=10772.833723653397) %!s(float64=3.221225472e+09) %!s(float64=0.468384074941452)}
I0323 19:31:32.603110       1 generic_scheduler.go:690] shares [%!s(*schedulercache.Resource=&{46000 27477053276 2 0 0 map[]}) %!s(*schedulercache.Resource=&{46000 13754632765 2 0 0 map[]})]
I0323 19:31:32.603140       1 generic_scheduler.go:695] Admitted pod: user1-0 podDemand &{%!s(int64=1000) %!s(int64=3221225472) %!s(int64=1) %!s(int64=0) %!s(int=0) map[]} usage &{%!s(int64=0) %!s(int64=0) %!s(int64=0) %!s(int64=0) %!s(int=0) map[]}
I0323 19:31:32.632651       1 factory.go:1068] [tanle] Next Pod user1-3
I0323 19:31:32.632753       1 generic_scheduler.go:510] demand 0: =  {%!s(float64=5392.731535756154) %!s(float64=3.221225472e+09) %!s(float64=0.23446658851113714)}
I0323 19:31:32.632781       1 generic_scheduler.go:510] demand 1: =  {%!s(float64=10772.833723653397) %!s(float64=3.221225472e+09) %!s(float64=0.468384074941452)}
I0323 19:31:32.632791       1 generic_scheduler.go:690] shares [%!s(*schedulercache.Resource=&{46000 27477053276 2 0 0 map[]}) %!s(*schedulercache.Resource=&{46000 13754632765 2 0 0 map[]})]
I0323 19:31:32.632808       1 generic_scheduler.go:695] Admitted pod: user1-3 podDemand &{%!s(int64=23000) %!s(int64=3221225472) %!s(int64=0) %!s(int64=0) %!s(int=0) map[]} usage &{%!s(int64=1000) %!s(int64=3221225472) %!s(int64=1) %!s(int64=0) %!s(int=0) map[]}
I0323 19:31:32.632942       1 factory.go:1068] [tanle] Next Pod user1-2
I0323 19:31:32.633030       1 generic_scheduler.go:510] demand 0: =  {%!s(float64=5392.731535756154) %!s(float64=3.221225472e+09) %!s(float64=0.23446658851113714)}
I0323 19:31:32.633052       1 generic_scheduler.go:510] demand 1: =  {%!s(float64=10772.833723653397) %!s(float64=3.221225472e+09) %!s(float64=0.468384074941452)}
I0323 19:31:32.633067       1 generic_scheduler.go:690] shares [%!s(*schedulercache.Resource=&{46000 27477053276 2 0 0 map[]}) %!s(*schedulercache.Resource=&{46000 13754632765 2 0 0 map[]})]
I0323 19:31:32.633085       1 generic_scheduler.go:591] demand.MilliCPU: 23000, currentUsage.MilliCPU 24000, share.MilliCPU 46000
I0323 19:31:32.633092       1 generic_scheduler.go:692] Rejected pod: user1-2 podDemand &{%!s(int64=23000) %!s(int64=3221225472) %!s(int64=0) %!s(int64=0) %!s(int=0) map[]} usage &{%!s(int64=24000) %!s(int64=6442450944) %!s(int64=1) %!s(int64=0) %!s(int=0) map[]} share[1]&{%!s(int64=46000) %!s(int64=13754632765) %!s(int64=2) %!s(int64=0) %!s(int=0) map[]}
I0323 19:31:32.674054       1 factory.go:1068] [tanle] Next Pod user1-1
I0323 19:31:32.674152       1 generic_scheduler.go:510] demand 0: =  {%!s(float64=5392.731535756154) %!s(float64=3.221225472e+09) %!s(float64=0.23446658851113714)}
I0323 19:31:32.674171       1 generic_scheduler.go:510] demand 1: =  {%!s(float64=10772.833723653397) %!s(float64=3.221225472e+09) %!s(float64=0.468384074941452)}
I0323 19:31:32.674180       1 generic_scheduler.go:690] shares [%!s(*schedulercache.Resource=&{46000 27477053276 2 0 0 map[]}) %!s(*schedulercache.Resource=&{46000 13754632765 2 0 0 map[]})]
I0323 19:31:32.674191       1 generic_scheduler.go:695] Admitted pod: user1-1 podDemand &{%!s(int64=1000) %!s(int64=3221225472) %!s(int64=1) %!s(int64=0) %!s(int=0) map[]} usage &{%!s(int64=24000) %!s(int64=6442450944) %!s(int64=1) %!s(int64=0) %!s(int=0) map[]}
I0323 19:31:32.674303       1 factory.go:1068] [tanle] Next Pod user1-2
I0323 19:31:32.674356       1 generic_scheduler.go:510] demand 0: =  {%!s(float64=5392.731535756154) %!s(float64=3.221225472e+09) %!s(float64=0.23446658851113714)}
I0323 19:31:32.674371       1 generic_scheduler.go:510] demand 1: =  {%!s(float64=10772.833723653397) %!s(float64=3.221225472e+09) %!s(float64=0.468384074941452)}
I0323 19:31:32.674379       1 generic_scheduler.go:690] shares [%!s(*schedulercache.Resource=&{46000 27477053276 2 0 0 map[]}) %!s(*schedulercache.Resource=&{46000 13754632765 2 0 0 map[]})]
I0323 19:31:32.674393       1 generic_scheduler.go:591] demand.MilliCPU: 23000, currentUsage.MilliCPU 25000, share.MilliCPU 46000
I0323 19:31:32.674397       1 generic_scheduler.go:692] Rejected pod: user1-2 podDemand &{%!s(int64=23000) %!s(int64=3221225472) %!s(int64=0) %!s(int64=0) %!s(int=0) map[]} usage &{%!s(int64=25000) %!s(int64=9663676416) %!s(int64=2) %!s(int64=0) %!s(int=0) map[]} share[1]&{%!s(int64=46000) %!s(int64=13754632765) %!s(int64=2) %!s(int64=0) %!s(int=0) map[]}
W0323 19:31:32.674457       1 factory.go:1226] Request for pod user1/user1-2 already in flight, abandoning
I0323 19:31:32.696252       1 factory.go:1068] [tanle] Next Pod user2-3
I0323 19:31:32.696335       1 generic_scheduler.go:510] demand 0: =  {%!s(float64=5392.731535756154) %!s(float64=3.221225472e+09) %!s(float64=0.23446658851113714)}
I0323 19:31:32.696356       1 generic_scheduler.go:510] demand 1: =  {%!s(float64=10772.833723653397) %!s(float64=3.221225472e+09) %!s(float64=0.468384074941452)}
I0323 19:31:32.696374       1 generic_scheduler.go:690] shares [%!s(*schedulercache.Resource=&{46000 27477053276 2 0 0 map[]}) %!s(*schedulercache.Resource=&{46000 13754632765 2 0 0 map[]})]
I0323 19:31:32.696409       1 generic_scheduler.go:695] Admitted pod: user2-3 podDemand &{%!s(int64=23000) %!s(int64=3221225472) %!s(int64=0) %!s(int64=0) %!s(int=0) map[]} usage &{%!s(int64=0) %!s(int64=0) %!s(int64=0) %!s(int64=0) %!s(int=0) map[]}
I0323 19:31:32.696561       1 factory.go:1068] [tanle] Next Pod user2-1
I0323 19:31:32.696641       1 generic_scheduler.go:510] demand 0: =  {%!s(float64=5392.731535756154) %!s(float64=3.221225472e+09) %!s(float64=0.23446658851113714)}
I0323 19:31:32.696662       1 generic_scheduler.go:510] demand 1: =  {%!s(float64=10772.833723653397) %!s(float64=3.221225472e+09) %!s(float64=0.468384074941452)}
I0323 19:31:32.696677       1 generic_scheduler.go:690] shares [%!s(*schedulercache.Resource=&{46000 27477053276 2 0 0 map[]}) %!s(*schedulercache.Resource=&{46000 13754632765 2 0 0 map[]})]
I0323 19:31:32.696695       1 generic_scheduler.go:695] Admitted pod: user2-1 podDemand &{%!s(int64=1000) %!s(int64=3221225472) %!s(int64=1) %!s(int64=0) %!s(int=0) map[]} usage &{%!s(int64=23000) %!s(int64=3221225472) %!s(int64=0) %!s(int64=0) %!s(int=0) map[]}
I0323 19:31:32.696761       1 factory.go:1068] [tanle] Next Pod user2-0
I0323 19:31:32.696861       1 generic_scheduler.go:510] demand 0: =  {%!s(float64=5392.731535756154) %!s(float64=3.221225472e+09) %!s(float64=0.23446658851113714)}
I0323 19:31:32.696904       1 generic_scheduler.go:510] demand 1: =  {%!s(float64=10772.833723653397) %!s(float64=3.221225472e+09) %!s(float64=0.468384074941452)}
I0323 19:31:32.696915       1 generic_scheduler.go:690] shares [%!s(*schedulercache.Resource=&{46000 27477053276 2 0 0 map[]}) %!s(*schedulercache.Resource=&{46000 13754632765 2 0 0 map[]})]
I0323 19:31:32.696935       1 generic_scheduler.go:695] Admitted pod: user2-0 podDemand &{%!s(int64=1000) %!s(int64=3221225472) %!s(int64=1) %!s(int64=0) %!s(int=0) map[]} usage &{%!s(int64=24000) %!s(int64=6442450944) %!s(int64=1) %!s(int64=0) %!s(int=0) map[]}
I0323 19:31:32.696997       1 factory.go:1068] [tanle] Next Pod user2-2
I0323 19:31:32.697076       1 generic_scheduler.go:510] demand 0: =  {%!s(float64=5392.731535756154) %!s(float64=3.221225472e+09) %!s(float64=0.23446658851113714)}
I0323 19:31:32.697093       1 generic_scheduler.go:510] demand 1: =  {%!s(float64=10772.833723653397) %!s(float64=3.221225472e+09) %!s(float64=0.468384074941452)}
I0323 19:31:32.697101       1 generic_scheduler.go:690] shares [%!s(*schedulercache.Resource=&{46000 27477053276 2 0 0 map[]}) %!s(*schedulercache.Resource=&{46000 13754632765 2 0 0 map[]})]
I0323 19:31:32.697112       1 generic_scheduler.go:591] demand.MilliCPU: 23000, currentUsage.MilliCPU 25000, share.MilliCPU 46000
I0323 19:31:32.697116       1 generic_scheduler.go:692] Rejected pod: user2-2 podDemand &{%!s(int64=23000) %!s(int64=3221225472) %!s(int64=0) %!s(int64=0) %!s(int=0) map[]} usage &{%!s(int64=25000) %!s(int64=9663676416) %!s(int64=2) %!s(int64=0) %!s(int=0) map[]} share[1]&{%!s(int64=46000) %!s(int64=13754632765) %!s(int64=2) %!s(int64=0) %!s(int=0) map[]}
I0323 19:31:32.722277       1 factory.go:1068] [tanle] Next Pod user2-2
I0323 19:31:32.722393       1 generic_scheduler.go:510] demand 0: =  {%!s(float64=5392.731535756154) %!s(float64=3.221225472e+09) %!s(float64=0.23446658851113714)}
I0323 19:31:32.722424       1 generic_scheduler.go:510] demand 1: =  {%!s(float64=10772.833723653397) %!s(float64=3.221225472e+09) %!s(float64=0.468384074941452)}
I0323 19:31:32.722445       1 generic_scheduler.go:690] shares [%!s(*schedulercache.Resource=&{46000 27477053276 2 0 0 map[]}) %!s(*schedulercache.Resource=&{46000 13754632765 2 0 0 map[]})]
I0323 19:31:32.722468       1 generic_scheduler.go:591] demand.MilliCPU: 23000, currentUsage.MilliCPU 25000, share.MilliCPU 46000
I0323 19:31:32.722475       1 generic_scheduler.go:692] Rejected pod: user2-2 podDemand &{%!s(int64=23000) %!s(int64=3221225472) %!s(int64=0) %!s(int64=0) %!s(int=0) map[]} usage &{%!s(int64=25000) %!s(int64=9663676416) %!s(int64=2) %!s(int64=0) %!s(int=0) map[]} share[1]&{%!s(int64=46000) %!s(int64=13754632765) %!s(int64=2) %!s(int64=0) %!s(int=0) map[]}
W0323 19:31:32.722532       1 factory.go:1226] Request for pod user2/user2-2 already in flight, abandoning
I0323 19:31:34.024287       1 factory.go:1068] [tanle] Next Pod user1-2
I0323 19:31:34.024428       1 generic_scheduler.go:510] demand 0: =  {%!s(float64=5392.731535756154) %!s(float64=3.221225472e+09) %!s(float64=0.23446658851113714)}
I0323 19:31:34.024464       1 generic_scheduler.go:510] demand 1: =  {%!s(float64=10772.833723653397) %!s(float64=3.221225472e+09) %!s(float64=0.468384074941452)}
I0323 19:31:34.024483       1 generic_scheduler.go:690] shares [%!s(*schedulercache.Resource=&{46000 27477053276 2 0 0 map[]}) %!s(*schedulercache.Resource=&{46000 13754632765 2 0 0 map[]})]
I0323 19:31:34.024506       1 generic_scheduler.go:591] demand.MilliCPU: 23000, currentUsage.MilliCPU 25000, share.MilliCPU 46000
I0323 19:31:34.024518       1 generic_scheduler.go:692] Rejected pod: user1-2 podDemand &{%!s(int64=23000) %!s(int64=3221225472) %!s(int64=0) %!s(int64=0) %!s(int=0) map[]} usage &{%!s(int64=25000) %!s(int64=9663676416) %!s(int64=2) %!s(int64=0) %!s(int=0) map[]} share[1]&{%!s(int64=46000) %!s(int64=13754632765) %!s(int64=2) %!s(int64=0) %!s(int=0) map[]}
I0323 19:31:34.038392       1 factory.go:1068] [tanle] Next Pod user2-2
I0323 19:31:34.038571       1 generic_scheduler.go:510] demand 0: =  {%!s(float64=5392.731535756154) %!s(float64=3.221225472e+09) %!s(float64=0.23446658851113714)}
I0323 19:31:34.038615       1 generic_scheduler.go:510] demand 1: =  {%!s(float64=10772.833723653397) %!s(float64=3.221225472e+09) %!s(float64=0.468384074941452)}
I0323 19:31:34.038644       1 generic_scheduler.go:690] shares [%!s(*schedulercache.Resource=&{46000 27477053276 2 0 0 map[]}) %!s(*schedulercache.Resource=&{46000 13754632765 2 0 0 map[]})]
I0323 19:31:34.038678       1 generic_scheduler.go:591] demand.MilliCPU: 23000, currentUsage.MilliCPU 25000, share.MilliCPU 46000
I0323 19:31:34.038693       1 generic_scheduler.go:692] Rejected pod: user2-2 podDemand &{%!s(int64=23000) %!s(int64=3221225472) %!s(int64=0) %!s(int64=0) %!s(int=0) map[]} usage &{%!s(int64=25000) %!s(int64=9663676416) %!s(int64=2) %!s(int64=0) %!s(int=0) map[]} share[1]&{%!s(int64=46000) %!s(int64=13754632765) %!s(int64=2) %!s(int64=0) %!s(int=0) map[]}
I0323 19:31:36.781284       1 factory.go:1068] [tanle] Next Pod user2-2
I0323 19:31:36.781527       1 generic_scheduler.go:510] demand 0: =  {%!s(float64=5392.731535756154) %!s(float64=3.221225472e+09) %!s(float64=0.23446658851113714)}
I0323 19:31:36.781570       1 generic_scheduler.go:510] demand 1: =  {%!s(float64=10772.833723653397) %!s(float64=3.221225472e+09) %!s(float64=0.468384074941452)}
I0323 19:31:36.781592       1 generic_scheduler.go:690] shares [%!s(*schedulercache.Resource=&{46000 27477053276 2 0 0 map[]}) %!s(*schedulercache.Resource=&{46000 13754632765 2 0 0 map[]})]
I0323 19:31:36.781621       1 generic_scheduler.go:591] demand.MilliCPU: 23000, currentUsage.MilliCPU 25000, share.MilliCPU 46000
I0323 19:31:36.781631       1 generic_scheduler.go:692] Rejected pod: user2-2 podDemand &{%!s(int64=23000) %!s(int64=3221225472) %!s(int64=0) %!s(int64=0) %!s(int=0) map[]} usage &{%!s(int64=25000) %!s(int64=9663676416) %!s(int64=2) %!s(int64=0) %!s(int=0) map[]} share[1]&{%!s(int64=46000) %!s(int64=13754632765) %!s(int64=2) %!s(int64=0) %!s(int=0) map[]}
I0323 19:31:36.781788       1 factory.go:1068] [tanle] Next Pod user1-2
I0323 19:31:36.781939       1 generic_scheduler.go:510] demand 0: =  {%!s(float64=5392.731535756154) %!s(float64=3.221225472e+09) %!s(float64=0.23446658851113714)}
I0323 19:31:36.781973       1 generic_scheduler.go:510] demand 1: =  {%!s(float64=10772.833723653397) %!s(float64=3.221225472e+09) %!s(float64=0.468384074941452)}
I0323 19:31:36.781993       1 generic_scheduler.go:690] shares [%!s(*schedulercache.Resource=&{46000 27477053276 2 0 0 map[]}) %!s(*schedulercache.Resource=&{46000 13754632765 2 0 0 map[]})]
I0323 19:31:36.782016       1 generic_scheduler.go:591] demand.MilliCPU: 23000, currentUsage.MilliCPU 25000, share.MilliCPU 46000
I0323 19:31:36.782025       1 generic_scheduler.go:692] Rejected pod: user1-2 podDemand &{%!s(int64=23000) %!s(int64=3221225472) %!s(int64=0) %!s(int64=0) %!s(int=0) map[]} usage &{%!s(int64=25000) %!s(int64=9663676416) %!s(int64=2) %!s(int64=0) %!s(int=0) map[]} share[1]&{%!s(int64=46000) %!s(int64=13754632765) %!s(int64=2) %!s(int64=0) %!s(int=0) map[]}
I0323 19:31:41.988403       1 factory.go:1068] [tanle] Next Pod user1-2
I0323 19:31:41.988584       1 generic_scheduler.go:510] demand 0: =  {%!s(float64=5392.731535756154) %!s(float64=3.221225472e+09) %!s(float64=0.23446658851113714)}
I0323 19:31:41.988625       1 generic_scheduler.go:510] demand 1: =  {%!s(float64=10772.833723653397) %!s(float64=3.221225472e+09) %!s(float64=0.468384074941452)}
I0323 19:31:41.988643       1 generic_scheduler.go:690] shares [%!s(*schedulercache.Resource=&{46000 27477053276 2 0 0 map[]}) %!s(*schedulercache.Resource=&{46000 13754632765 2 0 0 map[]})]
I0323 19:31:41.988669       1 generic_scheduler.go:591] demand.MilliCPU: 23000, currentUsage.MilliCPU 25000, share.MilliCPU 46000
I0323 19:31:41.988679       1 generic_scheduler.go:692] Rejected pod: user1-2 podDemand &{%!s(int64=23000) %!s(int64=3221225472) %!s(int64=0) %!s(int64=0) %!s(int=0) map[]} usage &{%!s(int64=25000) %!s(int64=9663676416) %!s(int64=2) %!s(int64=0) %!s(int=0) map[]} share[1]&{%!s(int64=46000) %!s(int64=13754632765) %!s(int64=2) %!s(int64=0) %!s(int=0) map[]}
I0323 19:31:41.988823       1 factory.go:1068] [tanle] Next Pod user2-2
I0323 19:31:41.988978       1 generic_scheduler.go:510] demand 0: =  {%!s(float64=5392.731535756154) %!s(float64=3.221225472e+09) %!s(float64=0.23446658851113714)}
I0323 19:31:41.989025       1 generic_scheduler.go:510] demand 1: =  {%!s(float64=10772.833723653397) %!s(float64=3.221225472e+09) %!s(float64=0.468384074941452)}
I0323 19:31:41.989057       1 generic_scheduler.go:690] shares [%!s(*schedulercache.Resource=&{46000 27477053276 2 0 0 map[]}) %!s(*schedulercache.Resource=&{46000 13754632765 2 0 0 map[]})]
I0323 19:31:41.989093       1 generic_scheduler.go:591] demand.MilliCPU: 23000, currentUsage.MilliCPU 25000, share.MilliCPU 46000
I0323 19:31:41.989108       1 generic_scheduler.go:692] Rejected pod: user2-2 podDemand &{%!s(int64=23000) %!s(int64=3221225472) %!s(int64=0) %!s(int64=0) %!s(int=0) map[]} usage &{%!s(int64=25000) %!s(int64=9663676416) %!s(int64=2) %!s(int64=0) %!s(int=0) map[]} share[1]&{%!s(int64=46000) %!s(int64=13754632765) %!s(int64=2) %!s(int64=0) %!s(int=0) map[]}
I0323 19:31:50.238910       1 factory.go:1068] [tanle] Next Pod user2-2
I0323 19:31:50.239074       1 generic_scheduler.go:510] demand 0: =  {%!s(float64=5392.731535756154) %!s(float64=3.221225472e+09) %!s(float64=0.23446658851113714)}
I0323 19:31:50.239116       1 generic_scheduler.go:510] demand 1: =  {%!s(float64=10772.833723653397) %!s(float64=3.221225472e+09) %!s(float64=0.468384074941452)}
I0323 19:31:50.239140       1 generic_scheduler.go:690] shares [%!s(*schedulercache.Resource=&{46000 27477053276 2 0 0 map[]}) %!s(*schedulercache.Resource=&{46000 13754632765 2 0 0 map[]})]
I0323 19:31:50.239163       1 generic_scheduler.go:591] demand.MilliCPU: 23000, currentUsage.MilliCPU 25000, share.MilliCPU 46000
I0323 19:31:50.239172       1 generic_scheduler.go:692] Rejected pod: user2-2 podDemand &{%!s(int64=23000) %!s(int64=3221225472) %!s(int64=0) %!s(int64=0) %!s(int=0) map[]} usage &{%!s(int64=25000) %!s(int64=9663676416) %!s(int64=2) %!s(int64=0) %!s(int=0) map[]} share[1]&{%!s(int64=46000) %!s(int64=13754632765) %!s(int64=2) %!s(int64=0) %!s(int=0) map[]}
I0323 19:31:50.239307       1 factory.go:1068] [tanle] Next Pod user1-2
I0323 19:31:50.239469       1 generic_scheduler.go:510] demand 0: =  {%!s(float64=5392.731535756154) %!s(float64=3.221225472e+09) %!s(float64=0.23446658851113714)}
I0323 19:31:50.239503       1 generic_scheduler.go:510] demand 1: =  {%!s(float64=10772.833723653397) %!s(float64=3.221225472e+09) %!s(float64=0.468384074941452)}
I0323 19:31:50.239523       1 generic_scheduler.go:690] shares [%!s(*schedulercache.Resource=&{46000 27477053276 2 0 0 map[]}) %!s(*schedulercache.Resource=&{46000 13754632765 2 0 0 map[]})]
I0323 19:31:50.239545       1 generic_scheduler.go:591] demand.MilliCPU: 23000, currentUsage.MilliCPU 25000, share.MilliCPU 46000
I0323 19:31:50.239558       1 generic_scheduler.go:692] Rejected pod: user1-2 podDemand &{%!s(int64=23000) %!s(int64=3221225472) %!s(int64=0) %!s(int64=0) %!s(int=0) map[]} usage &{%!s(int64=25000) %!s(int64=9663676416) %!s(int64=2) %!s(int64=0) %!s(int=0) map[]} share[1]&{%!s(int64=46000) %!s(int64=13754632765) %!s(int64=2) %!s(int64=0) %!s(int=0) map[]}
I0323 19:32:06.242841       1 factory.go:1068] [tanle] Next Pod user1-2
I0323 19:32:06.243085       1 generic_scheduler.go:510] demand 0: =  {%!s(float64=5392.731535756154) %!s(float64=3.221225472e+09) %!s(float64=0.23446658851113714)}
I0323 19:32:06.243169       1 generic_scheduler.go:510] demand 1: =  {%!s(float64=10772.833723653397) %!s(float64=3.221225472e+09) %!s(float64=0.468384074941452)}
I0323 19:32:06.243210       1 generic_scheduler.go:690] shares [%!s(*schedulercache.Resource=&{46000 27477053276 2 0 0 map[]}) %!s(*schedulercache.Resource=&{46000 13754632765 2 0 0 map[]})]
I0323 19:32:06.243266       1 generic_scheduler.go:591] demand.MilliCPU: 23000, currentUsage.MilliCPU 25000, share.MilliCPU 46000
I0323 19:32:06.243292       1 generic_scheduler.go:692] Rejected pod: user1-2 podDemand &{%!s(int64=23000) %!s(int64=3221225472) %!s(int64=0) %!s(int64=0) %!s(int=0) map[]} usage &{%!s(int64=25000) %!s(int64=9663676416) %!s(int64=2) %!s(int64=0) %!s(int=0) map[]} share[1]&{%!s(int64=46000) %!s(int64=13754632765) %!s(int64=2) %!s(int64=0) %!s(int=0) map[]}
I0323 19:32:06.243418       1 factory.go:1068] [tanle] Next Pod user2-2
I0323 19:32:06.243574       1 generic_scheduler.go:510] demand 0: =  {%!s(float64=5392.731535756154) %!s(float64=3.221225472e+09) %!s(float64=0.23446658851113714)}
I0323 19:32:06.243593       1 generic_scheduler.go:510] demand 1: =  {%!s(float64=10772.833723653397) %!s(float64=3.221225472e+09) %!s(float64=0.468384074941452)}
I0323 19:32:06.243603       1 generic_scheduler.go:690] shares [%!s(*schedulercache.Resource=&{46000 27477053276 2 0 0 map[]}) %!s(*schedulercache.Resource=&{46000 13754632765 2 0 0 map[]})]
I0323 19:32:06.243622       1 generic_scheduler.go:591] demand.MilliCPU: 23000, currentUsage.MilliCPU 25000, share.MilliCPU 46000
I0323 19:32:06.243635       1 generic_scheduler.go:692] Rejected pod: user2-2 podDemand &{%!s(int64=23000) %!s(int64=3221225472) %!s(int64=0) %!s(int64=0) %!s(int=0) map[]} usage &{%!s(int64=25000) %!s(int64=9663676416) %!s(int64=2) %!s(int64=0) %!s(int=0) map[]} share[1]&{%!s(int64=46000) %!s(int64=13754632765) %!s(int64=2) %!s(int64=0) %!s(int=0) map[]}
I0323 19:32:38.246907       1 factory.go:1068] [tanle] Next Pod user2-2
I0323 19:32:38.247086       1 generic_scheduler.go:510] demand 0: =  {%!s(float64=5392.731535756154) %!s(float64=3.221225472e+09) %!s(float64=0.23446658851113714)}
I0323 19:32:38.247131       1 generic_scheduler.go:510] demand 1: =  {%!s(float64=10772.833723653397) %!s(float64=3.221225472e+09) %!s(float64=0.468384074941452)}
I0323 19:32:38.247148       1 generic_scheduler.go:690] shares [%!s(*schedulercache.Resource=&{46000 27477053276 2 0 0 map[]}) %!s(*schedulercache.Resource=&{46000 13754632765 2 0 0 map[]})]
I0323 19:32:38.247181       1 generic_scheduler.go:591] demand.MilliCPU: 23000, currentUsage.MilliCPU 25000, share.MilliCPU 46000
I0323 19:32:38.247191       1 generic_scheduler.go:692] Rejected pod: user2-2 podDemand &{%!s(int64=23000) %!s(int64=3221225472) %!s(int64=0) %!s(int64=0) %!s(int=0) map[]} usage &{%!s(int64=25000) %!s(int64=9663676416) %!s(int64=2) %!s(int64=0) %!s(int=0) map[]} share[1]&{%!s(int64=46000) %!s(int64=13754632765) %!s(int64=2) %!s(int64=0) %!s(int=0) map[]}
I0323 19:32:38.247354       1 factory.go:1068] [tanle] Next Pod user1-2
I0323 19:32:38.247469       1 generic_scheduler.go:510] demand 0: =  {%!s(float64=5392.731535756154) %!s(float64=3.221225472e+09) %!s(float64=0.23446658851113714)}
I0323 19:32:38.247493       1 generic_scheduler.go:510] demand 1: =  {%!s(float64=10772.833723653397) %!s(float64=3.221225472e+09) %!s(float64=0.468384074941452)}
I0323 19:32:38.247502       1 generic_scheduler.go:690] shares [%!s(*schedulercache.Resource=&{46000 27477053276 2 0 0 map[]}) %!s(*schedulercache.Resource=&{46000 13754632765 2 0 0 map[]})]
I0323 19:32:38.247522       1 generic_scheduler.go:591] demand.MilliCPU: 23000, currentUsage.MilliCPU 25000, share.MilliCPU 46000
I0323 19:32:38.247526       1 generic_scheduler.go:692] Rejected pod: user1-2 podDemand &{%!s(int64=23000) %!s(int64=3221225472) %!s(int64=0) %!s(int64=0) %!s(int=0) map[]} usage &{%!s(int64=25000) %!s(int64=9663676416) %!s(int64=2) %!s(int64=0) %!s(int=0) map[]} share[1]&{%!s(int64=46000) %!s(int64=13754632765) %!s(int64=2) %!s(int64=0) %!s(int=0) map[]}
I0323 19:32:59.437096       1 factory.go:1068] [tanle] Next Pod user1-2
I0323 19:32:59.873569       1 factory.go:1068] [tanle] Next Pod user2-2
W0323 19:33:39.493845       1 factory.go:1246] A pod user2/user2-2 no longer exists
W0323 19:33:39.516990       1 factory.go:1246] A pod user1/user1-2 no longer exists
I0323 19:34:00.984165       1 factory.go:1068] [tanle] Next Pod user2-0
I0323 19:34:00.984326       1 generic_scheduler.go:510] demand 0: =  {%!s(float64=5392.731535756154) %!s(float64=3.221225472e+09) %!s(float64=0.23446658851113714)}
I0323 19:34:00.984373       1 generic_scheduler.go:510] demand 1: =  {%!s(float64=10772.833723653397) %!s(float64=3.221225472e+09) %!s(float64=0.468384074941452)}
I0323 19:34:00.984393       1 generic_scheduler.go:690] shares [%!s(*schedulercache.Resource=&{46000 27477053276 2 0 0 map[]}) %!s(*schedulercache.Resource=&{46000 13754632765 2 0 0 map[]})]
I0323 19:34:00.984418       1 generic_scheduler.go:695] Admitted pod: user2-0 podDemand &{%!s(int64=1000) %!s(int64=3221225472) %!s(int64=1) %!s(int64=0) %!s(int=0) map[]} usage &{%!s(int64=0) %!s(int64=0) %!s(int64=0) %!s(int64=0) %!s(int=0) map[]}
I0323 19:34:01.007726       1 factory.go:1068] [tanle] Next Pod user2-2
I0323 19:34:01.007825       1 generic_scheduler.go:510] demand 0: =  {%!s(float64=5392.731535756154) %!s(float64=3.221225472e+09) %!s(float64=0.23446658851113714)}
I0323 19:34:01.007851       1 generic_scheduler.go:510] demand 1: =  {%!s(float64=10772.833723653397) %!s(float64=3.221225472e+09) %!s(float64=0.468384074941452)}
I0323 19:34:01.007861       1 generic_scheduler.go:690] shares [%!s(*schedulercache.Resource=&{46000 27477053276 2 0 0 map[]}) %!s(*schedulercache.Resource=&{46000 13754632765 2 0 0 map[]})]
I0323 19:34:01.007876       1 generic_scheduler.go:695] Admitted pod: user2-2 podDemand &{%!s(int64=23000) %!s(int64=3221225472) %!s(int64=0) %!s(int64=0) %!s(int=0) map[]} usage &{%!s(int64=1000) %!s(int64=3221225472) %!s(int64=1) %!s(int64=0) %!s(int=0) map[]}
I0323 19:34:01.007995       1 factory.go:1068] [tanle] Next Pod user2-3
I0323 19:34:01.008064       1 generic_scheduler.go:510] demand 0: =  {%!s(float64=5392.731535756154) %!s(float64=3.221225472e+09) %!s(float64=0.23446658851113714)}
I0323 19:34:01.008087       1 generic_scheduler.go:510] demand 1: =  {%!s(float64=10772.833723653397) %!s(float64=3.221225472e+09) %!s(float64=0.468384074941452)}
I0323 19:34:01.008097       1 generic_scheduler.go:690] shares [%!s(*schedulercache.Resource=&{46000 27477053276 2 0 0 map[]}) %!s(*schedulercache.Resource=&{46000 13754632765 2 0 0 map[]})]
I0323 19:34:01.008110       1 generic_scheduler.go:591] demand.MilliCPU: 23000, currentUsage.MilliCPU 24000, share.MilliCPU 46000
I0323 19:34:01.008115       1 generic_scheduler.go:692] Rejected pod: user2-3 podDemand &{%!s(int64=23000) %!s(int64=3221225472) %!s(int64=0) %!s(int64=0) %!s(int=0) map[]} usage &{%!s(int64=24000) %!s(int64=6442450944) %!s(int64=1) %!s(int64=0) %!s(int=0) map[]} share[1]&{%!s(int64=46000) %!s(int64=13754632765) %!s(int64=2) %!s(int64=0) %!s(int=0) map[]}
I0323 19:34:01.040686       1 factory.go:1068] [tanle] Next Pod user2-1
I0323 19:34:01.040792       1 generic_scheduler.go:510] demand 0: =  {%!s(float64=5392.731535756154) %!s(float64=3.221225472e+09) %!s(float64=0.23446658851113714)}
I0323 19:34:01.040814       1 generic_scheduler.go:510] demand 1: =  {%!s(float64=10772.833723653397) %!s(float64=3.221225472e+09) %!s(float64=0.468384074941452)}
I0323 19:34:01.040823       1 generic_scheduler.go:690] shares [%!s(*schedulercache.Resource=&{46000 27477053276 2 0 0 map[]}) %!s(*schedulercache.Resource=&{46000 13754632765 2 0 0 map[]})]
I0323 19:34:01.040852       1 generic_scheduler.go:695] Admitted pod: user2-1 podDemand &{%!s(int64=1000) %!s(int64=3221225472) %!s(int64=1) %!s(int64=0) %!s(int=0) map[]} usage &{%!s(int64=24000) %!s(int64=6442450944) %!s(int64=1) %!s(int64=0) %!s(int=0) map[]}
I0323 19:34:01.040961       1 factory.go:1068] [tanle] Next Pod user2-3
I0323 19:34:01.041028       1 generic_scheduler.go:510] demand 0: =  {%!s(float64=5392.731535756154) %!s(float64=3.221225472e+09) %!s(float64=0.23446658851113714)}
I0323 19:34:01.041046       1 generic_scheduler.go:510] demand 1: =  {%!s(float64=10772.833723653397) %!s(float64=3.221225472e+09) %!s(float64=0.468384074941452)}
I0323 19:34:01.041055       1 generic_scheduler.go:690] shares [%!s(*schedulercache.Resource=&{46000 27477053276 2 0 0 map[]}) %!s(*schedulercache.Resource=&{46000 13754632765 2 0 0 map[]})]
I0323 19:34:01.041068       1 generic_scheduler.go:591] demand.MilliCPU: 23000, currentUsage.MilliCPU 25000, share.MilliCPU 46000
I0323 19:34:01.041072       1 generic_scheduler.go:692] Rejected pod: user2-3 podDemand &{%!s(int64=23000) %!s(int64=3221225472) %!s(int64=0) %!s(int64=0) %!s(int=0) map[]} usage &{%!s(int64=25000) %!s(int64=9663676416) %!s(int64=2) %!s(int64=0) %!s(int=0) map[]} share[1]&{%!s(int64=46000) %!s(int64=13754632765) %!s(int64=2) %!s(int64=0) %!s(int=0) map[]}
W0323 19:34:01.041138       1 factory.go:1226] Request for pod user2/user2-3 already in flight, abandoning
I0323 19:34:01.239049       1 factory.go:1068] [tanle] Next Pod user1-1
I0323 19:34:01.239256       1 generic_scheduler.go:510] demand 0: =  {%!s(float64=5392.731535756154) %!s(float64=3.221225472e+09) %!s(float64=0.23446658851113714)}
I0323 19:34:01.239295       1 generic_scheduler.go:510] demand 1: =  {%!s(float64=10772.833723653397) %!s(float64=3.221225472e+09) %!s(float64=0.468384074941452)}
I0323 19:34:01.239315       1 generic_scheduler.go:690] shares [%!s(*schedulercache.Resource=&{46000 27477053276 2 0 0 map[]}) %!s(*schedulercache.Resource=&{46000 13754632765 2 0 0 map[]})]
I0323 19:34:01.239348       1 generic_scheduler.go:695] Admitted pod: user1-1 podDemand &{%!s(int64=1000) %!s(int64=3221225472) %!s(int64=1) %!s(int64=0) %!s(int=0) map[]} usage &{%!s(int64=0) %!s(int64=0) %!s(int64=0) %!s(int64=0) %!s(int=0) map[]}
I0323 19:34:01.239463       1 factory.go:1068] [tanle] Next Pod user1-2
I0323 19:34:01.239636       1 generic_scheduler.go:510] demand 0: =  {%!s(float64=5392.731535756154) %!s(float64=3.221225472e+09) %!s(float64=0.23446658851113714)}
I0323 19:34:01.239686       1 generic_scheduler.go:510] demand 1: =  {%!s(float64=10772.833723653397) %!s(float64=3.221225472e+09) %!s(float64=0.468384074941452)}
I0323 19:34:01.239723       1 generic_scheduler.go:690] shares [%!s(*schedulercache.Resource=&{46000 27477053276 2 0 0 map[]}) %!s(*schedulercache.Resource=&{46000 13754632765 2 0 0 map[]})]
I0323 19:34:01.239763       1 generic_scheduler.go:695] Admitted pod: user1-2 podDemand &{%!s(int64=23000) %!s(int64=3221225472) %!s(int64=0) %!s(int64=0) %!s(int=0) map[]} usage &{%!s(int64=1000) %!s(int64=3221225472) %!s(int64=1) %!s(int64=0) %!s(int=0) map[]}
I0323 19:34:01.239987       1 factory.go:1068] [tanle] Next Pod user1-0
I0323 19:34:01.240135       1 generic_scheduler.go:510] demand 0: =  {%!s(float64=5392.731535756154) %!s(float64=3.221225472e+09) %!s(float64=0.23446658851113714)}
I0323 19:34:01.240170       1 generic_scheduler.go:510] demand 1: =  {%!s(float64=10772.833723653397) %!s(float64=3.221225472e+09) %!s(float64=0.468384074941452)}
I0323 19:34:01.240201       1 generic_scheduler.go:690] shares [%!s(*schedulercache.Resource=&{46000 27477053276 2 0 0 map[]}) %!s(*schedulercache.Resource=&{46000 13754632765 2 0 0 map[]})]
I0323 19:34:01.240234       1 generic_scheduler.go:695] Admitted pod: user1-0 podDemand &{%!s(int64=1000) %!s(int64=3221225472) %!s(int64=1) %!s(int64=0) %!s(int=0) map[]} usage &{%!s(int64=24000) %!s(int64=6442450944) %!s(int64=1) %!s(int64=0) %!s(int=0) map[]}
I0323 19:34:01.240336       1 factory.go:1068] [tanle] Next Pod user1-3
I0323 19:34:01.240466       1 generic_scheduler.go:510] demand 0: =  {%!s(float64=5392.731535756154) %!s(float64=3.221225472e+09) %!s(float64=0.23446658851113714)}
I0323 19:34:01.240494       1 generic_scheduler.go:510] demand 1: =  {%!s(float64=10772.833723653397) %!s(float64=3.221225472e+09) %!s(float64=0.468384074941452)}
I0323 19:34:01.240511       1 generic_scheduler.go:690] shares [%!s(*schedulercache.Resource=&{46000 27477053276 2 0 0 map[]}) %!s(*schedulercache.Resource=&{46000 13754632765 2 0 0 map[]})]
I0323 19:34:01.240531       1 generic_scheduler.go:591] demand.MilliCPU: 23000, currentUsage.MilliCPU 25000, share.MilliCPU 46000
I0323 19:34:01.240541       1 generic_scheduler.go:692] Rejected pod: user1-3 podDemand &{%!s(int64=23000) %!s(int64=3221225472) %!s(int64=0) %!s(int64=0) %!s(int=0) map[]} usage &{%!s(int64=25000) %!s(int64=9663676416) %!s(int64=2) %!s(int64=0) %!s(int=0) map[]} share[1]&{%!s(int64=46000) %!s(int64=13754632765) %!s(int64=2) %!s(int64=0) %!s(int=0) map[]}
I0323 19:34:01.750950       1 factory.go:1068] [tanle] Next Pod user1-3
I0323 19:34:01.751136       1 generic_scheduler.go:510] demand 0: =  {%!s(float64=5392.731535756154) %!s(float64=3.221225472e+09) %!s(float64=0.23446658851113714)}
I0323 19:34:01.751180       1 generic_scheduler.go:510] demand 1: =  {%!s(float64=10772.833723653397) %!s(float64=3.221225472e+09) %!s(float64=0.468384074941452)}
I0323 19:34:01.751198       1 generic_scheduler.go:690] shares [%!s(*schedulercache.Resource=&{46000 27477053276 2 0 0 map[]}) %!s(*schedulercache.Resource=&{46000 13754632765 2 0 0 map[]})]
I0323 19:34:01.751223       1 generic_scheduler.go:591] demand.MilliCPU: 23000, currentUsage.MilliCPU 25000, share.MilliCPU 46000
I0323 19:34:01.751233       1 generic_scheduler.go:692] Rejected pod: user1-3 podDemand &{%!s(int64=23000) %!s(int64=3221225472) %!s(int64=0) %!s(int64=0) %!s(int=0) map[]} usage &{%!s(int64=25000) %!s(int64=9663676416) %!s(int64=2) %!s(int64=0) %!s(int=0) map[]} share[1]&{%!s(int64=46000) %!s(int64=13754632765) %!s(int64=2) %!s(int64=0) %!s(int=0) map[]}
W0323 19:34:01.751356       1 factory.go:1226] Request for pod user1/user1-3 already in flight, abandoning
I0323 19:34:02.033688       1 factory.go:1068] [tanle] Next Pod user2-3
I0323 19:34:02.033865       1 generic_scheduler.go:510] demand 0: =  {%!s(float64=5392.731535756154) %!s(float64=3.221225472e+09) %!s(float64=0.23446658851113714)}
I0323 19:34:02.033913       1 generic_scheduler.go:510] demand 1: =  {%!s(float64=10772.833723653397) %!s(float64=3.221225472e+09) %!s(float64=0.468384074941452)}
I0323 19:34:02.033943       1 generic_scheduler.go:690] shares [%!s(*schedulercache.Resource=&{46000 27477053276 2 0 0 map[]}) %!s(*schedulercache.Resource=&{46000 13754632765 2 0 0 map[]})]
I0323 19:34:02.033986       1 generic_scheduler.go:591] demand.MilliCPU: 23000, currentUsage.MilliCPU 25000, share.MilliCPU 46000
I0323 19:34:02.034001       1 generic_scheduler.go:692] Rejected pod: user2-3 podDemand &{%!s(int64=23000) %!s(int64=3221225472) %!s(int64=0) %!s(int64=0) %!s(int=0) map[]} usage &{%!s(int64=25000) %!s(int64=9663676416) %!s(int64=2) %!s(int64=0) %!s(int=0) map[]} share[1]&{%!s(int64=46000) %!s(int64=13754632765) %!s(int64=2) %!s(int64=0) %!s(int=0) map[]}
I0323 19:34:02.495808       1 factory.go:1068] [tanle] Next Pod user1-3
I0323 19:34:02.496030       1 generic_scheduler.go:510] demand 0: =  {%!s(float64=5392.731535756154) %!s(float64=3.221225472e+09) %!s(float64=0.23446658851113714)}
I0323 19:34:02.496091       1 generic_scheduler.go:510] demand 1: =  {%!s(float64=10772.833723653397) %!s(float64=3.221225472e+09) %!s(float64=0.468384074941452)}
I0323 19:34:02.496154       1 generic_scheduler.go:690] shares [%!s(*schedulercache.Resource=&{46000 27477053276 2 0 0 map[]}) %!s(*schedulercache.Resource=&{46000 13754632765 2 0 0 map[]})]
I0323 19:34:02.496196       1 generic_scheduler.go:591] demand.MilliCPU: 23000, currentUsage.MilliCPU 25000, share.MilliCPU 46000
I0323 19:34:02.496233       1 generic_scheduler.go:692] Rejected pod: user1-3 podDemand &{%!s(int64=23000) %!s(int64=3221225472) %!s(int64=0) %!s(int64=0) %!s(int=0) map[]} usage &{%!s(int64=25000) %!s(int64=9663676416) %!s(int64=2) %!s(int64=0) %!s(int=0) map[]} share[1]&{%!s(int64=46000) %!s(int64=13754632765) %!s(int64=2) %!s(int64=0) %!s(int=0) map[]}
I0323 19:34:04.515347       1 factory.go:1068] [tanle] Next Pod user2-3
I0323 19:34:04.515543       1 generic_scheduler.go:510] demand 0: =  {%!s(float64=5392.731535756154) %!s(float64=3.221225472e+09) %!s(float64=0.23446658851113714)}
I0323 19:34:04.515581       1 generic_scheduler.go:510] demand 1: =  {%!s(float64=10772.833723653397) %!s(float64=3.221225472e+09) %!s(float64=0.468384074941452)}
I0323 19:34:04.515599       1 generic_scheduler.go:690] shares [%!s(*schedulercache.Resource=&{46000 27477053276 2 0 0 map[]}) %!s(*schedulercache.Resource=&{46000 13754632765 2 0 0 map[]})]
I0323 19:34:04.515629       1 generic_scheduler.go:591] demand.MilliCPU: 23000, currentUsage.MilliCPU 25000, share.MilliCPU 46000
I0323 19:34:04.515638       1 generic_scheduler.go:692] Rejected pod: user2-3 podDemand &{%!s(int64=23000) %!s(int64=3221225472) %!s(int64=0) %!s(int64=0) %!s(int=0) map[]} usage &{%!s(int64=25000) %!s(int64=9663676416) %!s(int64=2) %!s(int64=0) %!s(int=0) map[]} share[1]&{%!s(int64=46000) %!s(int64=13754632765) %!s(int64=2) %!s(int64=0) %!s(int=0) map[]}
I0323 19:34:04.796092       1 factory.go:1068] [tanle] Next Pod user1-3
I0323 19:34:04.796280       1 generic_scheduler.go:510] demand 0: =  {%!s(float64=5392.731535756154) %!s(float64=3.221225472e+09) %!s(float64=0.23446658851113714)}
I0323 19:34:04.796317       1 generic_scheduler.go:510] demand 1: =  {%!s(float64=10772.833723653397) %!s(float64=3.221225472e+09) %!s(float64=0.468384074941452)}
I0323 19:34:04.796335       1 generic_scheduler.go:690] shares [%!s(*schedulercache.Resource=&{46000 27477053276 2 0 0 map[]}) %!s(*schedulercache.Resource=&{46000 13754632765 2 0 0 map[]})]
I0323 19:34:04.796361       1 generic_scheduler.go:591] demand.MilliCPU: 23000, currentUsage.MilliCPU 25000, share.MilliCPU 46000
I0323 19:34:04.796375       1 generic_scheduler.go:692] Rejected pod: user1-3 podDemand &{%!s(int64=23000) %!s(int64=3221225472) %!s(int64=0) %!s(int64=0) %!s(int=0) map[]} usage &{%!s(int64=25000) %!s(int64=9663676416) %!s(int64=2) %!s(int64=0) %!s(int=0) map[]} share[1]&{%!s(int64=46000) %!s(int64=13754632765) %!s(int64=2) %!s(int64=0) %!s(int=0) map[]}
I0323 19:34:09.489678       1 factory.go:1068] [tanle] Next Pod user2-3
I0323 19:34:09.489892       1 generic_scheduler.go:510] demand 0: =  {%!s(float64=5392.731535756154) %!s(float64=3.221225472e+09) %!s(float64=0.23446658851113714)}
I0323 19:34:09.489942       1 generic_scheduler.go:510] demand 1: =  {%!s(float64=10772.833723653397) %!s(float64=3.221225472e+09) %!s(float64=0.468384074941452)}
I0323 19:34:09.489971       1 generic_scheduler.go:690] shares [%!s(*schedulercache.Resource=&{46000 27477053276 2 0 0 map[]}) %!s(*schedulercache.Resource=&{46000 13754632765 2 0 0 map[]})]
I0323 19:34:09.490006       1 generic_scheduler.go:591] demand.MilliCPU: 23000, currentUsage.MilliCPU 25000, share.MilliCPU 46000
I0323 19:34:09.490024       1 generic_scheduler.go:692] Rejected pod: user2-3 podDemand &{%!s(int64=23000) %!s(int64=3221225472) %!s(int64=0) %!s(int64=0) %!s(int=0) map[]} usage &{%!s(int64=25000) %!s(int64=9663676416) %!s(int64=2) %!s(int64=0) %!s(int=0) map[]} share[1]&{%!s(int64=46000) %!s(int64=13754632765) %!s(int64=2) %!s(int64=0) %!s(int=0) map[]}
I0323 19:34:10.805284       1 factory.go:1068] [tanle] Next Pod user1-3
I0323 19:34:10.805443       1 generic_scheduler.go:510] demand 0: =  {%!s(float64=5392.731535756154) %!s(float64=3.221225472e+09) %!s(float64=0.23446658851113714)}
I0323 19:34:10.805480       1 generic_scheduler.go:510] demand 1: =  {%!s(float64=10772.833723653397) %!s(float64=3.221225472e+09) %!s(float64=0.468384074941452)}
I0323 19:34:10.805497       1 generic_scheduler.go:690] shares [%!s(*schedulercache.Resource=&{46000 27477053276 2 0 0 map[]}) %!s(*schedulercache.Resource=&{46000 13754632765 2 0 0 map[]})]
I0323 19:34:10.805521       1 generic_scheduler.go:591] demand.MilliCPU: 23000, currentUsage.MilliCPU 25000, share.MilliCPU 46000
I0323 19:34:10.805532       1 generic_scheduler.go:692] Rejected pod: user1-3 podDemand &{%!s(int64=23000) %!s(int64=3221225472) %!s(int64=0) %!s(int64=0) %!s(int=0) map[]} usage &{%!s(int64=25000) %!s(int64=9663676416) %!s(int64=2) %!s(int64=0) %!s(int=0) map[]} share[1]&{%!s(int64=46000) %!s(int64=13754632765) %!s(int64=2) %!s(int64=0) %!s(int=0) map[]}
I0323 19:34:17.766081       1 factory.go:1068] [tanle] Next Pod user2-3
I0323 19:34:17.766254       1 generic_scheduler.go:510] demand 0: =  {%!s(float64=5392.731535756154) %!s(float64=3.221225472e+09) %!s(float64=0.23446658851113714)}
I0323 19:34:17.766296       1 generic_scheduler.go:510] demand 1: =  {%!s(float64=10772.833723653397) %!s(float64=3.221225472e+09) %!s(float64=0.468384074941452)}
I0323 19:34:17.766330       1 generic_scheduler.go:690] shares [%!s(*schedulercache.Resource=&{46000 27477053276 2 0 0 map[]}) %!s(*schedulercache.Resource=&{46000 13754632765 2 0 0 map[]})]
I0323 19:34:17.766360       1 generic_scheduler.go:591] demand.MilliCPU: 23000, currentUsage.MilliCPU 25000, share.MilliCPU 46000
I0323 19:34:17.766376       1 generic_scheduler.go:692] Rejected pod: user2-3 podDemand &{%!s(int64=23000) %!s(int64=3221225472) %!s(int64=0) %!s(int64=0) %!s(int=0) map[]} usage &{%!s(int64=25000) %!s(int64=9663676416) %!s(int64=2) %!s(int64=0) %!s(int=0) map[]} share[1]&{%!s(int64=46000) %!s(int64=13754632765) %!s(int64=2) %!s(int64=0) %!s(int=0) map[]}
I0323 19:34:19.267415       1 factory.go:1068] [tanle] Next Pod user1-3
I0323 19:34:19.267579       1 generic_scheduler.go:510] demand 0: =  {%!s(float64=5392.731535756154) %!s(float64=3.221225472e+09) %!s(float64=0.23446658851113714)}
I0323 19:34:19.267616       1 generic_scheduler.go:510] demand 1: =  {%!s(float64=10772.833723653397) %!s(float64=3.221225472e+09) %!s(float64=0.468384074941452)}
I0323 19:34:19.267633       1 generic_scheduler.go:690] shares [%!s(*schedulercache.Resource=&{46000 27477053276 2 0 0 map[]}) %!s(*schedulercache.Resource=&{46000 13754632765 2 0 0 map[]})]
I0323 19:34:19.267654       1 generic_scheduler.go:591] demand.MilliCPU: 23000, currentUsage.MilliCPU 25000, share.MilliCPU 46000
I0323 19:34:19.267663       1 generic_scheduler.go:692] Rejected pod: user1-3 podDemand &{%!s(int64=23000) %!s(int64=3221225472) %!s(int64=0) %!s(int64=0) %!s(int=0) map[]} usage &{%!s(int64=25000) %!s(int64=9663676416) %!s(int64=2) %!s(int64=0) %!s(int=0) map[]} share[1]&{%!s(int64=46000) %!s(int64=13754632765) %!s(int64=2) %!s(int64=0) %!s(int=0) map[]}
I0323 19:34:33.775488       1 factory.go:1068] [tanle] Next Pod user2-3
I0323 19:34:33.776011       1 generic_scheduler.go:510] demand 0: =  {%!s(float64=5392.731535756154) %!s(float64=3.221225472e+09) %!s(float64=0.23446658851113714)}
I0323 19:34:33.776116       1 generic_scheduler.go:510] demand 1: =  {%!s(float64=10772.833723653397) %!s(float64=3.221225472e+09) %!s(float64=0.468384074941452)}
I0323 19:34:33.776147       1 generic_scheduler.go:690] shares [%!s(*schedulercache.Resource=&{46000 27477053276 2 0 0 map[]}) %!s(*schedulercache.Resource=&{46000 13754632765 2 0 0 map[]})]
I0323 19:34:33.776190       1 generic_scheduler.go:591] demand.MilliCPU: 23000, currentUsage.MilliCPU 25000, share.MilliCPU 46000
I0323 19:34:33.776201       1 generic_scheduler.go:692] Rejected pod: user2-3 podDemand &{%!s(int64=23000) %!s(int64=3221225472) %!s(int64=0) %!s(int64=0) %!s(int=0) map[]} usage &{%!s(int64=25000) %!s(int64=9663676416) %!s(int64=2) %!s(int64=0) %!s(int=0) map[]} share[1]&{%!s(int64=46000) %!s(int64=13754632765) %!s(int64=2) %!s(int64=0) %!s(int=0) map[]}
I0323 19:34:35.270407       1 factory.go:1068] [tanle] Next Pod user1-3
I0323 19:34:35.270582       1 generic_scheduler.go:510] demand 0: =  {%!s(float64=5392.731535756154) %!s(float64=3.221225472e+09) %!s(float64=0.23446658851113714)}
I0323 19:34:35.270611       1 generic_scheduler.go:510] demand 1: =  {%!s(float64=10772.833723653397) %!s(float64=3.221225472e+09) %!s(float64=0.468384074941452)}
I0323 19:34:35.270622       1 generic_scheduler.go:690] shares [%!s(*schedulercache.Resource=&{46000 27477053276 2 0 0 map[]}) %!s(*schedulercache.Resource=&{46000 13754632765 2 0 0 map[]})]
I0323 19:34:35.270673       1 generic_scheduler.go:591] demand.MilliCPU: 23000, currentUsage.MilliCPU 25000, share.MilliCPU 46000
I0323 19:34:35.270679       1 generic_scheduler.go:692] Rejected pod: user1-3 podDemand &{%!s(int64=23000) %!s(int64=3221225472) %!s(int64=0) %!s(int64=0) %!s(int=0) map[]} usage &{%!s(int64=25000) %!s(int64=9663676416) %!s(int64=2) %!s(int64=0) %!s(int=0) map[]} share[1]&{%!s(int64=46000) %!s(int64=13754632765) %!s(int64=2) %!s(int64=0) %!s(int=0) map[]}
I0323 19:35:06.279354       1 factory.go:1068] [tanle] Next Pod user2-3
I0323 19:35:06.279586       1 generic_scheduler.go:510] demand 0: =  {%!s(float64=5392.731535756154) %!s(float64=3.221225472e+09) %!s(float64=0.23446658851113714)}
I0323 19:35:06.279675       1 generic_scheduler.go:510] demand 1: =  {%!s(float64=10772.833723653397) %!s(float64=3.221225472e+09) %!s(float64=0.468384074941452)}
I0323 19:35:06.279765       1 generic_scheduler.go:690] shares [%!s(*schedulercache.Resource=&{46000 27477053276 2 0 0 map[]}) %!s(*schedulercache.Resource=&{46000 13754632765 2 0 0 map[]})]
I0323 19:35:06.279822       1 generic_scheduler.go:591] demand.MilliCPU: 23000, currentUsage.MilliCPU 25000, share.MilliCPU 46000
I0323 19:35:06.279846       1 generic_scheduler.go:692] Rejected pod: user2-3 podDemand &{%!s(int64=23000) %!s(int64=3221225472) %!s(int64=0) %!s(int64=0) %!s(int=0) map[]} usage &{%!s(int64=25000) %!s(int64=9663676416) %!s(int64=2) %!s(int64=0) %!s(int=0) map[]} share[1]&{%!s(int64=46000) %!s(int64=13754632765) %!s(int64=2) %!s(int64=0) %!s(int=0) map[]}
I0323 19:35:07.272886       1 factory.go:1068] [tanle] Next Pod user1-3
I0323 19:35:07.273025       1 generic_scheduler.go:510] demand 0: =  {%!s(float64=5392.731535756154) %!s(float64=3.221225472e+09) %!s(float64=0.23446658851113714)}
I0323 19:35:07.273064       1 generic_scheduler.go:510] demand 1: =  {%!s(float64=10772.833723653397) %!s(float64=3.221225472e+09) %!s(float64=0.468384074941452)}
I0323 19:35:07.273083       1 generic_scheduler.go:690] shares [%!s(*schedulercache.Resource=&{46000 27477053276 2 0 0 map[]}) %!s(*schedulercache.Resource=&{46000 13754632765 2 0 0 map[]})]
I0323 19:35:07.273107       1 generic_scheduler.go:591] demand.MilliCPU: 23000, currentUsage.MilliCPU 25000, share.MilliCPU 46000
I0323 19:35:07.273117       1 generic_scheduler.go:692] Rejected pod: user1-3 podDemand &{%!s(int64=23000) %!s(int64=3221225472) %!s(int64=0) %!s(int64=0) %!s(int=0) map[]} usage &{%!s(int64=25000) %!s(int64=9663676416) %!s(int64=2) %!s(int64=0) %!s(int=0) map[]} share[1]&{%!s(int64=46000) %!s(int64=13754632765) %!s(int64=2) %!s(int64=0) %!s(int=0) map[]}
I0323 19:36:06.011153       1 factory.go:1068] [tanle] Next Pod user2-5
I0323 19:36:06.011353       1 generic_scheduler.go:510] demand 0: =  {%!s(float64=5392.731535756154) %!s(float64=3.221225472e+09) %!s(float64=0.23446658851113714)}
I0323 19:36:06.011414       1 generic_scheduler.go:510] demand 1: =  {%!s(float64=10772.833723653397) %!s(float64=3.221225472e+09) %!s(float64=0.468384074941452)}
I0323 19:36:06.011443       1 generic_scheduler.go:690] shares [%!s(*schedulercache.Resource=&{46000 27477053276 2 0 0 map[]}) %!s(*schedulercache.Resource=&{46000 13754632765 2 0 0 map[]})]
I0323 19:36:06.011487       1 generic_scheduler.go:692] Rejected pod: user2-5 podDemand &{%!s(int64=1000) %!s(int64=3221225472) %!s(int64=1) %!s(int64=0) %!s(int=0) map[]} usage &{%!s(int64=25000) %!s(int64=9663676416) %!s(int64=2) %!s(int64=0) %!s(int=0) map[]} share[1]&{%!s(int64=46000) %!s(int64=13754632765) %!s(int64=2) %!s(int64=0) %!s(int=0) map[]}
I0323 19:36:06.027504       1 factory.go:1068] [tanle] Next Pod user2-4
I0323 19:36:06.027636       1 generic_scheduler.go:510] demand 0: =  {%!s(float64=5392.731535756154) %!s(float64=3.221225472e+09) %!s(float64=0.23446658851113714)}
I0323 19:36:06.027668       1 generic_scheduler.go:510] demand 1: =  {%!s(float64=10772.833723653397) %!s(float64=3.221225472e+09) %!s(float64=0.468384074941452)}
I0323 19:36:06.027679       1 generic_scheduler.go:690] shares [%!s(*schedulercache.Resource=&{46000 27477053276 2 0 0 map[]}) %!s(*schedulercache.Resource=&{46000 13754632765 2 0 0 map[]})]
I0323 19:36:06.027696       1 generic_scheduler.go:692] Rejected pod: user2-4 podDemand &{%!s(int64=1000) %!s(int64=3221225472) %!s(int64=1) %!s(int64=0) %!s(int=0) map[]} usage &{%!s(int64=25000) %!s(int64=9663676416) %!s(int64=2) %!s(int64=0) %!s(int=0) map[]} share[1]&{%!s(int64=46000) %!s(int64=13754632765) %!s(int64=2) %!s(int64=0) %!s(int=0) map[]}
I0323 19:36:06.049697       1 factory.go:1068] [tanle] Next Pod user2-5
I0323 19:36:06.049840       1 generic_scheduler.go:510] demand 0: =  {%!s(float64=5392.731535756154) %!s(float64=3.221225472e+09) %!s(float64=0.23446658851113714)}
I0323 19:36:06.049874       1 generic_scheduler.go:510] demand 1: =  {%!s(float64=10772.833723653397) %!s(float64=3.221225472e+09) %!s(float64=0.468384074941452)}
I0323 19:36:06.049894       1 generic_scheduler.go:690] shares [%!s(*schedulercache.Resource=&{46000 27477053276 2 0 0 map[]}) %!s(*schedulercache.Resource=&{46000 13754632765 2 0 0 map[]})]
I0323 19:36:06.049922       1 generic_scheduler.go:692] Rejected pod: user2-5 podDemand &{%!s(int64=1000) %!s(int64=3221225472) %!s(int64=1) %!s(int64=0) %!s(int=0) map[]} usage &{%!s(int64=25000) %!s(int64=9663676416) %!s(int64=2) %!s(int64=0) %!s(int=0) map[]} share[1]&{%!s(int64=46000) %!s(int64=13754632765) %!s(int64=2) %!s(int64=0) %!s(int=0) map[]}
W0323 19:36:06.050026       1 factory.go:1226] Request for pod user2/user2-5 already in flight, abandoning
I0323 19:36:06.050037       1 factory.go:1068] [tanle] Next Pod user2-4
I0323 19:36:06.050141       1 generic_scheduler.go:510] demand 0: =  {%!s(float64=5392.731535756154) %!s(float64=3.221225472e+09) %!s(float64=0.23446658851113714)}
I0323 19:36:06.050159       1 generic_scheduler.go:510] demand 1: =  {%!s(float64=10772.833723653397) %!s(float64=3.221225472e+09) %!s(float64=0.468384074941452)}
I0323 19:36:06.050171       1 generic_scheduler.go:690] shares [%!s(*schedulercache.Resource=&{46000 27477053276 2 0 0 map[]}) %!s(*schedulercache.Resource=&{46000 13754632765 2 0 0 map[]})]
I0323 19:36:06.050185       1 generic_scheduler.go:692] Rejected pod: user2-4 podDemand &{%!s(int64=1000) %!s(int64=3221225472) %!s(int64=1) %!s(int64=0) %!s(int=0) map[]} usage &{%!s(int64=25000) %!s(int64=9663676416) %!s(int64=2) %!s(int64=0) %!s(int=0) map[]} share[1]&{%!s(int64=46000) %!s(int64=13754632765) %!s(int64=2) %!s(int64=0) %!s(int=0) map[]}
W0323 19:36:06.050266       1 factory.go:1226] Request for pod user2/user2-4 already in flight, abandoning
I0323 19:36:06.302705       1 factory.go:1068] [tanle] Next Pod user2-3
I0323 19:36:06.302932       1 generic_scheduler.go:510] demand 0: =  {%!s(float64=5392.731535756154) %!s(float64=3.221225472e+09) %!s(float64=0.23446658851113714)}
I0323 19:36:06.302983       1 generic_scheduler.go:510] demand 1: =  {%!s(float64=10772.833723653397) %!s(float64=3.221225472e+09) %!s(float64=0.468384074941452)}
I0323 19:36:06.303013       1 generic_scheduler.go:690] shares [%!s(*schedulercache.Resource=&{46000 27477053276 2 0 0 map[]}) %!s(*schedulercache.Resource=&{46000 13754632765 2 0 0 map[]})]
I0323 19:36:06.303054       1 generic_scheduler.go:591] demand.MilliCPU: 23000, currentUsage.MilliCPU 25000, share.MilliCPU 46000
I0323 19:36:06.303071       1 generic_scheduler.go:692] Rejected pod: user2-3 podDemand &{%!s(int64=23000) %!s(int64=3221225472) %!s(int64=0) %!s(int64=0) %!s(int=0) map[]} usage &{%!s(int64=25000) %!s(int64=9663676416) %!s(int64=2) %!s(int64=0) %!s(int=0) map[]} share[1]&{%!s(int64=46000) %!s(int64=13754632765) %!s(int64=2) %!s(int64=0) %!s(int=0) map[]}
I0323 19:36:07.014582       1 factory.go:1068] [tanle] Next Pod user2-5
I0323 19:36:07.014710       1 generic_scheduler.go:510] demand 0: =  {%!s(float64=5392.731535756154) %!s(float64=3.221225472e+09) %!s(float64=0.23446658851113714)}
I0323 19:36:07.014740       1 generic_scheduler.go:510] demand 1: =  {%!s(float64=10772.833723653397) %!s(float64=3.221225472e+09) %!s(float64=0.468384074941452)}
I0323 19:36:07.014757       1 generic_scheduler.go:690] shares [%!s(*schedulercache.Resource=&{46000 27477053276 2 0 0 map[]}) %!s(*schedulercache.Resource=&{46000 13754632765 2 0 0 map[]})]
I0323 19:36:07.014778       1 generic_scheduler.go:692] Rejected pod: user2-5 podDemand &{%!s(int64=1000) %!s(int64=3221225472) %!s(int64=1) %!s(int64=0) %!s(int=0) map[]} usage &{%!s(int64=25000) %!s(int64=9663676416) %!s(int64=2) %!s(int64=0) %!s(int=0) map[]} share[1]&{%!s(int64=46000) %!s(int64=13754632765) %!s(int64=2) %!s(int64=0) %!s(int=0) map[]}
I0323 19:36:07.033734       1 factory.go:1068] [tanle] Next Pod user2-4
I0323 19:36:07.033870       1 generic_scheduler.go:510] demand 0: =  {%!s(float64=5392.731535756154) %!s(float64=3.221225472e+09) %!s(float64=0.23446658851113714)}
I0323 19:36:07.033909       1 generic_scheduler.go:510] demand 1: =  {%!s(float64=10772.833723653397) %!s(float64=3.221225472e+09) %!s(float64=0.468384074941452)}
I0323 19:36:07.033927       1 generic_scheduler.go:690] shares [%!s(*schedulercache.Resource=&{46000 27477053276 2 0 0 map[]}) %!s(*schedulercache.Resource=&{46000 13754632765 2 0 0 map[]})]
I0323 19:36:07.033972       1 generic_scheduler.go:692] Rejected pod: user2-4 podDemand &{%!s(int64=1000) %!s(int64=3221225472) %!s(int64=1) %!s(int64=0) %!s(int=0) map[]} usage &{%!s(int64=25000) %!s(int64=9663676416) %!s(int64=2) %!s(int64=0) %!s(int=0) map[]} share[1]&{%!s(int64=46000) %!s(int64=13754632765) %!s(int64=2) %!s(int64=0) %!s(int=0) map[]}
I0323 19:36:07.275738       1 factory.go:1068] [tanle] Next Pod user1-3
I0323 19:36:07.275957       1 generic_scheduler.go:510] demand 0: =  {%!s(float64=5392.731535756154) %!s(float64=3.221225472e+09) %!s(float64=0.23446658851113714)}
I0323 19:36:07.276011       1 generic_scheduler.go:510] demand 1: =  {%!s(float64=10772.833723653397) %!s(float64=3.221225472e+09) %!s(float64=0.468384074941452)}
I0323 19:36:07.276128       1 generic_scheduler.go:690] shares [%!s(*schedulercache.Resource=&{46000 27477053276 2 0 0 map[]}) %!s(*schedulercache.Resource=&{46000 13754632765 2 0 0 map[]})]
I0323 19:36:07.276167       1 generic_scheduler.go:591] demand.MilliCPU: 23000, currentUsage.MilliCPU 25000, share.MilliCPU 46000
I0323 19:36:07.276181       1 generic_scheduler.go:692] Rejected pod: user1-3 podDemand &{%!s(int64=23000) %!s(int64=3221225472) %!s(int64=0) %!s(int64=0) %!s(int=0) map[]} usage &{%!s(int64=25000) %!s(int64=9663676416) %!s(int64=2) %!s(int64=0) %!s(int=0) map[]} share[1]&{%!s(int64=46000) %!s(int64=13754632765) %!s(int64=2) %!s(int64=0) %!s(int=0) map[]}
I0323 19:36:07.316186       1 factory.go:1068] [tanle] Next Pod user2-3
I0323 19:36:07.316299       1 generic_scheduler.go:510] demand 0: =  {%!s(float64=5392.731535756154) %!s(float64=3.221225472e+09) %!s(float64=0.23446658851113714)}
I0323 19:36:07.316328       1 generic_scheduler.go:510] demand 1: =  {%!s(float64=10772.833723653397) %!s(float64=3.221225472e+09) %!s(float64=0.468384074941452)}
I0323 19:36:07.316338       1 generic_scheduler.go:690] shares [%!s(*schedulercache.Resource=&{46000 27477053276 2 0 0 map[]}) %!s(*schedulercache.Resource=&{46000 13754632765 2 0 0 map[]})]
I0323 19:36:07.316353       1 generic_scheduler.go:591] demand.MilliCPU: 23000, currentUsage.MilliCPU 25000, share.MilliCPU 46000
I0323 19:36:07.316360       1 generic_scheduler.go:692] Rejected pod: user2-3 podDemand &{%!s(int64=23000) %!s(int64=3221225472) %!s(int64=0) %!s(int64=0) %!s(int=0) map[]} usage &{%!s(int64=25000) %!s(int64=9663676416) %!s(int64=2) %!s(int64=0) %!s(int=0) map[]} share[1]&{%!s(int64=46000) %!s(int64=13754632765) %!s(int64=2) %!s(int64=0) %!s(int=0) map[]}
I0323 19:36:08.283310       1 factory.go:1068] [tanle] Next Pod user1-3
I0323 19:36:08.283462       1 generic_scheduler.go:510] demand 0: =  {%!s(float64=5392.731535756154) %!s(float64=3.221225472e+09) %!s(float64=0.23446658851113714)}
I0323 19:36:08.283493       1 generic_scheduler.go:510] demand 1: =  {%!s(float64=10772.833723653397) %!s(float64=3.221225472e+09) %!s(float64=0.468384074941452)}
I0323 19:36:08.283507       1 generic_scheduler.go:690] shares [%!s(*schedulercache.Resource=&{46000 27477053276 2 0 0 map[]}) %!s(*schedulercache.Resource=&{46000 13754632765 2 0 0 map[]})]
I0323 19:36:08.283524       1 generic_scheduler.go:591] demand.MilliCPU: 23000, currentUsage.MilliCPU 25000, share.MilliCPU 46000
I0323 19:36:08.283531       1 generic_scheduler.go:692] Rejected pod: user1-3 podDemand &{%!s(int64=23000) %!s(int64=3221225472) %!s(int64=0) %!s(int64=0) %!s(int=0) map[]} usage &{%!s(int64=25000) %!s(int64=9663676416) %!s(int64=2) %!s(int64=0) %!s(int=0) map[]} share[1]&{%!s(int64=46000) %!s(int64=13754632765) %!s(int64=2) %!s(int64=0) %!s(int=0) map[]}
I0323 19:36:09.522771       1 factory.go:1068] [tanle] Next Pod user2-5
I0323 19:36:09.523001       1 generic_scheduler.go:510] demand 0: =  {%!s(float64=5392.731535756154) %!s(float64=3.221225472e+09) %!s(float64=0.23446658851113714)}
I0323 19:36:09.523132       1 generic_scheduler.go:510] demand 1: =  {%!s(float64=10772.833723653397) %!s(float64=3.221225472e+09) %!s(float64=0.468384074941452)}
I0323 19:36:09.523178       1 generic_scheduler.go:690] shares [%!s(*schedulercache.Resource=&{46000 27477053276 2 0 0 map[]}) %!s(*schedulercache.Resource=&{46000 13754632765 2 0 0 map[]})]
I0323 19:36:09.523278       1 generic_scheduler.go:692] Rejected pod: user2-5 podDemand &{%!s(int64=1000) %!s(int64=3221225472) %!s(int64=1) %!s(int64=0) %!s(int=0) map[]} usage &{%!s(int64=25000) %!s(int64=9663676416) %!s(int64=2) %!s(int64=0) %!s(int=0) map[]} share[1]&{%!s(int64=46000) %!s(int64=13754632765) %!s(int64=2) %!s(int64=0) %!s(int=0) map[]}
I0323 19:36:09.523558       1 factory.go:1068] [tanle] Next Pod user2-4
I0323 19:36:09.523676       1 generic_scheduler.go:510] demand 0: =  {%!s(float64=5392.731535756154) %!s(float64=3.221225472e+09) %!s(float64=0.23446658851113714)}
I0323 19:36:09.523720       1 generic_scheduler.go:510] demand 1: =  {%!s(float64=10772.833723653397) %!s(float64=3.221225472e+09) %!s(float64=0.468384074941452)}
I0323 19:36:09.523739       1 generic_scheduler.go:690] shares [%!s(*schedulercache.Resource=&{46000 27477053276 2 0 0 map[]}) %!s(*schedulercache.Resource=&{46000 13754632765 2 0 0 map[]})]
I0323 19:36:09.523773       1 generic_scheduler.go:692] Rejected pod: user2-4 podDemand &{%!s(int64=1000) %!s(int64=3221225472) %!s(int64=1) %!s(int64=0) %!s(int=0) map[]} usage &{%!s(int64=25000) %!s(int64=9663676416) %!s(int64=2) %!s(int64=0) %!s(int=0) map[]} share[1]&{%!s(int64=46000) %!s(int64=13754632765) %!s(int64=2) %!s(int64=0) %!s(int=0) map[]}
I0323 19:36:09.524968       1 factory.go:1068] [tanle] Next Pod user2-3
I0323 19:36:09.525131       1 generic_scheduler.go:510] demand 0: =  {%!s(float64=5392.731535756154) %!s(float64=3.221225472e+09) %!s(float64=0.23446658851113714)}
I0323 19:36:09.525242       1 generic_scheduler.go:510] demand 1: =  {%!s(float64=10772.833723653397) %!s(float64=3.221225472e+09) %!s(float64=0.468384074941452)}
I0323 19:36:09.525275       1 generic_scheduler.go:690] shares [%!s(*schedulercache.Resource=&{46000 27477053276 2 0 0 map[]}) %!s(*schedulercache.Resource=&{46000 13754632765 2 0 0 map[]})]
I0323 19:36:09.525339       1 generic_scheduler.go:591] demand.MilliCPU: 23000, currentUsage.MilliCPU 25000, share.MilliCPU 46000
I0323 19:36:09.525357       1 generic_scheduler.go:692] Rejected pod: user2-3 podDemand &{%!s(int64=23000) %!s(int64=3221225472) %!s(int64=0) %!s(int64=0) %!s(int=0) map[]} usage &{%!s(int64=25000) %!s(int64=9663676416) %!s(int64=2) %!s(int64=0) %!s(int=0) map[]} share[1]&{%!s(int64=46000) %!s(int64=13754632765) %!s(int64=2) %!s(int64=0) %!s(int=0) map[]}
I0323 19:36:10.291323       1 factory.go:1068] [tanle] Next Pod user1-3
I0323 19:36:10.291538       1 generic_scheduler.go:510] demand 0: =  {%!s(float64=5392.731535756154) %!s(float64=3.221225472e+09) %!s(float64=0.23446658851113714)}
I0323 19:36:10.291587       1 generic_scheduler.go:510] demand 1: =  {%!s(float64=10772.833723653397) %!s(float64=3.221225472e+09) %!s(float64=0.468384074941452)}
I0323 19:36:10.291614       1 generic_scheduler.go:690] shares [%!s(*schedulercache.Resource=&{46000 27477053276 2 0 0 map[]}) %!s(*schedulercache.Resource=&{46000 13754632765 2 0 0 map[]})]
I0323 19:36:10.291639       1 generic_scheduler.go:591] demand.MilliCPU: 23000, currentUsage.MilliCPU 25000, share.MilliCPU 46000
I0323 19:36:10.291651       1 generic_scheduler.go:692] Rejected pod: user1-3 podDemand &{%!s(int64=23000) %!s(int64=3221225472) %!s(int64=0) %!s(int64=0) %!s(int=0) map[]} usage &{%!s(int64=25000) %!s(int64=9663676416) %!s(int64=2) %!s(int64=0) %!s(int=0) map[]} share[1]&{%!s(int64=46000) %!s(int64=13754632765) %!s(int64=2) %!s(int64=0) %!s(int=0) map[]}
I0323 19:36:13.525235       1 factory.go:1068] [tanle] Next Pod user2-4
I0323 19:36:13.525366       1 generic_scheduler.go:510] demand 0: =  {%!s(float64=5392.731535756154) %!s(float64=3.221225472e+09) %!s(float64=0.23446658851113714)}
I0323 19:36:13.525399       1 generic_scheduler.go:510] demand 1: =  {%!s(float64=10772.833723653397) %!s(float64=3.221225472e+09) %!s(float64=0.468384074941452)}
I0323 19:36:13.525417       1 generic_scheduler.go:690] shares [%!s(*schedulercache.Resource=&{46000 27477053276 2 0 0 map[]}) %!s(*schedulercache.Resource=&{46000 13754632765 2 0 0 map[]})]
I0323 19:36:13.525433       1 generic_scheduler.go:692] Rejected pod: user2-4 podDemand &{%!s(int64=1000) %!s(int64=3221225472) %!s(int64=1) %!s(int64=0) %!s(int=0) map[]} usage &{%!s(int64=25000) %!s(int64=9663676416) %!s(int64=2) %!s(int64=0) %!s(int=0) map[]} share[1]&{%!s(int64=46000) %!s(int64=13754632765) %!s(int64=2) %!s(int64=0) %!s(int=0) map[]}
I0323 19:36:13.525578       1 factory.go:1068] [tanle] Next Pod user2-5
I0323 19:36:13.525648       1 generic_scheduler.go:510] demand 0: =  {%!s(float64=5392.731535756154) %!s(float64=3.221225472e+09) %!s(float64=0.23446658851113714)}
I0323 19:36:13.525668       1 generic_scheduler.go:510] demand 1: =  {%!s(float64=10772.833723653397) %!s(float64=3.221225472e+09) %!s(float64=0.468384074941452)}
I0323 19:36:13.525681       1 generic_scheduler.go:690] shares [%!s(*schedulercache.Resource=&{46000 27477053276 2 0 0 map[]}) %!s(*schedulercache.Resource=&{46000 13754632765 2 0 0 map[]})]
I0323 19:36:13.525701       1 generic_scheduler.go:692] Rejected pod: user2-5 podDemand &{%!s(int64=1000) %!s(int64=3221225472) %!s(int64=1) %!s(int64=0) %!s(int=0) map[]} usage &{%!s(int64=25000) %!s(int64=9663676416) %!s(int64=2) %!s(int64=0) %!s(int=0) map[]} share[1]&{%!s(int64=46000) %!s(int64=13754632765) %!s(int64=2) %!s(int64=0) %!s(int=0) map[]}
I0323 19:36:13.527169       1 factory.go:1068] [tanle] Next Pod user2-3
I0323 19:36:13.527264       1 generic_scheduler.go:510] demand 0: =  {%!s(float64=5392.731535756154) %!s(float64=3.221225472e+09) %!s(float64=0.23446658851113714)}
I0323 19:36:13.527288       1 generic_scheduler.go:510] demand 1: =  {%!s(float64=10772.833723653397) %!s(float64=3.221225472e+09) %!s(float64=0.468384074941452)}
I0323 19:36:13.527299       1 generic_scheduler.go:690] shares [%!s(*schedulercache.Resource=&{46000 27477053276 2 0 0 map[]}) %!s(*schedulercache.Resource=&{46000 13754632765 2 0 0 map[]})]
I0323 19:36:13.527317       1 generic_scheduler.go:591] demand.MilliCPU: 23000, currentUsage.MilliCPU 25000, share.MilliCPU 46000
I0323 19:36:13.527329       1 generic_scheduler.go:692] Rejected pod: user2-3 podDemand &{%!s(int64=23000) %!s(int64=3221225472) %!s(int64=0) %!s(int64=0) %!s(int=0) map[]} usage &{%!s(int64=25000) %!s(int64=9663676416) %!s(int64=2) %!s(int64=0) %!s(int=0) map[]} share[1]&{%!s(int64=46000) %!s(int64=13754632765) %!s(int64=2) %!s(int64=0) %!s(int=0) map[]}
I0323 19:36:14.989136       1 factory.go:1068] [tanle] Next Pod user1-3
I0323 19:36:14.989285       1 generic_scheduler.go:510] demand 0: =  {%!s(float64=5392.731535756154) %!s(float64=3.221225472e+09) %!s(float64=0.23446658851113714)}
I0323 19:36:14.989321       1 generic_scheduler.go:510] demand 1: =  {%!s(float64=10772.833723653397) %!s(float64=3.221225472e+09) %!s(float64=0.468384074941452)}
I0323 19:36:14.989341       1 generic_scheduler.go:690] shares [%!s(*schedulercache.Resource=&{46000 27477053276 2 0 0 map[]}) %!s(*schedulercache.Resource=&{46000 13754632765 2 0 0 map[]})]
I0323 19:36:14.989393       1 generic_scheduler.go:591] demand.MilliCPU: 23000, currentUsage.MilliCPU 25000, share.MilliCPU 46000
I0323 19:36:14.989419       1 generic_scheduler.go:692] Rejected pod: user1-3 podDemand &{%!s(int64=23000) %!s(int64=3221225472) %!s(int64=0) %!s(int64=0) %!s(int=0) map[]} usage &{%!s(int64=25000) %!s(int64=9663676416) %!s(int64=2) %!s(int64=0) %!s(int=0) map[]} share[1]&{%!s(int64=46000) %!s(int64=13754632765) %!s(int64=2) %!s(int64=0) %!s(int=0) map[]}
I0323 19:36:15.018057       1 factory.go:1068] [tanle] Next Pod user2-6
I0323 19:36:15.018249       1 generic_scheduler.go:510] demand 0: =  {%!s(float64=5392.731535756154) %!s(float64=3.221225472e+09) %!s(float64=0.23446658851113714)}
I0323 19:36:15.018315       1 generic_scheduler.go:510] demand 1: =  {%!s(float64=10772.833723653397) %!s(float64=3.221225472e+09) %!s(float64=0.468384074941452)}
I0323 19:36:15.018333       1 generic_scheduler.go:690] shares [%!s(*schedulercache.Resource=&{46000 27477053276 2 0 0 map[]}) %!s(*schedulercache.Resource=&{46000 13754632765 2 0 0 map[]})]
I0323 19:36:15.018358       1 generic_scheduler.go:591] demand.MilliCPU: 23000, currentUsage.MilliCPU 25000, share.MilliCPU 46000
I0323 19:36:15.018366       1 generic_scheduler.go:692] Rejected pod: user2-6 podDemand &{%!s(int64=23000) %!s(int64=3221225472) %!s(int64=0) %!s(int64=0) %!s(int=0) map[]} usage &{%!s(int64=25000) %!s(int64=9663676416) %!s(int64=2) %!s(int64=0) %!s(int=0) map[]} share[1]&{%!s(int64=46000) %!s(int64=13754632765) %!s(int64=2) %!s(int64=0) %!s(int=0) map[]}
I0323 19:36:15.042841       1 factory.go:1068] [tanle] Next Pod user2-6
I0323 19:36:15.043076       1 generic_scheduler.go:510] demand 0: =  {%!s(float64=5392.731535756154) %!s(float64=3.221225472e+09) %!s(float64=0.23446658851113714)}
I0323 19:36:15.043128       1 generic_scheduler.go:510] demand 1: =  {%!s(float64=10772.833723653397) %!s(float64=3.221225472e+09) %!s(float64=0.468384074941452)}
I0323 19:36:15.043139       1 generic_scheduler.go:690] shares [%!s(*schedulercache.Resource=&{46000 27477053276 2 0 0 map[]}) %!s(*schedulercache.Resource=&{46000 13754632765 2 0 0 map[]})]
I0323 19:36:15.043156       1 generic_scheduler.go:591] demand.MilliCPU: 23000, currentUsage.MilliCPU 25000, share.MilliCPU 46000
I0323 19:36:15.043161       1 generic_scheduler.go:692] Rejected pod: user2-6 podDemand &{%!s(int64=23000) %!s(int64=3221225472) %!s(int64=0) %!s(int64=0) %!s(int=0) map[]} usage &{%!s(int64=25000) %!s(int64=9663676416) %!s(int64=2) %!s(int64=0) %!s(int=0) map[]} share[1]&{%!s(int64=46000) %!s(int64=13754632765) %!s(int64=2) %!s(int64=0) %!s(int=0) map[]}
W0323 19:36:15.043310       1 factory.go:1226] Request for pod user2/user2-6 already in flight, abandoning
I0323 19:36:15.063821       1 factory.go:1068] [tanle] Next Pod user2-7
I0323 19:36:15.064023       1 generic_scheduler.go:510] demand 0: =  {%!s(float64=5392.731535756154) %!s(float64=3.221225472e+09) %!s(float64=0.23446658851113714)}
I0323 19:36:15.064063       1 generic_scheduler.go:510] demand 1: =  {%!s(float64=10772.833723653397) %!s(float64=3.221225472e+09) %!s(float64=0.468384074941452)}
I0323 19:36:15.064082       1 generic_scheduler.go:690] shares [%!s(*schedulercache.Resource=&{46000 27477053276 2 0 0 map[]}) %!s(*schedulercache.Resource=&{46000 13754632765 2 0 0 map[]})]
I0323 19:36:15.064108       1 generic_scheduler.go:591] demand.MilliCPU: 23000, currentUsage.MilliCPU 25000, share.MilliCPU 46000
I0323 19:36:15.064118       1 generic_scheduler.go:692] Rejected pod: user2-7 podDemand &{%!s(int64=23000) %!s(int64=3221225472) %!s(int64=0) %!s(int64=0) %!s(int=0) map[]} usage &{%!s(int64=25000) %!s(int64=9663676416) %!s(int64=2) %!s(int64=0) %!s(int=0) map[]} share[1]&{%!s(int64=46000) %!s(int64=13754632765) %!s(int64=2) %!s(int64=0) %!s(int=0) map[]}
I0323 19:36:15.256271       1 factory.go:1068] [tanle] Next Pod user2-7
I0323 19:36:15.256442       1 generic_scheduler.go:510] demand 0: =  {%!s(float64=5392.731535756154) %!s(float64=3.221225472e+09) %!s(float64=0.23446658851113714)}
I0323 19:36:15.256473       1 generic_scheduler.go:510] demand 1: =  {%!s(float64=10772.833723653397) %!s(float64=3.221225472e+09) %!s(float64=0.468384074941452)}
I0323 19:36:15.256504       1 generic_scheduler.go:690] shares [%!s(*schedulercache.Resource=&{46000 27477053276 2 0 0 map[]}) %!s(*schedulercache.Resource=&{46000 13754632765 2 0 0 map[]})]
I0323 19:36:15.256550       1 generic_scheduler.go:591] demand.MilliCPU: 23000, currentUsage.MilliCPU 25000, share.MilliCPU 46000
I0323 19:36:15.256558       1 generic_scheduler.go:692] Rejected pod: user2-7 podDemand &{%!s(int64=23000) %!s(int64=3221225472) %!s(int64=0) %!s(int64=0) %!s(int=0) map[]} usage &{%!s(int64=25000) %!s(int64=9663676416) %!s(int64=2) %!s(int64=0) %!s(int=0) map[]} share[1]&{%!s(int64=46000) %!s(int64=13754632765) %!s(int64=2) %!s(int64=0) %!s(int=0) map[]}
W0323 19:36:15.256648       1 factory.go:1226] Request for pod user2/user2-7 already in flight, abandoning
I0323 19:36:16.021248       1 factory.go:1068] [tanle] Next Pod user2-6
I0323 19:36:16.021386       1 generic_scheduler.go:510] demand 0: =  {%!s(float64=5392.731535756154) %!s(float64=3.221225472e+09) %!s(float64=0.23446658851113714)}
I0323 19:36:16.021427       1 generic_scheduler.go:510] demand 1: =  {%!s(float64=10772.833723653397) %!s(float64=3.221225472e+09) %!s(float64=0.468384074941452)}
I0323 19:36:16.021455       1 generic_scheduler.go:690] shares [%!s(*schedulercache.Resource=&{46000 27477053276 2 0 0 map[]}) %!s(*schedulercache.Resource=&{46000 13754632765 2 0 0 map[]})]
I0323 19:36:16.021485       1 generic_scheduler.go:591] demand.MilliCPU: 23000, currentUsage.MilliCPU 25000, share.MilliCPU 46000
I0323 19:36:16.021506       1 generic_scheduler.go:692] Rejected pod: user2-6 podDemand &{%!s(int64=23000) %!s(int64=3221225472) %!s(int64=0) %!s(int64=0) %!s(int=0) map[]} usage &{%!s(int64=25000) %!s(int64=9663676416) %!s(int64=2) %!s(int64=0) %!s(int=0) map[]} share[1]&{%!s(int64=46000) %!s(int64=13754632765) %!s(int64=2) %!s(int64=0) %!s(int=0) map[]}
I0323 19:36:16.069013       1 factory.go:1068] [tanle] Next Pod user2-7
I0323 19:36:16.069180       1 generic_scheduler.go:510] demand 0: =  {%!s(float64=5392.731535756154) %!s(float64=3.221225472e+09) %!s(float64=0.23446658851113714)}
I0323 19:36:16.069213       1 generic_scheduler.go:510] demand 1: =  {%!s(float64=10772.833723653397) %!s(float64=3.221225472e+09) %!s(float64=0.468384074941452)}
I0323 19:36:16.069226       1 generic_scheduler.go:690] shares [%!s(*schedulercache.Resource=&{46000 27477053276 2 0 0 map[]}) %!s(*schedulercache.Resource=&{46000 13754632765 2 0 0 map[]})]
I0323 19:36:16.069242       1 generic_scheduler.go:591] demand.MilliCPU: 23000, currentUsage.MilliCPU 25000, share.MilliCPU 46000
I0323 19:36:16.069247       1 generic_scheduler.go:692] Rejected pod: user2-7 podDemand &{%!s(int64=23000) %!s(int64=3221225472) %!s(int64=0) %!s(int64=0) %!s(int=0) map[]} usage &{%!s(int64=25000) %!s(int64=9663676416) %!s(int64=2) %!s(int64=0) %!s(int=0) map[]} share[1]&{%!s(int64=46000) %!s(int64=13754632765) %!s(int64=2) %!s(int64=0) %!s(int=0) map[]}
I0323 19:36:18.023964       1 factory.go:1068] [tanle] Next Pod user2-6
I0323 19:36:18.024172       1 generic_scheduler.go:510] demand 0: =  {%!s(float64=5392.731535756154) %!s(float64=3.221225472e+09) %!s(float64=0.23446658851113714)}
I0323 19:36:18.024242       1 generic_scheduler.go:510] demand 1: =  {%!s(float64=10772.833723653397) %!s(float64=3.221225472e+09) %!s(float64=0.468384074941452)}
I0323 19:36:18.024273       1 generic_scheduler.go:690] shares [%!s(*schedulercache.Resource=&{46000 27477053276 2 0 0 map[]}) %!s(*schedulercache.Resource=&{46000 13754632765 2 0 0 map[]})]
I0323 19:36:18.024303       1 generic_scheduler.go:695] Admitted pod: user2-6 podDemand &{%!s(int64=23000) %!s(int64=3221225472) %!s(int64=0) %!s(int64=0) %!s(int=0) map[]} usage &{%!s(int64=23000) %!s(int64=3221225472) %!s(int64=0) %!s(int64=0) %!s(int=0) map[]}
I0323 19:36:18.073258       1 factory.go:1068] [tanle] Next Pod user2-7
I0323 19:36:18.073430       1 generic_scheduler.go:510] demand 0: =  {%!s(float64=5392.731535756154) %!s(float64=3.221225472e+09) %!s(float64=0.23446658851113714)}
I0323 19:36:18.073468       1 generic_scheduler.go:510] demand 1: =  {%!s(float64=10772.833723653397) %!s(float64=3.221225472e+09) %!s(float64=0.468384074941452)}
I0323 19:36:18.073479       1 generic_scheduler.go:690] shares [%!s(*schedulercache.Resource=&{46000 27477053276 2 0 0 map[]}) %!s(*schedulercache.Resource=&{46000 13754632765 2 0 0 map[]})]
I0323 19:36:18.073493       1 generic_scheduler.go:591] demand.MilliCPU: 23000, currentUsage.MilliCPU 46000, share.MilliCPU 46000
I0323 19:36:18.073506       1 generic_scheduler.go:692] Rejected pod: user2-7 podDemand &{%!s(int64=23000) %!s(int64=3221225472) %!s(int64=0) %!s(int64=0) %!s(int=0) map[]} usage &{%!s(int64=46000) %!s(int64=6442450944) %!s(int64=0) %!s(int64=0) %!s(int=0) map[]} share[1]&{%!s(int64=46000) %!s(int64=13754632765) %!s(int64=2) %!s(int64=0) %!s(int=0) map[]}
I0323 19:36:18.087409       1 factory.go:1068] [tanle] Next Pod user2-7
I0323 19:36:18.087516       1 generic_scheduler.go:510] demand 0: =  {%!s(float64=5392.731535756154) %!s(float64=3.221225472e+09) %!s(float64=0.23446658851113714)}
I0323 19:36:18.087539       1 generic_scheduler.go:510] demand 1: =  {%!s(float64=10772.833723653397) %!s(float64=3.221225472e+09) %!s(float64=0.468384074941452)}
I0323 19:36:18.087550       1 generic_scheduler.go:690] shares [%!s(*schedulercache.Resource=&{46000 27477053276 2 0 0 map[]}) %!s(*schedulercache.Resource=&{46000 13754632765 2 0 0 map[]})]
I0323 19:36:18.087565       1 generic_scheduler.go:591] demand.MilliCPU: 23000, currentUsage.MilliCPU 46000, share.MilliCPU 46000
I0323 19:36:18.087571       1 generic_scheduler.go:692] Rejected pod: user2-7 podDemand &{%!s(int64=23000) %!s(int64=3221225472) %!s(int64=0) %!s(int64=0) %!s(int=0) map[]} usage &{%!s(int64=46000) %!s(int64=6442450944) %!s(int64=0) %!s(int64=0) %!s(int=0) map[]} share[1]&{%!s(int64=46000) %!s(int64=13754632765) %!s(int64=2) %!s(int64=0) %!s(int=0) map[]}
W0323 19:36:18.087652       1 factory.go:1226] Request for pod user2/user2-7 already in flight, abandoning
I0323 19:36:21.528991       1 factory.go:1068] [tanle] Next Pod user2-4
I0323 19:36:21.529208       1 generic_scheduler.go:510] demand 0: =  {%!s(float64=5392.731535756154) %!s(float64=3.221225472e+09) %!s(float64=0.23446658851113714)}
I0323 19:36:21.529265       1 generic_scheduler.go:510] demand 1: =  {%!s(float64=10772.833723653397) %!s(float64=3.221225472e+09) %!s(float64=0.468384074941452)}
I0323 19:36:21.529285       1 generic_scheduler.go:690] shares [%!s(*schedulercache.Resource=&{46000 27477053276 2 0 0 map[]}) %!s(*schedulercache.Resource=&{46000 13754632765 2 0 0 map[]})]
I0323 19:36:21.529317       1 generic_scheduler.go:695] Admitted pod: user2-4 podDemand &{%!s(int64=1000) %!s(int64=3221225472) %!s(int64=1) %!s(int64=0) %!s(int=0) map[]} usage &{%!s(int64=46000) %!s(int64=6442450944) %!s(int64=0) %!s(int64=0) %!s(int=0) map[]}
I0323 19:36:21.529430       1 factory.go:1068] [tanle] Next Pod user2-5
I0323 19:36:21.529547       1 generic_scheduler.go:510] demand 0: =  {%!s(float64=5392.731535756154) %!s(float64=3.221225472e+09) %!s(float64=0.23446658851113714)}
I0323 19:36:21.529570       1 generic_scheduler.go:510] demand 1: =  {%!s(float64=10772.833723653397) %!s(float64=3.221225472e+09) %!s(float64=0.468384074941452)}
I0323 19:36:21.529583       1 generic_scheduler.go:690] shares [%!s(*schedulercache.Resource=&{46000 27477053276 2 0 0 map[]}) %!s(*schedulercache.Resource=&{46000 13754632765 2 0 0 map[]})]
I0323 19:36:21.529597       1 generic_scheduler.go:695] Admitted pod: user2-5 podDemand &{%!s(int64=1000) %!s(int64=3221225472) %!s(int64=1) %!s(int64=0) %!s(int=0) map[]} usage &{%!s(int64=47000) %!s(int64=9663676416) %!s(int64=1) %!s(int64=0) %!s(int=0) map[]}
I0323 19:36:21.529655       1 factory.go:1068] [tanle] Next Pod user2-3
I0323 19:36:21.529744       1 generic_scheduler.go:510] demand 0: =  {%!s(float64=5392.731535756154) %!s(float64=3.221225472e+09) %!s(float64=0.23446658851113714)}
I0323 19:36:21.529767       1 generic_scheduler.go:510] demand 1: =  {%!s(float64=10772.833723653397) %!s(float64=3.221225472e+09) %!s(float64=0.468384074941452)}
I0323 19:36:21.529783       1 generic_scheduler.go:690] shares [%!s(*schedulercache.Resource=&{46000 27477053276 2 0 0 map[]}) %!s(*schedulercache.Resource=&{46000 13754632765 2 0 0 map[]})]
I0323 19:36:21.529802       1 generic_scheduler.go:591] demand.MilliCPU: 23000, currentUsage.MilliCPU 48000, share.MilliCPU 46000
I0323 19:36:21.529812       1 generic_scheduler.go:692] Rejected pod: user2-3 podDemand &{%!s(int64=23000) %!s(int64=3221225472) %!s(int64=0) %!s(int64=0) %!s(int=0) map[]} usage &{%!s(int64=48000) %!s(int64=12884901888) %!s(int64=2) %!s(int64=0) %!s(int=0) map[]} share[1]&{%!s(int64=46000) %!s(int64=13754632765) %!s(int64=2) %!s(int64=0) %!s(int=0) map[]}
I0323 19:36:21.545850       1 factory.go:1068] [tanle] Next Pod user2-3
I0323 19:36:21.546093       1 generic_scheduler.go:510] demand 0: =  {%!s(float64=5392.731535756154) %!s(float64=3.221225472e+09) %!s(float64=0.23446658851113714)}
I0323 19:36:21.546147       1 generic_scheduler.go:510] demand 1: =  {%!s(float64=10772.833723653397) %!s(float64=3.221225472e+09) %!s(float64=0.468384074941452)}
I0323 19:36:21.546167       1 generic_scheduler.go:690] shares [%!s(*schedulercache.Resource=&{46000 27477053276 2 0 0 map[]}) %!s(*schedulercache.Resource=&{46000 13754632765 2 0 0 map[]})]
I0323 19:36:21.546197       1 generic_scheduler.go:591] demand.MilliCPU: 23000, currentUsage.MilliCPU 48000, share.MilliCPU 46000
I0323 19:36:21.546205       1 generic_scheduler.go:692] Rejected pod: user2-3 podDemand &{%!s(int64=23000) %!s(int64=3221225472) %!s(int64=0) %!s(int64=0) %!s(int=0) map[]} usage &{%!s(int64=48000) %!s(int64=12884901888) %!s(int64=2) %!s(int64=0) %!s(int=0) map[]} share[1]&{%!s(int64=46000) %!s(int64=13754632765) %!s(int64=2) %!s(int64=0) %!s(int=0) map[]}
W0323 19:36:21.546343       1 factory.go:1226] Request for pod user2/user2-3 already in flight, abandoning
I0323 19:36:22.078029       1 factory.go:1068] [tanle] Next Pod user2-7
I0323 19:36:22.078212       1 generic_scheduler.go:510] demand 0: =  {%!s(float64=5392.731535756154) %!s(float64=3.221225472e+09) %!s(float64=0.23446658851113714)}
I0323 19:36:22.078249       1 generic_scheduler.go:510] demand 1: =  {%!s(float64=10772.833723653397) %!s(float64=3.221225472e+09) %!s(float64=0.468384074941452)}
I0323 19:36:22.078299       1 generic_scheduler.go:690] shares [%!s(*schedulercache.Resource=&{46000 27477053276 2 0 0 map[]}) %!s(*schedulercache.Resource=&{46000 13754632765 2 0 0 map[]})]
I0323 19:36:22.078329       1 generic_scheduler.go:591] demand.MilliCPU: 23000, currentUsage.MilliCPU 47000, share.MilliCPU 46000
I0323 19:36:22.078342       1 generic_scheduler.go:692] Rejected pod: user2-7 podDemand &{%!s(int64=23000) %!s(int64=3221225472) %!s(int64=0) %!s(int64=0) %!s(int=0) map[]} usage &{%!s(int64=47000) %!s(int64=9663676416) %!s(int64=1) %!s(int64=0) %!s(int=0) map[]} share[1]&{%!s(int64=46000) %!s(int64=13754632765) %!s(int64=2) %!s(int64=0) %!s(int=0) map[]}
I0323 19:36:22.991924       1 factory.go:1068] [tanle] Next Pod user1-3
I0323 19:36:22.992163       1 generic_scheduler.go:510] demand 0: =  {%!s(float64=5392.731535756154) %!s(float64=3.221225472e+09) %!s(float64=0.23446658851113714)}
I0323 19:36:22.992221       1 generic_scheduler.go:510] demand 1: =  {%!s(float64=10772.833723653397) %!s(float64=3.221225472e+09) %!s(float64=0.468384074941452)}
I0323 19:36:22.992258       1 generic_scheduler.go:690] shares [%!s(*schedulercache.Resource=&{46000 27477053276 2 0 0 map[]}) %!s(*schedulercache.Resource=&{46000 13754632765 2 0 0 map[]})]
I0323 19:36:22.992306       1 generic_scheduler.go:591] demand.MilliCPU: 23000, currentUsage.MilliCPU 25000, share.MilliCPU 46000
I0323 19:36:22.992326       1 generic_scheduler.go:692] Rejected pod: user1-3 podDemand &{%!s(int64=23000) %!s(int64=3221225472) %!s(int64=0) %!s(int64=0) %!s(int=0) map[]} usage &{%!s(int64=25000) %!s(int64=9663676416) %!s(int64=2) %!s(int64=0) %!s(int=0) map[]} share[1]&{%!s(int64=46000) %!s(int64=13754632765) %!s(int64=2) %!s(int64=0) %!s(int=0) map[]}
I0323 19:36:22.996239       1 factory.go:1068] [tanle] Next Pod user1-3
I0323 19:36:22.996421       1 generic_scheduler.go:510] demand 0: =  {%!s(float64=5392.731535756154) %!s(float64=3.221225472e+09) %!s(float64=0.23446658851113714)}
I0323 19:36:22.996497       1 generic_scheduler.go:510] demand 1: =  {%!s(float64=10772.833723653397) %!s(float64=3.221225472e+09) %!s(float64=0.468384074941452)}
I0323 19:36:22.996560       1 generic_scheduler.go:690] shares [%!s(*schedulercache.Resource=&{46000 27477053276 2 0 0 map[]}) %!s(*schedulercache.Resource=&{46000 13754632765 2 0 0 map[]})]
I0323 19:36:22.996606       1 generic_scheduler.go:591] demand.MilliCPU: 23000, currentUsage.MilliCPU 25000, share.MilliCPU 46000
I0323 19:36:22.996637       1 generic_scheduler.go:692] Rejected pod: user1-3 podDemand &{%!s(int64=23000) %!s(int64=3221225472) %!s(int64=0) %!s(int64=0) %!s(int=0) map[]} usage &{%!s(int64=25000) %!s(int64=9663676416) %!s(int64=2) %!s(int64=0) %!s(int=0) map[]} share[1]&{%!s(int64=46000) %!s(int64=13754632765) %!s(int64=2) %!s(int64=0) %!s(int=0) map[]}
W0323 19:36:22.996767       1 factory.go:1226] Request for pod user1/user1-3 already in flight, abandoning
I0323 19:36:30.082319       1 factory.go:1068] [tanle] Next Pod user2-7
I0323 19:36:30.082479       1 generic_scheduler.go:510] demand 0: =  {%!s(float64=5392.731535756154) %!s(float64=3.221225472e+09) %!s(float64=0.23446658851113714)}
I0323 19:36:30.082510       1 generic_scheduler.go:510] demand 1: =  {%!s(float64=10772.833723653397) %!s(float64=3.221225472e+09) %!s(float64=0.468384074941452)}
I0323 19:36:30.082526       1 generic_scheduler.go:690] shares [%!s(*schedulercache.Resource=&{46000 27477053276 2 0 0 map[]}) %!s(*schedulercache.Resource=&{46000 13754632765 2 0 0 map[]})]
I0323 19:36:30.082545       1 generic_scheduler.go:591] demand.MilliCPU: 23000, currentUsage.MilliCPU 47000, share.MilliCPU 46000
I0323 19:36:30.082555       1 generic_scheduler.go:692] Rejected pod: user2-7 podDemand &{%!s(int64=23000) %!s(int64=3221225472) %!s(int64=0) %!s(int64=0) %!s(int=0) map[]} usage &{%!s(int64=47000) %!s(int64=9663676416) %!s(int64=1) %!s(int64=0) %!s(int=0) map[]} share[1]&{%!s(int64=46000) %!s(int64=13754632765) %!s(int64=2) %!s(int64=0) %!s(int=0) map[]}
I0323 19:36:31.243580       1 factory.go:1068] [tanle] Next Pod user1-4
I0323 19:36:31.243741       1 generic_scheduler.go:510] demand 0: =  {%!s(float64=5392.731535756154) %!s(float64=3.221225472e+09) %!s(float64=0.23446658851113714)}
I0323 19:36:31.243767       1 generic_scheduler.go:510] demand 1: =  {%!s(float64=10772.833723653397) %!s(float64=3.221225472e+09) %!s(float64=0.468384074941452)}
I0323 19:36:31.243781       1 generic_scheduler.go:690] shares [%!s(*schedulercache.Resource=&{46000 27477053276 2 0 0 map[]}) %!s(*schedulercache.Resource=&{46000 13754632765 2 0 0 map[]})]
I0323 19:36:31.243802       1 generic_scheduler.go:692] Rejected pod: user1-4 podDemand &{%!s(int64=1000) %!s(int64=3221225472) %!s(int64=1) %!s(int64=0) %!s(int=0) map[]} usage &{%!s(int64=25000) %!s(int64=9663676416) %!s(int64=2) %!s(int64=0) %!s(int=0) map[]} share[1]&{%!s(int64=46000) %!s(int64=13754632765) %!s(int64=2) %!s(int64=0) %!s(int=0) map[]}
I0323 19:36:31.509988       1 factory.go:1068] [tanle] Next Pod user1-5
I0323 19:36:31.510220       1 generic_scheduler.go:510] demand 0: =  {%!s(float64=5392.731535756154) %!s(float64=3.221225472e+09) %!s(float64=0.23446658851113714)}
I0323 19:36:31.510275       1 generic_scheduler.go:510] demand 1: =  {%!s(float64=10772.833723653397) %!s(float64=3.221225472e+09) %!s(float64=0.468384074941452)}
I0323 19:36:31.510300       1 generic_scheduler.go:690] shares [%!s(*schedulercache.Resource=&{46000 27477053276 2 0 0 map[]}) %!s(*schedulercache.Resource=&{46000 13754632765 2 0 0 map[]})]
I0323 19:36:31.510330       1 generic_scheduler.go:692] Rejected pod: user1-5 podDemand &{%!s(int64=1000) %!s(int64=3221225472) %!s(int64=1) %!s(int64=0) %!s(int=0) map[]} usage &{%!s(int64=25000) %!s(int64=9663676416) %!s(int64=2) %!s(int64=0) %!s(int=0) map[]} share[1]&{%!s(int64=46000) %!s(int64=13754632765) %!s(int64=2) %!s(int64=0) %!s(int=0) map[]}
I0323 19:36:31.532266       1 factory.go:1068] [tanle] Next Pod user1-4
I0323 19:36:31.532404       1 generic_scheduler.go:510] demand 0: =  {%!s(float64=5392.731535756154) %!s(float64=3.221225472e+09) %!s(float64=0.23446658851113714)}
I0323 19:36:31.532436       1 generic_scheduler.go:510] demand 1: =  {%!s(float64=10772.833723653397) %!s(float64=3.221225472e+09) %!s(float64=0.468384074941452)}
I0323 19:36:31.532447       1 generic_scheduler.go:690] shares [%!s(*schedulercache.Resource=&{46000 27477053276 2 0 0 map[]}) %!s(*schedulercache.Resource=&{46000 13754632765 2 0 0 map[]})]
I0323 19:36:31.532465       1 generic_scheduler.go:692] Rejected pod: user1-4 podDemand &{%!s(int64=1000) %!s(int64=3221225472) %!s(int64=1) %!s(int64=0) %!s(int=0) map[]} usage &{%!s(int64=25000) %!s(int64=9663676416) %!s(int64=2) %!s(int64=0) %!s(int=0) map[]} share[1]&{%!s(int64=46000) %!s(int64=13754632765) %!s(int64=2) %!s(int64=0) %!s(int=0) map[]}
I0323 19:36:31.532574       1 factory.go:1068] [tanle] Next Pod user1-5
W0323 19:36:31.532575       1 factory.go:1226] Request for pod user1/user1-4 already in flight, abandoning
I0323 19:36:31.532653       1 generic_scheduler.go:510] demand 0: =  {%!s(float64=5392.731535756154) %!s(float64=3.221225472e+09) %!s(float64=0.23446658851113714)}
I0323 19:36:31.532676       1 generic_scheduler.go:510] demand 1: =  {%!s(float64=10772.833723653397) %!s(float64=3.221225472e+09) %!s(float64=0.468384074941452)}
I0323 19:36:31.532692       1 generic_scheduler.go:690] shares [%!s(*schedulercache.Resource=&{46000 27477053276 2 0 0 map[]}) %!s(*schedulercache.Resource=&{46000 13754632765 2 0 0 map[]})]
I0323 19:36:31.532712       1 generic_scheduler.go:692] Rejected pod: user1-5 podDemand &{%!s(int64=1000) %!s(int64=3221225472) %!s(int64=1) %!s(int64=0) %!s(int=0) map[]} usage &{%!s(int64=25000) %!s(int64=9663676416) %!s(int64=2) %!s(int64=0) %!s(int=0) map[]} share[1]&{%!s(int64=46000) %!s(int64=13754632765) %!s(int64=2) %!s(int64=0) %!s(int=0) map[]}
W0323 19:36:31.532831       1 factory.go:1226] Request for pod user1/user1-5 already in flight, abandoning
I0323 19:36:32.247032       1 factory.go:1068] [tanle] Next Pod user1-4
I0323 19:36:32.247249       1 generic_scheduler.go:510] demand 0: =  {%!s(float64=5392.731535756154) %!s(float64=3.221225472e+09) %!s(float64=0.23446658851113714)}
I0323 19:36:32.247293       1 generic_scheduler.go:510] demand 1: =  {%!s(float64=10772.833723653397) %!s(float64=3.221225472e+09) %!s(float64=0.468384074941452)}
I0323 19:36:32.247315       1 generic_scheduler.go:690] shares [%!s(*schedulercache.Resource=&{46000 27477053276 2 0 0 map[]}) %!s(*schedulercache.Resource=&{46000 13754632765 2 0 0 map[]})]
I0323 19:36:32.247342       1 generic_scheduler.go:692] Rejected pod: user1-4 podDemand &{%!s(int64=1000) %!s(int64=3221225472) %!s(int64=1) %!s(int64=0) %!s(int=0) map[]} usage &{%!s(int64=25000) %!s(int64=9663676416) %!s(int64=2) %!s(int64=0) %!s(int=0) map[]} share[1]&{%!s(int64=46000) %!s(int64=13754632765) %!s(int64=2) %!s(int64=0) %!s(int=0) map[]}
I0323 19:36:32.513310       1 factory.go:1068] [tanle] Next Pod user1-5
I0323 19:36:32.513511       1 generic_scheduler.go:510] demand 0: =  {%!s(float64=5392.731535756154) %!s(float64=3.221225472e+09) %!s(float64=0.23446658851113714)}
I0323 19:36:32.513547       1 generic_scheduler.go:510] demand 1: =  {%!s(float64=10772.833723653397) %!s(float64=3.221225472e+09) %!s(float64=0.468384074941452)}
I0323 19:36:32.513565       1 generic_scheduler.go:690] shares [%!s(*schedulercache.Resource=&{46000 27477053276 2 0 0 map[]}) %!s(*schedulercache.Resource=&{46000 13754632765 2 0 0 map[]})]
I0323 19:36:32.513590       1 generic_scheduler.go:692] Rejected pod: user1-5 podDemand &{%!s(int64=1000) %!s(int64=3221225472) %!s(int64=1) %!s(int64=0) %!s(int=0) map[]} usage &{%!s(int64=25000) %!s(int64=9663676416) %!s(int64=2) %!s(int64=0) %!s(int=0) map[]} share[1]&{%!s(int64=46000) %!s(int64=13754632765) %!s(int64=2) %!s(int64=0) %!s(int=0) map[]}
I0323 19:36:34.252550       1 factory.go:1068] [tanle] Next Pod user1-4
I0323 19:36:34.252802       1 generic_scheduler.go:510] demand 0: =  {%!s(float64=5392.731535756154) %!s(float64=3.221225472e+09) %!s(float64=0.23446658851113714)}
I0323 19:36:34.252866       1 generic_scheduler.go:510] demand 1: =  {%!s(float64=10772.833723653397) %!s(float64=3.221225472e+09) %!s(float64=0.468384074941452)}
I0323 19:36:34.252893       1 generic_scheduler.go:690] shares [%!s(*schedulercache.Resource=&{46000 27477053276 2 0 0 map[]}) %!s(*schedulercache.Resource=&{46000 13754632765 2 0 0 map[]})]
I0323 19:36:34.252932       1 generic_scheduler.go:692] Rejected pod: user1-4 podDemand &{%!s(int64=1000) %!s(int64=3221225472) %!s(int64=1) %!s(int64=0) %!s(int=0) map[]} usage &{%!s(int64=25000) %!s(int64=9663676416) %!s(int64=2) %!s(int64=0) %!s(int=0) map[]} share[1]&{%!s(int64=46000) %!s(int64=13754632765) %!s(int64=2) %!s(int64=0) %!s(int=0) map[]}
I0323 19:36:34.516381       1 factory.go:1068] [tanle] Next Pod user1-5
I0323 19:36:34.516520       1 generic_scheduler.go:510] demand 0: =  {%!s(float64=5392.731535756154) %!s(float64=3.221225472e+09) %!s(float64=0.23446658851113714)}
I0323 19:36:34.516553       1 generic_scheduler.go:510] demand 1: =  {%!s(float64=10772.833723653397) %!s(float64=3.221225472e+09) %!s(float64=0.468384074941452)}
I0323 19:36:34.516574       1 generic_scheduler.go:690] shares [%!s(*schedulercache.Resource=&{46000 27477053276 2 0 0 map[]}) %!s(*schedulercache.Resource=&{46000 13754632765 2 0 0 map[]})]
I0323 19:36:34.516586       1 generic_scheduler.go:692] Rejected pod: user1-5 podDemand &{%!s(int64=1000) %!s(int64=3221225472) %!s(int64=1) %!s(int64=0) %!s(int=0) map[]} usage &{%!s(int64=25000) %!s(int64=9663676416) %!s(int64=2) %!s(int64=0) %!s(int=0) map[]} share[1]&{%!s(int64=46000) %!s(int64=13754632765) %!s(int64=2) %!s(int64=0) %!s(int=0) map[]}
I0323 19:36:37.532278       1 factory.go:1068] [tanle] Next Pod user2-3
I0323 19:36:37.532467       1 generic_scheduler.go:510] demand 0: =  {%!s(float64=5392.731535756154) %!s(float64=3.221225472e+09) %!s(float64=0.23446658851113714)}
I0323 19:36:37.532510       1 generic_scheduler.go:510] demand 1: =  {%!s(float64=10772.833723653397) %!s(float64=3.221225472e+09) %!s(float64=0.468384074941452)}
I0323 19:36:37.532533       1 generic_scheduler.go:690] shares [%!s(*schedulercache.Resource=&{46000 27477053276 2 0 0 map[]}) %!s(*schedulercache.Resource=&{46000 13754632765 2 0 0 map[]})]
I0323 19:36:37.532558       1 generic_scheduler.go:591] demand.MilliCPU: 23000, currentUsage.MilliCPU 24000, share.MilliCPU 46000
I0323 19:36:37.532571       1 generic_scheduler.go:692] Rejected pod: user2-3 podDemand &{%!s(int64=23000) %!s(int64=3221225472) %!s(int64=0) %!s(int64=0) %!s(int=0) map[]} usage &{%!s(int64=24000) %!s(int64=6442450944) %!s(int64=1) %!s(int64=0) %!s(int=0) map[]} share[1]&{%!s(int64=46000) %!s(int64=13754632765) %!s(int64=2) %!s(int64=0) %!s(int=0) map[]}
I0323 19:36:38.261893       1 factory.go:1068] [tanle] Next Pod user1-4
I0323 19:36:38.262073       1 generic_scheduler.go:510] demand 0: =  {%!s(float64=5392.731535756154) %!s(float64=3.221225472e+09) %!s(float64=0.23446658851113714)}
I0323 19:36:38.262114       1 generic_scheduler.go:510] demand 1: =  {%!s(float64=10772.833723653397) %!s(float64=3.221225472e+09) %!s(float64=0.468384074941452)}
I0323 19:36:38.262137       1 generic_scheduler.go:690] shares [%!s(*schedulercache.Resource=&{46000 27477053276 2 0 0 map[]}) %!s(*schedulercache.Resource=&{46000 13754632765 2 0 0 map[]})]
I0323 19:36:38.262159       1 generic_scheduler.go:695] Admitted pod: user1-4 podDemand &{%!s(int64=1000) %!s(int64=3221225472) %!s(int64=1) %!s(int64=0) %!s(int=0) map[]} usage &{%!s(int64=24000) %!s(int64=6442450944) %!s(int64=1) %!s(int64=0) %!s(int=0) map[]}
I0323 19:36:38.996149       1 factory.go:1068] [tanle] Next Pod user1-5
I0323 19:36:38.996375       1 generic_scheduler.go:510] demand 0: =  {%!s(float64=5392.731535756154) %!s(float64=3.221225472e+09) %!s(float64=0.23446658851113714)}
I0323 19:36:38.996434       1 generic_scheduler.go:510] demand 1: =  {%!s(float64=10772.833723653397) %!s(float64=3.221225472e+09) %!s(float64=0.468384074941452)}
I0323 19:36:38.996465       1 generic_scheduler.go:690] shares [%!s(*schedulercache.Resource=&{46000 27477053276 2 0 0 map[]}) %!s(*schedulercache.Resource=&{46000 13754632765 2 0 0 map[]})]
I0323 19:36:38.996501       1 generic_scheduler.go:692] Rejected pod: user1-5 podDemand &{%!s(int64=1000) %!s(int64=3221225472) %!s(int64=1) %!s(int64=0) %!s(int=0) map[]} usage &{%!s(int64=25000) %!s(int64=9663676416) %!s(int64=2) %!s(int64=0) %!s(int=0) map[]} share[1]&{%!s(int64=46000) %!s(int64=13754632765) %!s(int64=2) %!s(int64=0) %!s(int=0) map[]}
I0323 19:36:38.997024       1 factory.go:1068] [tanle] Next Pod user1-3
I0323 19:36:38.997174       1 generic_scheduler.go:510] demand 0: =  {%!s(float64=5392.731535756154) %!s(float64=3.221225472e+09) %!s(float64=0.23446658851113714)}
I0323 19:36:38.997199       1 generic_scheduler.go:510] demand 1: =  {%!s(float64=10772.833723653397) %!s(float64=3.221225472e+09) %!s(float64=0.468384074941452)}
I0323 19:36:38.997215       1 generic_scheduler.go:690] shares [%!s(*schedulercache.Resource=&{46000 27477053276 2 0 0 map[]}) %!s(*schedulercache.Resource=&{46000 13754632765 2 0 0 map[]})]
I0323 19:36:38.997235       1 generic_scheduler.go:591] demand.MilliCPU: 23000, currentUsage.MilliCPU 25000, share.MilliCPU 46000
I0323 19:36:38.997244       1 generic_scheduler.go:692] Rejected pod: user1-3 podDemand &{%!s(int64=23000) %!s(int64=3221225472) %!s(int64=0) %!s(int64=0) %!s(int=0) map[]} usage &{%!s(int64=25000) %!s(int64=9663676416) %!s(int64=2) %!s(int64=0) %!s(int=0) map[]} share[1]&{%!s(int64=46000) %!s(int64=13754632765) %!s(int64=2) %!s(int64=0) %!s(int=0) map[]}
I0323 19:36:46.086488       1 factory.go:1068] [tanle] Next Pod user2-7
I0323 19:36:46.086725       1 generic_scheduler.go:510] demand 0: =  {%!s(float64=5392.731535756154) %!s(float64=3.221225472e+09) %!s(float64=0.23446658851113714)}
I0323 19:36:46.086757       1 generic_scheduler.go:510] demand 1: =  {%!s(float64=10772.833723653397) %!s(float64=3.221225472e+09) %!s(float64=0.468384074941452)}
I0323 19:36:46.086773       1 generic_scheduler.go:690] shares [%!s(*schedulercache.Resource=&{46000 27477053276 2 0 0 map[]}) %!s(*schedulercache.Resource=&{46000 13754632765 2 0 0 map[]})]
I0323 19:36:46.086793       1 generic_scheduler.go:591] demand.MilliCPU: 23000, currentUsage.MilliCPU 24000, share.MilliCPU 46000
I0323 19:36:46.086800       1 generic_scheduler.go:692] Rejected pod: user2-7 podDemand &{%!s(int64=23000) %!s(int64=3221225472) %!s(int64=0) %!s(int64=0) %!s(int=0) map[]} usage &{%!s(int64=24000) %!s(int64=6442450944) %!s(int64=1) %!s(int64=0) %!s(int=0) map[]} share[1]&{%!s(int64=46000) %!s(int64=13754632765) %!s(int64=2) %!s(int64=0) %!s(int=0) map[]}
I0323 19:36:48.493178       1 factory.go:1068] [tanle] Next Pod user1-5
I0323 19:36:48.493370       1 generic_scheduler.go:510] demand 0: =  {%!s(float64=5392.731535756154) %!s(float64=3.221225472e+09) %!s(float64=0.23446658851113714)}
I0323 19:36:48.493411       1 generic_scheduler.go:510] demand 1: =  {%!s(float64=10772.833723653397) %!s(float64=3.221225472e+09) %!s(float64=0.468384074941452)}
I0323 19:36:48.493429       1 generic_scheduler.go:690] shares [%!s(*schedulercache.Resource=&{46000 27477053276 2 0 0 map[]}) %!s(*schedulercache.Resource=&{46000 13754632765 2 0 0 map[]})]
I0323 19:36:48.493452       1 generic_scheduler.go:695] Admitted pod: user1-5 podDemand &{%!s(int64=1000) %!s(int64=3221225472) %!s(int64=1) %!s(int64=0) %!s(int=0) map[]} usage &{%!s(int64=24000) %!s(int64=6442450944) %!s(int64=1) %!s(int64=0) %!s(int=0) map[]}
I0323 19:37:09.537452       1 factory.go:1068] [tanle] Next Pod user2-3
I0323 19:37:09.537620       1 generic_scheduler.go:510] demand 0: =  {%!s(float64=5392.731535756154) %!s(float64=3.221225472e+09) %!s(float64=0.23446658851113714)}
I0323 19:37:09.537660       1 generic_scheduler.go:510] demand 1: =  {%!s(float64=10772.833723653397) %!s(float64=3.221225472e+09) %!s(float64=0.468384074941452)}
I0323 19:37:09.537681       1 generic_scheduler.go:690] shares [%!s(*schedulercache.Resource=&{46000 27477053276 2 0 0 map[]}) %!s(*schedulercache.Resource=&{46000 13754632765 2 0 0 map[]})]
I0323 19:37:09.537709       1 generic_scheduler.go:591] demand.MilliCPU: 23000, currentUsage.MilliCPU 24000, share.MilliCPU 46000
I0323 19:37:09.537721       1 generic_scheduler.go:692] Rejected pod: user2-3 podDemand &{%!s(int64=23000) %!s(int64=3221225472) %!s(int64=0) %!s(int64=0) %!s(int=0) map[]} usage &{%!s(int64=24000) %!s(int64=6442450944) %!s(int64=1) %!s(int64=0) %!s(int=0) map[]} share[1]&{%!s(int64=46000) %!s(int64=13754632765) %!s(int64=2) %!s(int64=0) %!s(int=0) map[]}
I0323 19:37:10.999820       1 factory.go:1068] [tanle] Next Pod user1-3
I0323 19:37:11.000016       1 generic_scheduler.go:510] demand 0: =  {%!s(float64=5392.731535756154) %!s(float64=3.221225472e+09) %!s(float64=0.23446658851113714)}
I0323 19:37:11.000056       1 generic_scheduler.go:510] demand 1: =  {%!s(float64=10772.833723653397) %!s(float64=3.221225472e+09) %!s(float64=0.468384074941452)}
I0323 19:37:11.000077       1 generic_scheduler.go:690] shares [%!s(*schedulercache.Resource=&{46000 27477053276 2 0 0 map[]}) %!s(*schedulercache.Resource=&{46000 13754632765 2 0 0 map[]})]
I0323 19:37:11.000099       1 generic_scheduler.go:591] demand.MilliCPU: 23000, currentUsage.MilliCPU 25000, share.MilliCPU 46000
I0323 19:37:11.000110       1 generic_scheduler.go:692] Rejected pod: user1-3 podDemand &{%!s(int64=23000) %!s(int64=3221225472) %!s(int64=0) %!s(int64=0) %!s(int=0) map[]} usage &{%!s(int64=25000) %!s(int64=9663676416) %!s(int64=2) %!s(int64=0) %!s(int=0) map[]} share[1]&{%!s(int64=46000) %!s(int64=13754632765) %!s(int64=2) %!s(int64=0) %!s(int=0) map[]}
I0323 19:37:18.089576       1 factory.go:1068] [tanle] Next Pod user2-7
I0323 19:37:18.089732       1 generic_scheduler.go:510] demand 0: =  {%!s(float64=5392.731535756154) %!s(float64=3.221225472e+09) %!s(float64=0.23446658851113714)}
I0323 19:37:18.089768       1 generic_scheduler.go:510] demand 1: =  {%!s(float64=10772.833723653397) %!s(float64=3.221225472e+09) %!s(float64=0.468384074941452)}
I0323 19:37:18.089786       1 generic_scheduler.go:690] shares [%!s(*schedulercache.Resource=&{46000 27477053276 2 0 0 map[]}) %!s(*schedulercache.Resource=&{46000 13754632765 2 0 0 map[]})]
I0323 19:37:18.089808       1 generic_scheduler.go:591] demand.MilliCPU: 23000, currentUsage.MilliCPU 24000, share.MilliCPU 46000
I0323 19:37:18.089819       1 generic_scheduler.go:692] Rejected pod: user2-7 podDemand &{%!s(int64=23000) %!s(int64=3221225472) %!s(int64=0) %!s(int64=0) %!s(int=0) map[]} usage &{%!s(int64=24000) %!s(int64=6442450944) %!s(int64=1) %!s(int64=0) %!s(int=0) map[]} share[1]&{%!s(int64=46000) %!s(int64=13754632765) %!s(int64=2) %!s(int64=0) %!s(int=0) map[]}
I0323 19:38:01.058938       1 factory.go:1068] [tanle] Next Pod user2-8
I0323 19:38:01.059153       1 generic_scheduler.go:510] demand 0: =  {%!s(float64=5392.731535756154) %!s(float64=3.221225472e+09) %!s(float64=0.23446658851113714)}
I0323 19:38:01.059197       1 generic_scheduler.go:510] demand 1: =  {%!s(float64=10772.833723653397) %!s(float64=3.221225472e+09) %!s(float64=0.468384074941452)}
I0323 19:38:01.059215       1 generic_scheduler.go:690] shares [%!s(*schedulercache.Resource=&{46000 27477053276 2 0 0 map[]}) %!s(*schedulercache.Resource=&{46000 13754632765 2 0 0 map[]})]
I0323 19:38:01.059241       1 generic_scheduler.go:695] Admitted pod: user2-8 podDemand &{%!s(int64=1000) %!s(int64=3221225472) %!s(int64=1) %!s(int64=0) %!s(int=0) map[]} usage &{%!s(int64=24000) %!s(int64=6442450944) %!s(int64=1) %!s(int64=0) %!s(int=0) map[]}
I0323 19:38:01.074678       1 factory.go:1068] [tanle] Next Pod user2-9
I0323 19:38:01.074803       1 generic_scheduler.go:510] demand 0: =  {%!s(float64=5392.731535756154) %!s(float64=3.221225472e+09) %!s(float64=0.23446658851113714)}
I0323 19:38:01.074836       1 generic_scheduler.go:510] demand 1: =  {%!s(float64=10772.833723653397) %!s(float64=3.221225472e+09) %!s(float64=0.468384074941452)}
I0323 19:38:01.074856       1 generic_scheduler.go:690] shares [%!s(*schedulercache.Resource=&{46000 27477053276 2 0 0 map[]}) %!s(*schedulercache.Resource=&{46000 13754632765 2 0 0 map[]})]
I0323 19:38:01.074912       1 generic_scheduler.go:692] Rejected pod: user2-9 podDemand &{%!s(int64=1000) %!s(int64=3221225472) %!s(int64=1) %!s(int64=0) %!s(int=0) map[]} usage &{%!s(int64=25000) %!s(int64=9663676416) %!s(int64=2) %!s(int64=0) %!s(int=0) map[]} share[1]&{%!s(int64=46000) %!s(int64=13754632765) %!s(int64=2) %!s(int64=0) %!s(int=0) map[]}
I0323 19:38:01.250761       1 factory.go:1068] [tanle] Next Pod user2-9
I0323 19:38:01.250965       1 generic_scheduler.go:510] demand 0: =  {%!s(float64=5392.731535756154) %!s(float64=3.221225472e+09) %!s(float64=0.23446658851113714)}
I0323 19:38:01.251008       1 generic_scheduler.go:510] demand 1: =  {%!s(float64=10772.833723653397) %!s(float64=3.221225472e+09) %!s(float64=0.468384074941452)}
I0323 19:38:01.251029       1 generic_scheduler.go:690] shares [%!s(*schedulercache.Resource=&{46000 27477053276 2 0 0 map[]}) %!s(*schedulercache.Resource=&{46000 13754632765 2 0 0 map[]})]
I0323 19:38:01.251061       1 generic_scheduler.go:692] Rejected pod: user2-9 podDemand &{%!s(int64=1000) %!s(int64=3221225472) %!s(int64=1) %!s(int64=0) %!s(int=0) map[]} usage &{%!s(int64=25000) %!s(int64=9663676416) %!s(int64=2) %!s(int64=0) %!s(int=0) map[]} share[1]&{%!s(int64=46000) %!s(int64=13754632765) %!s(int64=2) %!s(int64=0) %!s(int=0) map[]}
W0323 19:38:01.251218       1 factory.go:1226] Request for pod user2/user2-9 already in flight, abandoning
I0323 19:38:02.077680       1 factory.go:1068] [tanle] Next Pod user2-9
I0323 19:38:02.077869       1 generic_scheduler.go:510] demand 0: =  {%!s(float64=5392.731535756154) %!s(float64=3.221225472e+09) %!s(float64=0.23446658851113714)}
I0323 19:38:02.077920       1 generic_scheduler.go:510] demand 1: =  {%!s(float64=10772.833723653397) %!s(float64=3.221225472e+09) %!s(float64=0.468384074941452)}
I0323 19:38:02.077940       1 generic_scheduler.go:690] shares [%!s(*schedulercache.Resource=&{46000 27477053276 2 0 0 map[]}) %!s(*schedulercache.Resource=&{46000 13754632765 2 0 0 map[]})]
I0323 19:38:02.077974       1 generic_scheduler.go:695] Admitted pod: user2-9 podDemand &{%!s(int64=1000) %!s(int64=3221225472) %!s(int64=1) %!s(int64=0) %!s(int=0) map[]} usage &{%!s(int64=24000) %!s(int64=6442450944) %!s(int64=1) %!s(int64=0) %!s(int=0) map[]}
I0323 19:38:09.540620       1 factory.go:1068] [tanle] Next Pod user2-3
I0323 19:38:09.540793       1 generic_scheduler.go:510] demand 0: =  {%!s(float64=5392.731535756154) %!s(float64=3.221225472e+09) %!s(float64=0.23446658851113714)}
I0323 19:38:09.540842       1 generic_scheduler.go:510] demand 1: =  {%!s(float64=10772.833723653397) %!s(float64=3.221225472e+09) %!s(float64=0.468384074941452)}
I0323 19:38:09.540868       1 generic_scheduler.go:690] shares [%!s(*schedulercache.Resource=&{46000 27477053276 2 0 0 map[]}) %!s(*schedulercache.Resource=&{46000 13754632765 2 0 0 map[]})]
I0323 19:38:09.540897       1 generic_scheduler.go:591] demand.MilliCPU: 23000, currentUsage.MilliCPU 24000, share.MilliCPU 46000
I0323 19:38:09.540907       1 generic_scheduler.go:692] Rejected pod: user2-3 podDemand &{%!s(int64=23000) %!s(int64=3221225472) %!s(int64=0) %!s(int64=0) %!s(int=0) map[]} usage &{%!s(int64=24000) %!s(int64=6442450944) %!s(int64=1) %!s(int64=0) %!s(int=0) map[]} share[1]&{%!s(int64=46000) %!s(int64=13754632765) %!s(int64=2) %!s(int64=0) %!s(int=0) map[]}
I0323 19:38:10.544013       1 factory.go:1068] [tanle] Next Pod user2-3
I0323 19:38:10.544183       1 generic_scheduler.go:510] demand 0: =  {%!s(float64=5392.731535756154) %!s(float64=3.221225472e+09) %!s(float64=0.23446658851113714)}
I0323 19:38:10.544216       1 generic_scheduler.go:510] demand 1: =  {%!s(float64=10772.833723653397) %!s(float64=3.221225472e+09) %!s(float64=0.468384074941452)}
I0323 19:38:10.544235       1 generic_scheduler.go:690] shares [%!s(*schedulercache.Resource=&{46000 27477053276 2 0 0 map[]}) %!s(*schedulercache.Resource=&{46000 13754632765 2 0 0 map[]})]
I0323 19:38:10.544262       1 generic_scheduler.go:591] demand.MilliCPU: 23000, currentUsage.MilliCPU 24000, share.MilliCPU 46000
I0323 19:38:10.544273       1 generic_scheduler.go:692] Rejected pod: user2-3 podDemand &{%!s(int64=23000) %!s(int64=3221225472) %!s(int64=0) %!s(int64=0) %!s(int=0) map[]} usage &{%!s(int64=24000) %!s(int64=6442450944) %!s(int64=1) %!s(int64=0) %!s(int=0) map[]} share[1]&{%!s(int64=46000) %!s(int64=13754632765) %!s(int64=2) %!s(int64=0) %!s(int=0) map[]}
I0323 19:38:11.003112       1 factory.go:1068] [tanle] Next Pod user1-3
I0323 19:38:11.003259       1 generic_scheduler.go:510] demand 0: =  {%!s(float64=5392.731535756154) %!s(float64=3.221225472e+09) %!s(float64=0.23446658851113714)}
I0323 19:38:11.003298       1 generic_scheduler.go:510] demand 1: =  {%!s(float64=10772.833723653397) %!s(float64=3.221225472e+09) %!s(float64=0.468384074941452)}
I0323 19:38:11.003316       1 generic_scheduler.go:690] shares [%!s(*schedulercache.Resource=&{46000 27477053276 2 0 0 map[]}) %!s(*schedulercache.Resource=&{46000 13754632765 2 0 0 map[]})]
I0323 19:38:11.003337       1 generic_scheduler.go:591] demand.MilliCPU: 23000, currentUsage.MilliCPU 25000, share.MilliCPU 46000
I0323 19:38:11.003351       1 generic_scheduler.go:692] Rejected pod: user1-3 podDemand &{%!s(int64=23000) %!s(int64=3221225472) %!s(int64=0) %!s(int64=0) %!s(int=0) map[]} usage &{%!s(int64=25000) %!s(int64=9663676416) %!s(int64=2) %!s(int64=0) %!s(int=0) map[]} share[1]&{%!s(int64=46000) %!s(int64=13754632765) %!s(int64=2) %!s(int64=0) %!s(int=0) map[]}
I0323 19:38:12.007870       1 factory.go:1068] [tanle] Next Pod user1-3
I0323 19:38:12.008054       1 generic_scheduler.go:510] demand 0: =  {%!s(float64=5392.731535756154) %!s(float64=3.221225472e+09) %!s(float64=0.23446658851113714)}
I0323 19:38:12.008094       1 generic_scheduler.go:510] demand 1: =  {%!s(float64=10772.833723653397) %!s(float64=3.221225472e+09) %!s(float64=0.468384074941452)}
I0323 19:38:12.008115       1 generic_scheduler.go:690] shares [%!s(*schedulercache.Resource=&{46000 27477053276 2 0 0 map[]}) %!s(*schedulercache.Resource=&{46000 13754632765 2 0 0 map[]})]
I0323 19:38:12.008140       1 generic_scheduler.go:591] demand.MilliCPU: 23000, currentUsage.MilliCPU 25000, share.MilliCPU 46000
I0323 19:38:12.008151       1 generic_scheduler.go:692] Rejected pod: user1-3 podDemand &{%!s(int64=23000) %!s(int64=3221225472) %!s(int64=0) %!s(int64=0) %!s(int=0) map[]} usage &{%!s(int64=25000) %!s(int64=9663676416) %!s(int64=2) %!s(int64=0) %!s(int=0) map[]} share[1]&{%!s(int64=46000) %!s(int64=13754632765) %!s(int64=2) %!s(int64=0) %!s(int=0) map[]}
I0323 19:38:12.546440       1 factory.go:1068] [tanle] Next Pod user2-3
I0323 19:38:12.546630       1 generic_scheduler.go:510] demand 0: =  {%!s(float64=5392.731535756154) %!s(float64=3.221225472e+09) %!s(float64=0.23446658851113714)}
I0323 19:38:12.546678       1 generic_scheduler.go:510] demand 1: =  {%!s(float64=10772.833723653397) %!s(float64=3.221225472e+09) %!s(float64=0.468384074941452)}
I0323 19:38:12.546701       1 generic_scheduler.go:690] shares [%!s(*schedulercache.Resource=&{46000 27477053276 2 0 0 map[]}) %!s(*schedulercache.Resource=&{46000 13754632765 2 0 0 map[]})]
I0323 19:38:12.546730       1 generic_scheduler.go:591] demand.MilliCPU: 23000, currentUsage.MilliCPU 24000, share.MilliCPU 46000
I0323 19:38:12.546745       1 generic_scheduler.go:692] Rejected pod: user2-3 podDemand &{%!s(int64=23000) %!s(int64=3221225472) %!s(int64=0) %!s(int64=0) %!s(int=0) map[]} usage &{%!s(int64=24000) %!s(int64=6442450944) %!s(int64=1) %!s(int64=0) %!s(int=0) map[]} share[1]&{%!s(int64=46000) %!s(int64=13754632765) %!s(int64=2) %!s(int64=0) %!s(int=0) map[]}
I0323 19:38:14.010586       1 factory.go:1068] [tanle] Next Pod user1-3
I0323 19:38:14.010727       1 generic_scheduler.go:510] demand 0: =  {%!s(float64=5392.731535756154) %!s(float64=3.221225472e+09) %!s(float64=0.23446658851113714)}
I0323 19:38:14.010759       1 generic_scheduler.go:510] demand 1: =  {%!s(float64=10772.833723653397) %!s(float64=3.221225472e+09) %!s(float64=0.468384074941452)}
I0323 19:38:14.010776       1 generic_scheduler.go:690] shares [%!s(*schedulercache.Resource=&{46000 27477053276 2 0 0 map[]}) %!s(*schedulercache.Resource=&{46000 13754632765 2 0 0 map[]})]
I0323 19:38:14.010802       1 generic_scheduler.go:591] demand.MilliCPU: 23000, currentUsage.MilliCPU 25000, share.MilliCPU 46000
I0323 19:38:14.010810       1 generic_scheduler.go:692] Rejected pod: user1-3 podDemand &{%!s(int64=23000) %!s(int64=3221225472) %!s(int64=0) %!s(int64=0) %!s(int=0) map[]} usage &{%!s(int64=25000) %!s(int64=9663676416) %!s(int64=2) %!s(int64=0) %!s(int=0) map[]} share[1]&{%!s(int64=46000) %!s(int64=13754632765) %!s(int64=2) %!s(int64=0) %!s(int=0) map[]}
I0323 19:38:16.549405       1 factory.go:1068] [tanle] Next Pod user2-3
I0323 19:38:16.549572       1 generic_scheduler.go:510] demand 0: =  {%!s(float64=5392.731535756154) %!s(float64=3.221225472e+09) %!s(float64=0.23446658851113714)}
I0323 19:38:16.549608       1 generic_scheduler.go:510] demand 1: =  {%!s(float64=10772.833723653397) %!s(float64=3.221225472e+09) %!s(float64=0.468384074941452)}
I0323 19:38:16.549626       1 generic_scheduler.go:690] shares [%!s(*schedulercache.Resource=&{46000 27477053276 2 0 0 map[]}) %!s(*schedulercache.Resource=&{46000 13754632765 2 0 0 map[]})]
I0323 19:38:16.549649       1 generic_scheduler.go:591] demand.MilliCPU: 23000, currentUsage.MilliCPU 24000, share.MilliCPU 46000
I0323 19:38:16.549661       1 generic_scheduler.go:692] Rejected pod: user2-3 podDemand &{%!s(int64=23000) %!s(int64=3221225472) %!s(int64=0) %!s(int64=0) %!s(int=0) map[]} usage &{%!s(int64=24000) %!s(int64=6442450944) %!s(int64=1) %!s(int64=0) %!s(int=0) map[]} share[1]&{%!s(int64=46000) %!s(int64=13754632765) %!s(int64=2) %!s(int64=0) %!s(int=0) map[]}
I0323 19:38:18.744523       1 factory.go:1068] [tanle] Next Pod user2-7
I0323 19:38:18.744710       1 generic_scheduler.go:510] demand 0: =  {%!s(float64=5392.731535756154) %!s(float64=3.221225472e+09) %!s(float64=0.23446658851113714)}
I0323 19:38:18.744750       1 generic_scheduler.go:510] demand 1: =  {%!s(float64=10772.833723653397) %!s(float64=3.221225472e+09) %!s(float64=0.468384074941452)}
I0323 19:38:18.744768       1 generic_scheduler.go:690] shares [%!s(*schedulercache.Resource=&{46000 27477053276 2 0 0 map[]}) %!s(*schedulercache.Resource=&{46000 13754632765 2 0 0 map[]})]
I0323 19:38:18.744789       1 generic_scheduler.go:591] demand.MilliCPU: 23000, currentUsage.MilliCPU 24000, share.MilliCPU 46000
I0323 19:38:18.744822       1 generic_scheduler.go:692] Rejected pod: user2-7 podDemand &{%!s(int64=23000) %!s(int64=3221225472) %!s(int64=0) %!s(int64=0) %!s(int=0) map[]} usage &{%!s(int64=24000) %!s(int64=6442450944) %!s(int64=1) %!s(int64=0) %!s(int=0) map[]} share[1]&{%!s(int64=46000) %!s(int64=13754632765) %!s(int64=2) %!s(int64=0) %!s(int=0) map[]}
I0323 19:38:18.744962       1 factory.go:1068] [tanle] Next Pod user1-3
I0323 19:38:18.745129       1 generic_scheduler.go:510] demand 0: =  {%!s(float64=5392.731535756154) %!s(float64=3.221225472e+09) %!s(float64=0.23446658851113714)}
I0323 19:38:18.745162       1 generic_scheduler.go:510] demand 1: =  {%!s(float64=10772.833723653397) %!s(float64=3.221225472e+09) %!s(float64=0.468384074941452)}
I0323 19:38:18.745179       1 generic_scheduler.go:690] shares [%!s(*schedulercache.Resource=&{46000 27477053276 2 0 0 map[]}) %!s(*schedulercache.Resource=&{46000 13754632765 2 0 0 map[]})]
I0323 19:38:18.745204       1 generic_scheduler.go:591] demand.MilliCPU: 23000, currentUsage.MilliCPU 25000, share.MilliCPU 46000
I0323 19:38:18.745214       1 generic_scheduler.go:692] Rejected pod: user1-3 podDemand &{%!s(int64=23000) %!s(int64=3221225472) %!s(int64=0) %!s(int64=0) %!s(int=0) map[]} usage &{%!s(int64=25000) %!s(int64=9663676416) %!s(int64=2) %!s(int64=0) %!s(int=0) map[]} share[1]&{%!s(int64=46000) %!s(int64=13754632765) %!s(int64=2) %!s(int64=0) %!s(int=0) map[]}
I0323 19:38:19.746938       1 factory.go:1068] [tanle] Next Pod user2-7
I0323 19:38:19.747119       1 generic_scheduler.go:510] demand 0: =  {%!s(float64=5392.731535756154) %!s(float64=3.221225472e+09) %!s(float64=0.23446658851113714)}
I0323 19:38:19.747160       1 generic_scheduler.go:510] demand 1: =  {%!s(float64=10772.833723653397) %!s(float64=3.221225472e+09) %!s(float64=0.468384074941452)}
I0323 19:38:19.747178       1 generic_scheduler.go:690] shares [%!s(*schedulercache.Resource=&{46000 27477053276 2 0 0 map[]}) %!s(*schedulercache.Resource=&{46000 13754632765 2 0 0 map[]})]
I0323 19:38:19.747203       1 generic_scheduler.go:591] demand.MilliCPU: 23000, currentUsage.MilliCPU 24000, share.MilliCPU 46000
I0323 19:38:19.747215       1 generic_scheduler.go:692] Rejected pod: user2-7 podDemand &{%!s(int64=23000) %!s(int64=3221225472) %!s(int64=0) %!s(int64=0) %!s(int=0) map[]} usage &{%!s(int64=24000) %!s(int64=6442450944) %!s(int64=1) %!s(int64=0) %!s(int=0) map[]} share[1]&{%!s(int64=46000) %!s(int64=13754632765) %!s(int64=2) %!s(int64=0) %!s(int=0) map[]}
I0323 19:38:21.749722       1 factory.go:1068] [tanle] Next Pod user2-7
I0323 19:38:21.749872       1 generic_scheduler.go:510] demand 0: =  {%!s(float64=5392.731535756154) %!s(float64=3.221225472e+09) %!s(float64=0.23446658851113714)}
I0323 19:38:21.749910       1 generic_scheduler.go:510] demand 1: =  {%!s(float64=10772.833723653397) %!s(float64=3.221225472e+09) %!s(float64=0.468384074941452)}
I0323 19:38:21.749925       1 generic_scheduler.go:690] shares [%!s(*schedulercache.Resource=&{46000 27477053276 2 0 0 map[]}) %!s(*schedulercache.Resource=&{46000 13754632765 2 0 0 map[]})]
I0323 19:38:21.749942       1 generic_scheduler.go:591] demand.MilliCPU: 23000, currentUsage.MilliCPU 24000, share.MilliCPU 46000
I0323 19:38:21.749949       1 generic_scheduler.go:692] Rejected pod: user2-7 podDemand &{%!s(int64=23000) %!s(int64=3221225472) %!s(int64=0) %!s(int64=0) %!s(int=0) map[]} usage &{%!s(int64=24000) %!s(int64=6442450944) %!s(int64=1) %!s(int64=0) %!s(int=0) map[]} share[1]&{%!s(int64=46000) %!s(int64=13754632765) %!s(int64=2) %!s(int64=0) %!s(int=0) map[]}
I0323 19:38:24.556262       1 factory.go:1068] [tanle] Next Pod user2-3
I0323 19:38:24.556563       1 generic_scheduler.go:510] demand 0: =  {%!s(float64=5392.731535756154) %!s(float64=3.221225472e+09) %!s(float64=0.23446658851113714)}
I0323 19:38:24.556607       1 generic_scheduler.go:510] demand 1: =  {%!s(float64=10772.833723653397) %!s(float64=3.221225472e+09) %!s(float64=0.468384074941452)}
I0323 19:38:24.556623       1 generic_scheduler.go:690] shares [%!s(*schedulercache.Resource=&{46000 27477053276 2 0 0 map[]}) %!s(*schedulercache.Resource=&{46000 13754632765 2 0 0 map[]})]
I0323 19:38:24.556640       1 generic_scheduler.go:591] demand.MilliCPU: 23000, currentUsage.MilliCPU 24000, share.MilliCPU 46000
I0323 19:38:24.556647       1 generic_scheduler.go:692] Rejected pod: user2-3 podDemand &{%!s(int64=23000) %!s(int64=3221225472) %!s(int64=0) %!s(int64=0) %!s(int=0) map[]} usage &{%!s(int64=24000) %!s(int64=6442450944) %!s(int64=1) %!s(int64=0) %!s(int=0) map[]} share[1]&{%!s(int64=46000) %!s(int64=13754632765) %!s(int64=2) %!s(int64=0) %!s(int=0) map[]}
I0323 19:38:25.752394       1 factory.go:1068] [tanle] Next Pod user2-7
I0323 19:38:25.752552       1 generic_scheduler.go:510] demand 0: =  {%!s(float64=5392.731535756154) %!s(float64=3.221225472e+09) %!s(float64=0.23446658851113714)}
I0323 19:38:25.752590       1 generic_scheduler.go:510] demand 1: =  {%!s(float64=10772.833723653397) %!s(float64=3.221225472e+09) %!s(float64=0.468384074941452)}
I0323 19:38:25.752606       1 generic_scheduler.go:690] shares [%!s(*schedulercache.Resource=&{46000 27477053276 2 0 0 map[]}) %!s(*schedulercache.Resource=&{46000 13754632765 2 0 0 map[]})]
I0323 19:38:25.752629       1 generic_scheduler.go:591] demand.MilliCPU: 23000, currentUsage.MilliCPU 24000, share.MilliCPU 46000
I0323 19:38:25.752640       1 generic_scheduler.go:692] Rejected pod: user2-7 podDemand &{%!s(int64=23000) %!s(int64=3221225472) %!s(int64=0) %!s(int64=0) %!s(int=0) map[]} usage &{%!s(int64=24000) %!s(int64=6442450944) %!s(int64=1) %!s(int64=0) %!s(int=0) map[]} share[1]&{%!s(int64=46000) %!s(int64=13754632765) %!s(int64=2) %!s(int64=0) %!s(int=0) map[]}
I0323 19:38:26.748077       1 factory.go:1068] [tanle] Next Pod user1-3
I0323 19:38:26.748301       1 generic_scheduler.go:510] demand 0: =  {%!s(float64=5392.731535756154) %!s(float64=3.221225472e+09) %!s(float64=0.23446658851113714)}
I0323 19:38:26.748334       1 generic_scheduler.go:510] demand 1: =  {%!s(float64=10772.833723653397) %!s(float64=3.221225472e+09) %!s(float64=0.468384074941452)}
I0323 19:38:26.748354       1 generic_scheduler.go:690] shares [%!s(*schedulercache.Resource=&{46000 27477053276 2 0 0 map[]}) %!s(*schedulercache.Resource=&{46000 13754632765 2 0 0 map[]})]
I0323 19:38:26.748382       1 generic_scheduler.go:591] demand.MilliCPU: 23000, currentUsage.MilliCPU 25000, share.MilliCPU 46000
I0323 19:38:26.748392       1 generic_scheduler.go:692] Rejected pod: user1-3 podDemand &{%!s(int64=23000) %!s(int64=3221225472) %!s(int64=0) %!s(int64=0) %!s(int=0) map[]} usage &{%!s(int64=25000) %!s(int64=9663676416) %!s(int64=2) %!s(int64=0) %!s(int=0) map[]} share[1]&{%!s(int64=46000) %!s(int64=13754632765) %!s(int64=2) %!s(int64=0) %!s(int=0) map[]}
I0323 19:38:29.060774       1 factory.go:1068] [tanle] Next Pod user2-10
I0323 19:38:29.060905       1 generic_scheduler.go:510] demand 0: =  {%!s(float64=5392.731535756154) %!s(float64=3.221225472e+09) %!s(float64=0.23446658851113714)}
I0323 19:38:29.060938       1 generic_scheduler.go:510] demand 1: =  {%!s(float64=10772.833723653397) %!s(float64=3.221225472e+09) %!s(float64=0.468384074941452)}
I0323 19:38:29.060958       1 generic_scheduler.go:690] shares [%!s(*schedulercache.Resource=&{46000 27477053276 2 0 0 map[]}) %!s(*schedulercache.Resource=&{46000 13754632765 2 0 0 map[]})]
I0323 19:38:29.060978       1 generic_scheduler.go:591] demand.MilliCPU: 23000, currentUsage.MilliCPU 24000, share.MilliCPU 46000
I0323 19:38:29.060985       1 generic_scheduler.go:692] Rejected pod: user2-10 podDemand &{%!s(int64=23000) %!s(int64=3221225472) %!s(int64=0) %!s(int64=0) %!s(int=0) map[]} usage &{%!s(int64=24000) %!s(int64=6442450944) %!s(int64=1) %!s(int64=0) %!s(int=0) map[]} share[1]&{%!s(int64=46000) %!s(int64=13754632765) %!s(int64=2) %!s(int64=0) %!s(int=0) map[]}
I0323 19:38:29.084161       1 factory.go:1068] [tanle] Next Pod user2-10
I0323 19:38:29.084360       1 generic_scheduler.go:510] demand 0: =  {%!s(float64=5392.731535756154) %!s(float64=3.221225472e+09) %!s(float64=0.23446658851113714)}
I0323 19:38:29.084399       1 generic_scheduler.go:510] demand 1: =  {%!s(float64=10772.833723653397) %!s(float64=3.221225472e+09) %!s(float64=0.468384074941452)}
I0323 19:38:29.084419       1 generic_scheduler.go:690] shares [%!s(*schedulercache.Resource=&{46000 27477053276 2 0 0 map[]}) %!s(*schedulercache.Resource=&{46000 13754632765 2 0 0 map[]})]
I0323 19:38:29.084445       1 generic_scheduler.go:591] demand.MilliCPU: 23000, currentUsage.MilliCPU 24000, share.MilliCPU 46000
I0323 19:38:29.084458       1 generic_scheduler.go:692] Rejected pod: user2-10 podDemand &{%!s(int64=23000) %!s(int64=3221225472) %!s(int64=0) %!s(int64=0) %!s(int=0) map[]} usage &{%!s(int64=24000) %!s(int64=6442450944) %!s(int64=1) %!s(int64=0) %!s(int=0) map[]} share[1]&{%!s(int64=46000) %!s(int64=13754632765) %!s(int64=2) %!s(int64=0) %!s(int=0) map[]}
W0323 19:38:29.084589       1 factory.go:1226] Request for pod user2/user2-10 already in flight, abandoning
I0323 19:38:29.084604       1 factory.go:1068] [tanle] Next Pod user2-11
I0323 19:38:29.084692       1 generic_scheduler.go:510] demand 0: =  {%!s(float64=5392.731535756154) %!s(float64=3.221225472e+09) %!s(float64=0.23446658851113714)}
I0323 19:38:29.084720       1 generic_scheduler.go:510] demand 1: =  {%!s(float64=10772.833723653397) %!s(float64=3.221225472e+09) %!s(float64=0.468384074941452)}
I0323 19:38:29.084741       1 generic_scheduler.go:690] shares [%!s(*schedulercache.Resource=&{46000 27477053276 2 0 0 map[]}) %!s(*schedulercache.Resource=&{46000 13754632765 2 0 0 map[]})]
I0323 19:38:29.084764       1 generic_scheduler.go:591] demand.MilliCPU: 23000, currentUsage.MilliCPU 24000, share.MilliCPU 46000
I0323 19:38:29.084776       1 generic_scheduler.go:692] Rejected pod: user2-11 podDemand &{%!s(int64=23000) %!s(int64=3221225472) %!s(int64=0) %!s(int64=0) %!s(int=0) map[]} usage &{%!s(int64=24000) %!s(int64=6442450944) %!s(int64=1) %!s(int64=0) %!s(int=0) map[]} share[1]&{%!s(int64=46000) %!s(int64=13754632765) %!s(int64=2) %!s(int64=0) %!s(int=0) map[]}
I0323 19:38:29.095742       1 factory.go:1068] [tanle] Next Pod user2-11
I0323 19:38:29.096008       1 generic_scheduler.go:510] demand 0: =  {%!s(float64=5392.731535756154) %!s(float64=3.221225472e+09) %!s(float64=0.23446658851113714)}
I0323 19:38:29.096043       1 generic_scheduler.go:510] demand 1: =  {%!s(float64=10772.833723653397) %!s(float64=3.221225472e+09) %!s(float64=0.468384074941452)}
I0323 19:38:29.096059       1 generic_scheduler.go:690] shares [%!s(*schedulercache.Resource=&{46000 27477053276 2 0 0 map[]}) %!s(*schedulercache.Resource=&{46000 13754632765 2 0 0 map[]})]
I0323 19:38:29.096080       1 generic_scheduler.go:591] demand.MilliCPU: 23000, currentUsage.MilliCPU 24000, share.MilliCPU 46000
I0323 19:38:29.096091       1 generic_scheduler.go:692] Rejected pod: user2-11 podDemand &{%!s(int64=23000) %!s(int64=3221225472) %!s(int64=0) %!s(int64=0) %!s(int=0) map[]} usage &{%!s(int64=24000) %!s(int64=6442450944) %!s(int64=1) %!s(int64=0) %!s(int=0) map[]} share[1]&{%!s(int64=46000) %!s(int64=13754632765) %!s(int64=2) %!s(int64=0) %!s(int=0) map[]}
W0323 19:38:29.096250       1 factory.go:1226] Request for pod user2/user2-11 already in flight, abandoning
I0323 19:38:30.063891       1 factory.go:1068] [tanle] Next Pod user2-10
I0323 19:38:30.064076       1 generic_scheduler.go:510] demand 0: =  {%!s(float64=5392.731535756154) %!s(float64=3.221225472e+09) %!s(float64=0.23446658851113714)}
I0323 19:38:30.064117       1 generic_scheduler.go:510] demand 1: =  {%!s(float64=10772.833723653397) %!s(float64=3.221225472e+09) %!s(float64=0.468384074941452)}
I0323 19:38:30.064140       1 generic_scheduler.go:690] shares [%!s(*schedulercache.Resource=&{46000 27477053276 2 0 0 map[]}) %!s(*schedulercache.Resource=&{46000 13754632765 2 0 0 map[]})]
I0323 19:38:30.064169       1 generic_scheduler.go:591] demand.MilliCPU: 23000, currentUsage.MilliCPU 24000, share.MilliCPU 46000
I0323 19:38:30.064181       1 generic_scheduler.go:692] Rejected pod: user2-10 podDemand &{%!s(int64=23000) %!s(int64=3221225472) %!s(int64=0) %!s(int64=0) %!s(int=0) map[]} usage &{%!s(int64=24000) %!s(int64=6442450944) %!s(int64=1) %!s(int64=0) %!s(int=0) map[]} share[1]&{%!s(int64=46000) %!s(int64=13754632765) %!s(int64=2) %!s(int64=0) %!s(int=0) map[]}
I0323 19:38:30.087159       1 factory.go:1068] [tanle] Next Pod user2-11
I0323 19:38:30.087355       1 generic_scheduler.go:510] demand 0: =  {%!s(float64=5392.731535756154) %!s(float64=3.221225472e+09) %!s(float64=0.23446658851113714)}
I0323 19:38:30.087387       1 generic_scheduler.go:510] demand 1: =  {%!s(float64=10772.833723653397) %!s(float64=3.221225472e+09) %!s(float64=0.468384074941452)}
I0323 19:38:30.087402       1 generic_scheduler.go:690] shares [%!s(*schedulercache.Resource=&{46000 27477053276 2 0 0 map[]}) %!s(*schedulercache.Resource=&{46000 13754632765 2 0 0 map[]})]
I0323 19:38:30.087422       1 generic_scheduler.go:591] demand.MilliCPU: 23000, currentUsage.MilliCPU 24000, share.MilliCPU 46000
I0323 19:38:30.087430       1 generic_scheduler.go:692] Rejected pod: user2-11 podDemand &{%!s(int64=23000) %!s(int64=3221225472) %!s(int64=0) %!s(int64=0) %!s(int=0) map[]} usage &{%!s(int64=24000) %!s(int64=6442450944) %!s(int64=1) %!s(int64=0) %!s(int=0) map[]} share[1]&{%!s(int64=46000) %!s(int64=13754632765) %!s(int64=2) %!s(int64=0) %!s(int=0) map[]}
I0323 19:38:32.067015       1 factory.go:1068] [tanle] Next Pod user2-10
I0323 19:38:32.067194       1 generic_scheduler.go:510] demand 0: =  {%!s(float64=5392.731535756154) %!s(float64=3.221225472e+09) %!s(float64=0.23446658851113714)}
I0323 19:38:32.067237       1 generic_scheduler.go:510] demand 1: =  {%!s(float64=10772.833723653397) %!s(float64=3.221225472e+09) %!s(float64=0.468384074941452)}
I0323 19:38:32.067259       1 generic_scheduler.go:690] shares [%!s(*schedulercache.Resource=&{46000 27477053276 2 0 0 map[]}) %!s(*schedulercache.Resource=&{46000 13754632765 2 0 0 map[]})]
I0323 19:38:32.067289       1 generic_scheduler.go:591] demand.MilliCPU: 23000, currentUsage.MilliCPU 24000, share.MilliCPU 46000
I0323 19:38:32.067303       1 generic_scheduler.go:692] Rejected pod: user2-10 podDemand &{%!s(int64=23000) %!s(int64=3221225472) %!s(int64=0) %!s(int64=0) %!s(int=0) map[]} usage &{%!s(int64=24000) %!s(int64=6442450944) %!s(int64=1) %!s(int64=0) %!s(int=0) map[]} share[1]&{%!s(int64=46000) %!s(int64=13754632765) %!s(int64=2) %!s(int64=0) %!s(int=0) map[]}
I0323 19:38:32.261368       1 factory.go:1068] [tanle] Next Pod user2-11
I0323 19:38:32.261531       1 generic_scheduler.go:510] demand 0: =  {%!s(float64=5392.731535756154) %!s(float64=3.221225472e+09) %!s(float64=0.23446658851113714)}
I0323 19:38:32.261574       1 generic_scheduler.go:510] demand 1: =  {%!s(float64=10772.833723653397) %!s(float64=3.221225472e+09) %!s(float64=0.468384074941452)}
I0323 19:38:32.261593       1 generic_scheduler.go:690] shares [%!s(*schedulercache.Resource=&{46000 27477053276 2 0 0 map[]}) %!s(*schedulercache.Resource=&{46000 13754632765 2 0 0 map[]})]
I0323 19:38:32.261621       1 generic_scheduler.go:591] demand.MilliCPU: 23000, currentUsage.MilliCPU 24000, share.MilliCPU 46000
I0323 19:38:32.261634       1 generic_scheduler.go:692] Rejected pod: user2-11 podDemand &{%!s(int64=23000) %!s(int64=3221225472) %!s(int64=0) %!s(int64=0) %!s(int=0) map[]} usage &{%!s(int64=24000) %!s(int64=6442450944) %!s(int64=1) %!s(int64=0) %!s(int=0) map[]} share[1]&{%!s(int64=46000) %!s(int64=13754632765) %!s(int64=2) %!s(int64=0) %!s(int=0) map[]}
I0323 19:38:33.755370       1 factory.go:1068] [tanle] Next Pod user2-7
I0323 19:38:33.755535       1 generic_scheduler.go:510] demand 0: =  {%!s(float64=5392.731535756154) %!s(float64=3.221225472e+09) %!s(float64=0.23446658851113714)}
I0323 19:38:33.755595       1 generic_scheduler.go:510] demand 1: =  {%!s(float64=10772.833723653397) %!s(float64=3.221225472e+09) %!s(float64=0.468384074941452)}
I0323 19:38:33.755611       1 generic_scheduler.go:690] shares [%!s(*schedulercache.Resource=&{46000 27477053276 2 0 0 map[]}) %!s(*schedulercache.Resource=&{46000 13754632765 2 0 0 map[]})]
I0323 19:38:33.755633       1 generic_scheduler.go:591] demand.MilliCPU: 23000, currentUsage.MilliCPU 24000, share.MilliCPU 46000
I0323 19:38:33.755641       1 generic_scheduler.go:692] Rejected pod: user2-7 podDemand &{%!s(int64=23000) %!s(int64=3221225472) %!s(int64=0) %!s(int64=0) %!s(int=0) map[]} usage &{%!s(int64=24000) %!s(int64=6442450944) %!s(int64=1) %!s(int64=0) %!s(int=0) map[]} share[1]&{%!s(int64=46000) %!s(int64=13754632765) %!s(int64=2) %!s(int64=0) %!s(int=0) map[]}
I0323 19:38:36.071677       1 factory.go:1068] [tanle] Next Pod user2-10
I0323 19:38:36.071848       1 generic_scheduler.go:510] demand 0: =  {%!s(float64=5392.731535756154) %!s(float64=3.221225472e+09) %!s(float64=0.23446658851113714)}
I0323 19:38:36.071885       1 generic_scheduler.go:510] demand 1: =  {%!s(float64=10772.833723653397) %!s(float64=3.221225472e+09) %!s(float64=0.468384074941452)}
I0323 19:38:36.071901       1 generic_scheduler.go:690] shares [%!s(*schedulercache.Resource=&{46000 27477053276 2 0 0 map[]}) %!s(*schedulercache.Resource=&{46000 13754632765 2 0 0 map[]})]
I0323 19:38:36.071921       1 generic_scheduler.go:591] demand.MilliCPU: 23000, currentUsage.MilliCPU 24000, share.MilliCPU 46000
I0323 19:38:36.071928       1 generic_scheduler.go:692] Rejected pod: user2-10 podDemand &{%!s(int64=23000) %!s(int64=3221225472) %!s(int64=0) %!s(int64=0) %!s(int=0) map[]} usage &{%!s(int64=24000) %!s(int64=6442450944) %!s(int64=1) %!s(int64=0) %!s(int=0) map[]} share[1]&{%!s(int64=46000) %!s(int64=13754632765) %!s(int64=2) %!s(int64=0) %!s(int=0) map[]}
I0323 19:38:36.264226       1 factory.go:1068] [tanle] Next Pod user2-11
I0323 19:38:36.264364       1 generic_scheduler.go:510] demand 0: =  {%!s(float64=5392.731535756154) %!s(float64=3.221225472e+09) %!s(float64=0.23446658851113714)}
I0323 19:38:36.264403       1 generic_scheduler.go:510] demand 1: =  {%!s(float64=10772.833723653397) %!s(float64=3.221225472e+09) %!s(float64=0.468384074941452)}
I0323 19:38:36.264430       1 generic_scheduler.go:690] shares [%!s(*schedulercache.Resource=&{46000 27477053276 2 0 0 map[]}) %!s(*schedulercache.Resource=&{46000 13754632765 2 0 0 map[]})]
I0323 19:38:36.264459       1 generic_scheduler.go:591] demand.MilliCPU: 23000, currentUsage.MilliCPU 24000, share.MilliCPU 46000
I0323 19:38:36.264481       1 generic_scheduler.go:692] Rejected pod: user2-11 podDemand &{%!s(int64=23000) %!s(int64=3221225472) %!s(int64=0) %!s(int64=0) %!s(int=0) map[]} usage &{%!s(int64=24000) %!s(int64=6442450944) %!s(int64=1) %!s(int64=0) %!s(int=0) map[]} share[1]&{%!s(int64=46000) %!s(int64=13754632765) %!s(int64=2) %!s(int64=0) %!s(int=0) map[]}
I0323 19:38:40.999358       1 factory.go:1068] [tanle] Next Pod user2-3
I0323 19:38:40.999574       1 generic_scheduler.go:510] demand 0: =  {%!s(float64=5392.731535756154) %!s(float64=3.221225472e+09) %!s(float64=0.23446658851113714)}
I0323 19:38:40.999619       1 generic_scheduler.go:510] demand 1: =  {%!s(float64=10772.833723653397) %!s(float64=3.221225472e+09) %!s(float64=0.468384074941452)}
I0323 19:38:40.999640       1 generic_scheduler.go:690] shares [%!s(*schedulercache.Resource=&{46000 27477053276 2 0 0 map[]}) %!s(*schedulercache.Resource=&{46000 13754632765 2 0 0 map[]})]
I0323 19:38:40.999668       1 generic_scheduler.go:591] demand.MilliCPU: 23000, currentUsage.MilliCPU 24000, share.MilliCPU 46000
I0323 19:38:40.999680       1 generic_scheduler.go:692] Rejected pod: user2-3 podDemand &{%!s(int64=23000) %!s(int64=3221225472) %!s(int64=0) %!s(int64=0) %!s(int=0) map[]} usage &{%!s(int64=24000) %!s(int64=6442450944) %!s(int64=1) %!s(int64=0) %!s(int=0) map[]} share[1]&{%!s(int64=46000) %!s(int64=13754632765) %!s(int64=2) %!s(int64=0) %!s(int=0) map[]}
I0323 19:38:42.750953       1 factory.go:1068] [tanle] Next Pod user1-3
I0323 19:38:42.751121       1 generic_scheduler.go:510] demand 0: =  {%!s(float64=5392.731535756154) %!s(float64=3.221225472e+09) %!s(float64=0.23446658851113714)}
I0323 19:38:42.751156       1 generic_scheduler.go:510] demand 1: =  {%!s(float64=10772.833723653397) %!s(float64=3.221225472e+09) %!s(float64=0.468384074941452)}
I0323 19:38:42.751172       1 generic_scheduler.go:690] shares [%!s(*schedulercache.Resource=&{46000 27477053276 2 0 0 map[]}) %!s(*schedulercache.Resource=&{46000 13754632765 2 0 0 map[]})]
I0323 19:38:42.751193       1 generic_scheduler.go:591] demand.MilliCPU: 23000, currentUsage.MilliCPU 25000, share.MilliCPU 46000
I0323 19:38:42.751201       1 generic_scheduler.go:692] Rejected pod: user1-3 podDemand &{%!s(int64=23000) %!s(int64=3221225472) %!s(int64=0) %!s(int64=0) %!s(int=0) map[]} usage &{%!s(int64=25000) %!s(int64=9663676416) %!s(int64=2) %!s(int64=0) %!s(int=0) map[]} share[1]&{%!s(int64=46000) %!s(int64=13754632765) %!s(int64=2) %!s(int64=0) %!s(int=0) map[]}
I0323 19:38:44.074859       1 factory.go:1068] [tanle] Next Pod user2-10
I0323 19:38:44.075068       1 generic_scheduler.go:510] demand 0: =  {%!s(float64=5392.731535756154) %!s(float64=3.221225472e+09) %!s(float64=0.23446658851113714)}
I0323 19:38:44.075099       1 generic_scheduler.go:510] demand 1: =  {%!s(float64=10772.833723653397) %!s(float64=3.221225472e+09) %!s(float64=0.468384074941452)}
I0323 19:38:44.075112       1 generic_scheduler.go:690] shares [%!s(*schedulercache.Resource=&{46000 27477053276 2 0 0 map[]}) %!s(*schedulercache.Resource=&{46000 13754632765 2 0 0 map[]})]
I0323 19:38:44.075130       1 generic_scheduler.go:591] demand.MilliCPU: 23000, currentUsage.MilliCPU 24000, share.MilliCPU 46000
I0323 19:38:44.075136       1 generic_scheduler.go:692] Rejected pod: user2-10 podDemand &{%!s(int64=23000) %!s(int64=3221225472) %!s(int64=0) %!s(int64=0) %!s(int=0) map[]} usage &{%!s(int64=24000) %!s(int64=6442450944) %!s(int64=1) %!s(int64=0) %!s(int=0) map[]} share[1]&{%!s(int64=46000) %!s(int64=13754632765) %!s(int64=2) %!s(int64=0) %!s(int=0) map[]}
I0323 19:38:44.505378       1 factory.go:1068] [tanle] Next Pod user2-11
I0323 19:38:44.505567       1 generic_scheduler.go:510] demand 0: =  {%!s(float64=5392.731535756154) %!s(float64=3.221225472e+09) %!s(float64=0.23446658851113714)}
I0323 19:38:44.505605       1 generic_scheduler.go:510] demand 1: =  {%!s(float64=10772.833723653397) %!s(float64=3.221225472e+09) %!s(float64=0.468384074941452)}
I0323 19:38:44.505626       1 generic_scheduler.go:690] shares [%!s(*schedulercache.Resource=&{46000 27477053276 2 0 0 map[]}) %!s(*schedulercache.Resource=&{46000 13754632765 2 0 0 map[]})]
I0323 19:38:44.505651       1 generic_scheduler.go:591] demand.MilliCPU: 23000, currentUsage.MilliCPU 24000, share.MilliCPU 46000
I0323 19:38:44.505672       1 generic_scheduler.go:692] Rejected pod: user2-11 podDemand &{%!s(int64=23000) %!s(int64=3221225472) %!s(int64=0) %!s(int64=0) %!s(int=0) map[]} usage &{%!s(int64=24000) %!s(int64=6442450944) %!s(int64=1) %!s(int64=0) %!s(int=0) map[]} share[1]&{%!s(int64=46000) %!s(int64=13754632765) %!s(int64=2) %!s(int64=0) %!s(int=0) map[]}
I0323 19:38:49.759554       1 factory.go:1068] [tanle] Next Pod user2-7
I0323 19:38:49.759692       1 generic_scheduler.go:510] demand 0: =  {%!s(float64=5392.731535756154) %!s(float64=3.221225472e+09) %!s(float64=0.23446658851113714)}
I0323 19:38:49.759723       1 generic_scheduler.go:510] demand 1: =  {%!s(float64=10772.833723653397) %!s(float64=3.221225472e+09) %!s(float64=0.468384074941452)}
I0323 19:38:49.759739       1 generic_scheduler.go:690] shares [%!s(*schedulercache.Resource=&{46000 27477053276 2 0 0 map[]}) %!s(*schedulercache.Resource=&{46000 13754632765 2 0 0 map[]})]
I0323 19:38:49.759759       1 generic_scheduler.go:591] demand.MilliCPU: 23000, currentUsage.MilliCPU 24000, share.MilliCPU 46000
I0323 19:38:49.759766       1 generic_scheduler.go:692] Rejected pod: user2-7 podDemand &{%!s(int64=23000) %!s(int64=3221225472) %!s(int64=0) %!s(int64=0) %!s(int=0) map[]} usage &{%!s(int64=24000) %!s(int64=6442450944) %!s(int64=1) %!s(int64=0) %!s(int=0) map[]} share[1]&{%!s(int64=46000) %!s(int64=13754632765) %!s(int64=2) %!s(int64=0) %!s(int=0) map[]}
I0323 19:39:00.078977       1 factory.go:1068] [tanle] Next Pod user2-10
I0323 19:39:00.079165       1 generic_scheduler.go:510] demand 0: =  {%!s(float64=5392.731535756154) %!s(float64=3.221225472e+09) %!s(float64=0.23446658851113714)}
I0323 19:39:00.079200       1 generic_scheduler.go:510] demand 1: =  {%!s(float64=10772.833723653397) %!s(float64=3.221225472e+09) %!s(float64=0.468384074941452)}
I0323 19:39:00.079216       1 generic_scheduler.go:690] shares [%!s(*schedulercache.Resource=&{46000 27477053276 2 0 0 map[]}) %!s(*schedulercache.Resource=&{46000 13754632765 2 0 0 map[]})]
I0323 19:39:00.079241       1 generic_scheduler.go:591] demand.MilliCPU: 23000, currentUsage.MilliCPU 24000, share.MilliCPU 46000
I0323 19:39:00.079250       1 generic_scheduler.go:692] Rejected pod: user2-10 podDemand &{%!s(int64=23000) %!s(int64=3221225472) %!s(int64=0) %!s(int64=0) %!s(int=0) map[]} usage &{%!s(int64=24000) %!s(int64=6442450944) %!s(int64=1) %!s(int64=0) %!s(int=0) map[]} share[1]&{%!s(int64=46000) %!s(int64=13754632765) %!s(int64=2) %!s(int64=0) %!s(int=0) map[]}
I0323 19:39:00.508130       1 factory.go:1068] [tanle] Next Pod user2-11
I0323 19:39:00.508310       1 generic_scheduler.go:510] demand 0: =  {%!s(float64=5392.731535756154) %!s(float64=3.221225472e+09) %!s(float64=0.23446658851113714)}
I0323 19:39:00.508348       1 generic_scheduler.go:510] demand 1: =  {%!s(float64=10772.833723653397) %!s(float64=3.221225472e+09) %!s(float64=0.468384074941452)}
I0323 19:39:00.508368       1 generic_scheduler.go:690] shares [%!s(*schedulercache.Resource=&{46000 27477053276 2 0 0 map[]}) %!s(*schedulercache.Resource=&{46000 13754632765 2 0 0 map[]})]
I0323 19:39:00.508393       1 generic_scheduler.go:591] demand.MilliCPU: 23000, currentUsage.MilliCPU 24000, share.MilliCPU 46000
I0323 19:39:00.508403       1 generic_scheduler.go:692] Rejected pod: user2-11 podDemand &{%!s(int64=23000) %!s(int64=3221225472) %!s(int64=0) %!s(int64=0) %!s(int=0) map[]} usage &{%!s(int64=24000) %!s(int64=6442450944) %!s(int64=1) %!s(int64=0) %!s(int=0) map[]} share[1]&{%!s(int64=46000) %!s(int64=13754632765) %!s(int64=2) %!s(int64=0) %!s(int=0) map[]}
I0323 19:39:02.106705       1 factory.go:1068] [tanle] Next Pod user1-6
I0323 19:39:02.106858       1 generic_scheduler.go:510] demand 0: =  {%!s(float64=5392.731535756154) %!s(float64=3.221225472e+09) %!s(float64=0.23446658851113714)}
I0323 19:39:02.106921       1 generic_scheduler.go:510] demand 1: =  {%!s(float64=10772.833723653397) %!s(float64=3.221225472e+09) %!s(float64=0.468384074941452)}
I0323 19:39:02.106942       1 generic_scheduler.go:690] shares [%!s(*schedulercache.Resource=&{46000 27477053276 2 0 0 map[]}) %!s(*schedulercache.Resource=&{46000 13754632765 2 0 0 map[]})]
I0323 19:39:02.106969       1 generic_scheduler.go:695] Admitted pod: user1-6 podDemand &{%!s(int64=1000) %!s(int64=3221225472) %!s(int64=1) %!s(int64=0) %!s(int=0) map[]} usage &{%!s(int64=24000) %!s(int64=6442450944) %!s(int64=1) %!s(int64=0) %!s(int=0) map[]}
I0323 19:39:02.141978       1 factory.go:1068] [tanle] Next Pod user1-7
I0323 19:39:02.142134       1 generic_scheduler.go:510] demand 0: =  {%!s(float64=5392.731535756154) %!s(float64=3.221225472e+09) %!s(float64=0.23446658851113714)}
I0323 19:39:02.142164       1 generic_scheduler.go:510] demand 1: =  {%!s(float64=10772.833723653397) %!s(float64=3.221225472e+09) %!s(float64=0.468384074941452)}
I0323 19:39:02.142181       1 generic_scheduler.go:690] shares [%!s(*schedulercache.Resource=&{46000 27477053276 2 0 0 map[]}) %!s(*schedulercache.Resource=&{46000 13754632765 2 0 0 map[]})]
I0323 19:39:02.142202       1 generic_scheduler.go:692] Rejected pod: user1-7 podDemand &{%!s(int64=1000) %!s(int64=3221225472) %!s(int64=1) %!s(int64=0) %!s(int=0) map[]} usage &{%!s(int64=25000) %!s(int64=9663676416) %!s(int64=2) %!s(int64=0) %!s(int=0) map[]} share[1]&{%!s(int64=46000) %!s(int64=13754632765) %!s(int64=2) %!s(int64=0) %!s(int=0) map[]}
I0323 19:39:02.147323       1 factory.go:1068] [tanle] Next Pod user1-7
I0323 19:39:02.147520       1 generic_scheduler.go:510] demand 0: =  {%!s(float64=5392.731535756154) %!s(float64=3.221225472e+09) %!s(float64=0.23446658851113714)}
I0323 19:39:02.147559       1 generic_scheduler.go:510] demand 1: =  {%!s(float64=10772.833723653397) %!s(float64=3.221225472e+09) %!s(float64=0.468384074941452)}
I0323 19:39:02.147580       1 generic_scheduler.go:690] shares [%!s(*schedulercache.Resource=&{46000 27477053276 2 0 0 map[]}) %!s(*schedulercache.Resource=&{46000 13754632765 2 0 0 map[]})]
I0323 19:39:02.147606       1 generic_scheduler.go:692] Rejected pod: user1-7 podDemand &{%!s(int64=1000) %!s(int64=3221225472) %!s(int64=1) %!s(int64=0) %!s(int=0) map[]} usage &{%!s(int64=25000) %!s(int64=9663676416) %!s(int64=2) %!s(int64=0) %!s(int=0) map[]} share[1]&{%!s(int64=46000) %!s(int64=13754632765) %!s(int64=2) %!s(int64=0) %!s(int=0) map[]}
W0323 19:39:02.147751       1 factory.go:1226] Request for pod user1/user1-7 already in flight, abandoning
I0323 19:39:03.531648       1 factory.go:1068] [tanle] Next Pod user1-7
I0323 19:39:03.531831       1 generic_scheduler.go:510] demand 0: =  {%!s(float64=5392.731535756154) %!s(float64=3.221225472e+09) %!s(float64=0.23446658851113714)}
I0323 19:39:03.531871       1 generic_scheduler.go:510] demand 1: =  {%!s(float64=10772.833723653397) %!s(float64=3.221225472e+09) %!s(float64=0.468384074941452)}
I0323 19:39:03.531897       1 generic_scheduler.go:690] shares [%!s(*schedulercache.Resource=&{46000 27477053276 2 0 0 map[]}) %!s(*schedulercache.Resource=&{46000 13754632765 2 0 0 map[]})]
I0323 19:39:03.531926       1 generic_scheduler.go:692] Rejected pod: user1-7 podDemand &{%!s(int64=1000) %!s(int64=3221225472) %!s(int64=1) %!s(int64=0) %!s(int=0) map[]} usage &{%!s(int64=25000) %!s(int64=9663676416) %!s(int64=2) %!s(int64=0) %!s(int=0) map[]} share[1]&{%!s(int64=46000) %!s(int64=13754632765) %!s(int64=2) %!s(int64=0) %!s(int=0) map[]}
I0323 19:39:05.534501       1 factory.go:1068] [tanle] Next Pod user1-7
I0323 19:39:05.534734       1 generic_scheduler.go:510] demand 0: =  {%!s(float64=5392.731535756154) %!s(float64=3.221225472e+09) %!s(float64=0.23446658851113714)}
I0323 19:39:05.534775       1 generic_scheduler.go:510] demand 1: =  {%!s(float64=10772.833723653397) %!s(float64=3.221225472e+09) %!s(float64=0.468384074941452)}
I0323 19:39:05.534795       1 generic_scheduler.go:690] shares [%!s(*schedulercache.Resource=&{46000 27477053276 2 0 0 map[]}) %!s(*schedulercache.Resource=&{46000 13754632765 2 0 0 map[]})]
I0323 19:39:05.534818       1 generic_scheduler.go:695] Admitted pod: user1-7 podDemand &{%!s(int64=1000) %!s(int64=3221225472) %!s(int64=1) %!s(int64=0) %!s(int=0) map[]} usage &{%!s(int64=24000) %!s(int64=6442450944) %!s(int64=1) %!s(int64=0) %!s(int=0) map[]}
I0323 19:39:13.021448       1 factory.go:1068] [tanle] Next Pod user2-3
I0323 19:39:13.021661       1 generic_scheduler.go:510] demand 0: =  {%!s(float64=5392.731535756154) %!s(float64=3.221225472e+09) %!s(float64=0.23446658851113714)}
I0323 19:39:13.021704       1 generic_scheduler.go:510] demand 1: =  {%!s(float64=10772.833723653397) %!s(float64=3.221225472e+09) %!s(float64=0.468384074941452)}
I0323 19:39:13.021723       1 generic_scheduler.go:690] shares [%!s(*schedulercache.Resource=&{46000 27477053276 2 0 0 map[]}) %!s(*schedulercache.Resource=&{46000 13754632765 2 0 0 map[]})]
I0323 19:39:13.021750       1 generic_scheduler.go:695] Admitted pod: user2-3 podDemand &{%!s(int64=23000) %!s(int64=3221225472) %!s(int64=0) %!s(int64=0) %!s(int=0) map[]} usage &{%!s(int64=1000) %!s(int64=3221225472) %!s(int64=1) %!s(int64=0) %!s(int=0) map[]}
I0323 19:39:14.760481       1 factory.go:1068] [tanle] Next Pod user1-3
I0323 19:39:14.760658       1 generic_scheduler.go:510] demand 0: =  {%!s(float64=5392.731535756154) %!s(float64=3.221225472e+09) %!s(float64=0.23446658851113714)}
I0323 19:39:14.760695       1 generic_scheduler.go:510] demand 1: =  {%!s(float64=10772.833723653397) %!s(float64=3.221225472e+09) %!s(float64=0.468384074941452)}
I0323 19:39:14.760714       1 generic_scheduler.go:690] shares [%!s(*schedulercache.Resource=&{46000 27477053276 2 0 0 map[]}) %!s(*schedulercache.Resource=&{46000 13754632765 2 0 0 map[]})]
I0323 19:39:14.760736       1 generic_scheduler.go:591] demand.MilliCPU: 23000, currentUsage.MilliCPU 25000, share.MilliCPU 46000
I0323 19:39:14.760755       1 generic_scheduler.go:692] Rejected pod: user1-3 podDemand &{%!s(int64=23000) %!s(int64=3221225472) %!s(int64=0) %!s(int64=0) %!s(int=0) map[]} usage &{%!s(int64=25000) %!s(int64=9663676416) %!s(int64=2) %!s(int64=0) %!s(int=0) map[]} share[1]&{%!s(int64=46000) %!s(int64=13754632765) %!s(int64=2) %!s(int64=0) %!s(int=0) map[]}
I0323 19:39:14.764010       1 factory.go:1068] [tanle] Next Pod user1-3
I0323 19:39:14.764234       1 generic_scheduler.go:510] demand 0: =  {%!s(float64=5392.731535756154) %!s(float64=3.221225472e+09) %!s(float64=0.23446658851113714)}
I0323 19:39:14.764273       1 generic_scheduler.go:510] demand 1: =  {%!s(float64=10772.833723653397) %!s(float64=3.221225472e+09) %!s(float64=0.468384074941452)}
I0323 19:39:14.764293       1 generic_scheduler.go:690] shares [%!s(*schedulercache.Resource=&{46000 27477053276 2 0 0 map[]}) %!s(*schedulercache.Resource=&{46000 13754632765 2 0 0 map[]})]
I0323 19:39:14.764315       1 generic_scheduler.go:591] demand.MilliCPU: 23000, currentUsage.MilliCPU 25000, share.MilliCPU 46000
I0323 19:39:14.764327       1 generic_scheduler.go:692] Rejected pod: user1-3 podDemand &{%!s(int64=23000) %!s(int64=3221225472) %!s(int64=0) %!s(int64=0) %!s(int=0) map[]} usage &{%!s(int64=25000) %!s(int64=9663676416) %!s(int64=2) %!s(int64=0) %!s(int=0) map[]} share[1]&{%!s(int64=46000) %!s(int64=13754632765) %!s(int64=2) %!s(int64=0) %!s(int=0) map[]}
W0323 19:39:14.764449       1 factory.go:1226] Request for pod user1/user1-3 already in flight, abandoning
I0323 19:39:21.762441       1 factory.go:1068] [tanle] Next Pod user2-7
I0323 19:39:21.762702       1 generic_scheduler.go:510] demand 0: =  {%!s(float64=5392.731535756154) %!s(float64=3.221225472e+09) %!s(float64=0.23446658851113714)}
I0323 19:39:21.762750       1 generic_scheduler.go:510] demand 1: =  {%!s(float64=10772.833723653397) %!s(float64=3.221225472e+09) %!s(float64=0.468384074941452)}
I0323 19:39:21.762791       1 generic_scheduler.go:690] shares [%!s(*schedulercache.Resource=&{46000 27477053276 2 0 0 map[]}) %!s(*schedulercache.Resource=&{46000 13754632765 2 0 0 map[]})]
I0323 19:39:21.762825       1 generic_scheduler.go:695] Admitted pod: user2-7 podDemand &{%!s(int64=23000) %!s(int64=3221225472) %!s(int64=0) %!s(int64=0) %!s(int=0) map[]} usage &{%!s(int64=23000) %!s(int64=3221225472) %!s(int64=0) %!s(int64=0) %!s(int=0) map[]}
I0323 19:39:32.082836       1 factory.go:1068] [tanle] Next Pod user2-10
I0323 19:39:32.083059       1 generic_scheduler.go:510] demand 0: =  {%!s(float64=5392.731535756154) %!s(float64=3.221225472e+09) %!s(float64=0.23446658851113714)}
I0323 19:39:32.083147       1 generic_scheduler.go:510] demand 1: =  {%!s(float64=10772.833723653397) %!s(float64=3.221225472e+09) %!s(float64=0.468384074941452)}
I0323 19:39:32.083185       1 generic_scheduler.go:690] shares [%!s(*schedulercache.Resource=&{46000 27477053276 2 0 0 map[]}) %!s(*schedulercache.Resource=&{46000 13754632765 2 0 0 map[]})]
I0323 19:39:32.083215       1 generic_scheduler.go:591] demand.MilliCPU: 23000, currentUsage.MilliCPU 46000, share.MilliCPU 46000
I0323 19:39:32.083226       1 generic_scheduler.go:692] Rejected pod: user2-10 podDemand &{%!s(int64=23000) %!s(int64=3221225472) %!s(int64=0) %!s(int64=0) %!s(int=0) map[]} usage &{%!s(int64=46000) %!s(int64=6442450944) %!s(int64=0) %!s(int64=0) %!s(int=0) map[]} share[1]&{%!s(int64=46000) %!s(int64=13754632765) %!s(int64=2) %!s(int64=0) %!s(int=0) map[]}
I0323 19:39:32.511334       1 factory.go:1068] [tanle] Next Pod user2-11
I0323 19:39:32.511738       1 generic_scheduler.go:510] demand 0: =  {%!s(float64=5392.731535756154) %!s(float64=3.221225472e+09) %!s(float64=0.23446658851113714)}
I0323 19:39:32.511838       1 generic_scheduler.go:510] demand 1: =  {%!s(float64=10772.833723653397) %!s(float64=3.221225472e+09) %!s(float64=0.468384074941452)}
I0323 19:39:32.511880       1 generic_scheduler.go:690] shares [%!s(*schedulercache.Resource=&{46000 27477053276 2 0 0 map[]}) %!s(*schedulercache.Resource=&{46000 13754632765 2 0 0 map[]})]
I0323 19:39:32.511934       1 generic_scheduler.go:591] demand.MilliCPU: 23000, currentUsage.MilliCPU 46000, share.MilliCPU 46000
I0323 19:39:32.511955       1 generic_scheduler.go:692] Rejected pod: user2-11 podDemand &{%!s(int64=23000) %!s(int64=3221225472) %!s(int64=0) %!s(int64=0) %!s(int=0) map[]} usage &{%!s(int64=46000) %!s(int64=6442450944) %!s(int64=0) %!s(int64=0) %!s(int=0) map[]} share[1]&{%!s(int64=46000) %!s(int64=13754632765) %!s(int64=2) %!s(int64=0) %!s(int=0) map[]}
I0323 19:39:56.044164       1 factory.go:1068] [tanle] Next Pod user2-13
I0323 19:39:56.044503       1 generic_scheduler.go:510] demand 0: =  {%!s(float64=5392.731535756154) %!s(float64=3.221225472e+09) %!s(float64=0.23446658851113714)}
I0323 19:39:56.044579       1 generic_scheduler.go:510] demand 1: =  {%!s(float64=10772.833723653397) %!s(float64=3.221225472e+09) %!s(float64=0.468384074941452)}
I0323 19:39:56.044598       1 generic_scheduler.go:690] shares [%!s(*schedulercache.Resource=&{46000 27477053276 2 0 0 map[]}) %!s(*schedulercache.Resource=&{46000 13754632765 2 0 0 map[]})]
I0323 19:39:56.044634       1 generic_scheduler.go:695] Admitted pod: user2-13 podDemand &{%!s(int64=1000) %!s(int64=3221225472) %!s(int64=1) %!s(int64=0) %!s(int=0) map[]} usage &{%!s(int64=46000) %!s(int64=6442450944) %!s(int64=0) %!s(int64=0) %!s(int=0) map[]}
I0323 19:39:56.076225       1 factory.go:1068] [tanle] Next Pod user2-12
I0323 19:39:56.076577       1 generic_scheduler.go:510] demand 0: =  {%!s(float64=5392.731535756154) %!s(float64=3.221225472e+09) %!s(float64=0.23446658851113714)}
I0323 19:39:56.076644       1 generic_scheduler.go:510] demand 1: =  {%!s(float64=10772.833723653397) %!s(float64=3.221225472e+09) %!s(float64=0.468384074941452)}
I0323 19:39:56.076662       1 generic_scheduler.go:690] shares [%!s(*schedulercache.Resource=&{46000 27477053276 2 0 0 map[]}) %!s(*schedulercache.Resource=&{46000 13754632765 2 0 0 map[]})]
I0323 19:39:56.076704       1 generic_scheduler.go:695] Admitted pod: user2-12 podDemand &{%!s(int64=1000) %!s(int64=3221225472) %!s(int64=1) %!s(int64=0) %!s(int=0) map[]} usage &{%!s(int64=47000) %!s(int64=9663676416) %!s(int64=1) %!s(int64=0) %!s(int=0) map[]}
I0323 19:40:14.765150       1 factory.go:1068] [tanle] Next Pod user1-3
I0323 19:40:14.765340       1 generic_scheduler.go:510] demand 0: =  {%!s(float64=5392.731535756154) %!s(float64=3.221225472e+09) %!s(float64=0.23446658851113714)}
I0323 19:40:14.765376       1 generic_scheduler.go:510] demand 1: =  {%!s(float64=10772.833723653397) %!s(float64=3.221225472e+09) %!s(float64=0.468384074941452)}
I0323 19:40:14.765390       1 generic_scheduler.go:690] shares [%!s(*schedulercache.Resource=&{46000 27477053276 2 0 0 map[]}) %!s(*schedulercache.Resource=&{46000 13754632765 2 0 0 map[]})]
I0323 19:40:14.765411       1 generic_scheduler.go:591] demand.MilliCPU: 23000, currentUsage.MilliCPU 25000, share.MilliCPU 46000
I0323 19:40:14.765420       1 generic_scheduler.go:692] Rejected pod: user1-3 podDemand &{%!s(int64=23000) %!s(int64=3221225472) %!s(int64=0) %!s(int64=0) %!s(int=0) map[]} usage &{%!s(int64=25000) %!s(int64=9663676416) %!s(int64=2) %!s(int64=0) %!s(int=0) map[]} share[1]&{%!s(int64=46000) %!s(int64=13754632765) %!s(int64=2) %!s(int64=0) %!s(int=0) map[]}
I0323 19:40:14.768120       1 factory.go:1068] [tanle] Next Pod user1-3
I0323 19:40:14.768215       1 generic_scheduler.go:510] demand 0: =  {%!s(float64=5392.731535756154) %!s(float64=3.221225472e+09) %!s(float64=0.23446658851113714)}
I0323 19:40:14.768238       1 generic_scheduler.go:510] demand 1: =  {%!s(float64=10772.833723653397) %!s(float64=3.221225472e+09) %!s(float64=0.468384074941452)}
I0323 19:40:14.768248       1 generic_scheduler.go:690] shares [%!s(*schedulercache.Resource=&{46000 27477053276 2 0 0 map[]}) %!s(*schedulercache.Resource=&{46000 13754632765 2 0 0 map[]})]
I0323 19:40:14.768263       1 generic_scheduler.go:591] demand.MilliCPU: 23000, currentUsage.MilliCPU 25000, share.MilliCPU 46000
I0323 19:40:14.768269       1 generic_scheduler.go:692] Rejected pod: user1-3 podDemand &{%!s(int64=23000) %!s(int64=3221225472) %!s(int64=0) %!s(int64=0) %!s(int=0) map[]} usage &{%!s(int64=25000) %!s(int64=9663676416) %!s(int64=2) %!s(int64=0) %!s(int=0) map[]} share[1]&{%!s(int64=46000) %!s(int64=13754632765) %!s(int64=2) %!s(int64=0) %!s(int=0) map[]}
W0323 19:40:14.768348       1 factory.go:1226] Request for pod user1/user1-3 already in flight, abandoning
I0323 19:40:15.769497       1 factory.go:1068] [tanle] Next Pod user1-3
I0323 19:40:15.769716       1 generic_scheduler.go:510] demand 0: =  {%!s(float64=5392.731535756154) %!s(float64=3.221225472e+09) %!s(float64=0.23446658851113714)}
I0323 19:40:15.769767       1 generic_scheduler.go:510] demand 1: =  {%!s(float64=10772.833723653397) %!s(float64=3.221225472e+09) %!s(float64=0.468384074941452)}
I0323 19:40:15.769799       1 generic_scheduler.go:690] shares [%!s(*schedulercache.Resource=&{46000 27477053276 2 0 0 map[]}) %!s(*schedulercache.Resource=&{46000 13754632765 2 0 0 map[]})]
I0323 19:40:15.769837       1 generic_scheduler.go:591] demand.MilliCPU: 23000, currentUsage.MilliCPU 25000, share.MilliCPU 46000
I0323 19:40:15.769852       1 generic_scheduler.go:692] Rejected pod: user1-3 podDemand &{%!s(int64=23000) %!s(int64=3221225472) %!s(int64=0) %!s(int64=0) %!s(int=0) map[]} usage &{%!s(int64=25000) %!s(int64=9663676416) %!s(int64=2) %!s(int64=0) %!s(int=0) map[]} share[1]&{%!s(int64=46000) %!s(int64=13754632765) %!s(int64=2) %!s(int64=0) %!s(int=0) map[]}
I0323 19:40:17.772963       1 factory.go:1068] [tanle] Next Pod user1-3
I0323 19:40:17.773204       1 generic_scheduler.go:510] demand 0: =  {%!s(float64=5392.731535756154) %!s(float64=3.221225472e+09) %!s(float64=0.23446658851113714)}
I0323 19:40:17.773242       1 generic_scheduler.go:510] demand 1: =  {%!s(float64=10772.833723653397) %!s(float64=3.221225472e+09) %!s(float64=0.468384074941452)}
I0323 19:40:17.773262       1 generic_scheduler.go:690] shares [%!s(*schedulercache.Resource=&{46000 27477053276 2 0 0 map[]}) %!s(*schedulercache.Resource=&{46000 13754632765 2 0 0 map[]})]
I0323 19:40:17.773309       1 generic_scheduler.go:591] demand.MilliCPU: 23000, currentUsage.MilliCPU 25000, share.MilliCPU 46000
I0323 19:40:17.773319       1 generic_scheduler.go:692] Rejected pod: user1-3 podDemand &{%!s(int64=23000) %!s(int64=3221225472) %!s(int64=0) %!s(int64=0) %!s(int=0) map[]} usage &{%!s(int64=25000) %!s(int64=9663676416) %!s(int64=2) %!s(int64=0) %!s(int=0) map[]} share[1]&{%!s(int64=46000) %!s(int64=13754632765) %!s(int64=2) %!s(int64=0) %!s(int=0) map[]}
I0323 19:40:21.777486       1 factory.go:1068] [tanle] Next Pod user1-3
I0323 19:40:21.777761       1 generic_scheduler.go:510] demand 0: =  {%!s(float64=5392.731535756154) %!s(float64=3.221225472e+09) %!s(float64=0.23446658851113714)}
I0323 19:40:21.777798       1 generic_scheduler.go:510] demand 1: =  {%!s(float64=10772.833723653397) %!s(float64=3.221225472e+09) %!s(float64=0.468384074941452)}
I0323 19:40:21.777821       1 generic_scheduler.go:690] shares [%!s(*schedulercache.Resource=&{46000 27477053276 2 0 0 map[]}) %!s(*schedulercache.Resource=&{46000 13754632765 2 0 0 map[]})]
I0323 19:40:21.777846       1 generic_scheduler.go:591] demand.MilliCPU: 23000, currentUsage.MilliCPU 25000, share.MilliCPU 46000
I0323 19:40:21.777860       1 generic_scheduler.go:692] Rejected pod: user1-3 podDemand &{%!s(int64=23000) %!s(int64=3221225472) %!s(int64=0) %!s(int64=0) %!s(int=0) map[]} usage &{%!s(int64=25000) %!s(int64=9663676416) %!s(int64=2) %!s(int64=0) %!s(int=0) map[]} share[1]&{%!s(int64=46000) %!s(int64=13754632765) %!s(int64=2) %!s(int64=0) %!s(int=0) map[]}
I0323 19:40:29.782727       1 factory.go:1068] [tanle] Next Pod user1-3
I0323 19:40:29.782902       1 generic_scheduler.go:510] demand 0: =  {%!s(float64=5392.731535756154) %!s(float64=3.221225472e+09) %!s(float64=0.23446658851113714)}
I0323 19:40:29.782967       1 generic_scheduler.go:510] demand 1: =  {%!s(float64=10772.833723653397) %!s(float64=3.221225472e+09) %!s(float64=0.468384074941452)}
I0323 19:40:29.783000       1 generic_scheduler.go:690] shares [%!s(*schedulercache.Resource=&{46000 27477053276 2 0 0 map[]}) %!s(*schedulercache.Resource=&{46000 13754632765 2 0 0 map[]})]
I0323 19:40:29.783041       1 generic_scheduler.go:591] demand.MilliCPU: 23000, currentUsage.MilliCPU 25000, share.MilliCPU 46000
I0323 19:40:29.783057       1 generic_scheduler.go:692] Rejected pod: user1-3 podDemand &{%!s(int64=23000) %!s(int64=3221225472) %!s(int64=0) %!s(int64=0) %!s(int=0) map[]} usage &{%!s(int64=25000) %!s(int64=9663676416) %!s(int64=2) %!s(int64=0) %!s(int=0) map[]} share[1]&{%!s(int64=46000) %!s(int64=13754632765) %!s(int64=2) %!s(int64=0) %!s(int=0) map[]}
I0323 19:40:32.085757       1 factory.go:1068] [tanle] Next Pod user2-10
I0323 19:40:32.085910       1 generic_scheduler.go:510] demand 0: =  {%!s(float64=5392.731535756154) %!s(float64=3.221225472e+09) %!s(float64=0.23446658851113714)}
I0323 19:40:32.085947       1 generic_scheduler.go:510] demand 1: =  {%!s(float64=10772.833723653397) %!s(float64=3.221225472e+09) %!s(float64=0.468384074941452)}
I0323 19:40:32.085964       1 generic_scheduler.go:690] shares [%!s(*schedulercache.Resource=&{46000 27477053276 2 0 0 map[]}) %!s(*schedulercache.Resource=&{46000 13754632765 2 0 0 map[]})]
I0323 19:40:32.085987       1 generic_scheduler.go:591] demand.MilliCPU: 23000, currentUsage.MilliCPU 47000, share.MilliCPU 46000
I0323 19:40:32.085996       1 generic_scheduler.go:692] Rejected pod: user2-10 podDemand &{%!s(int64=23000) %!s(int64=3221225472) %!s(int64=0) %!s(int64=0) %!s(int=0) map[]} usage &{%!s(int64=47000) %!s(int64=9663676416) %!s(int64=1) %!s(int64=0) %!s(int=0) map[]} share[1]&{%!s(int64=46000) %!s(int64=13754632765) %!s(int64=2) %!s(int64=0) %!s(int=0) map[]}
I0323 19:40:32.515677       1 factory.go:1068] [tanle] Next Pod user2-11
I0323 19:40:32.516048       1 generic_scheduler.go:510] demand 0: =  {%!s(float64=5392.731535756154) %!s(float64=3.221225472e+09) %!s(float64=0.23446658851113714)}
I0323 19:40:32.516112       1 generic_scheduler.go:510] demand 1: =  {%!s(float64=10772.833723653397) %!s(float64=3.221225472e+09) %!s(float64=0.468384074941452)}
I0323 19:40:32.516146       1 generic_scheduler.go:690] shares [%!s(*schedulercache.Resource=&{46000 27477053276 2 0 0 map[]}) %!s(*schedulercache.Resource=&{46000 13754632765 2 0 0 map[]})]
I0323 19:40:32.516199       1 generic_scheduler.go:591] demand.MilliCPU: 23000, currentUsage.MilliCPU 47000, share.MilliCPU 46000
I0323 19:40:32.516210       1 generic_scheduler.go:692] Rejected pod: user2-11 podDemand &{%!s(int64=23000) %!s(int64=3221225472) %!s(int64=0) %!s(int64=0) %!s(int=0) map[]} usage &{%!s(int64=47000) %!s(int64=9663676416) %!s(int64=1) %!s(int64=0) %!s(int=0) map[]} share[1]&{%!s(int64=46000) %!s(int64=13754632765) %!s(int64=2) %!s(int64=0) %!s(int=0) map[]}
I0323 19:40:33.088681       1 factory.go:1068] [tanle] Next Pod user2-10
I0323 19:40:33.088909       1 generic_scheduler.go:510] demand 0: =  {%!s(float64=5392.731535756154) %!s(float64=3.221225472e+09) %!s(float64=0.23446658851113714)}
I0323 19:40:33.088969       1 generic_scheduler.go:510] demand 1: =  {%!s(float64=10772.833723653397) %!s(float64=3.221225472e+09) %!s(float64=0.468384074941452)}
I0323 19:40:33.088992       1 generic_scheduler.go:690] shares [%!s(*schedulercache.Resource=&{46000 27477053276 2 0 0 map[]}) %!s(*schedulercache.Resource=&{46000 13754632765 2 0 0 map[]})]
I0323 19:40:33.089024       1 generic_scheduler.go:591] demand.MilliCPU: 23000, currentUsage.MilliCPU 47000, share.MilliCPU 46000
I0323 19:40:33.089035       1 generic_scheduler.go:692] Rejected pod: user2-10 podDemand &{%!s(int64=23000) %!s(int64=3221225472) %!s(int64=0) %!s(int64=0) %!s(int=0) map[]} usage &{%!s(int64=47000) %!s(int64=9663676416) %!s(int64=1) %!s(int64=0) %!s(int=0) map[]} share[1]&{%!s(int64=46000) %!s(int64=13754632765) %!s(int64=2) %!s(int64=0) %!s(int=0) map[]}
I0323 19:40:33.518510       1 factory.go:1068] [tanle] Next Pod user2-11
I0323 19:40:33.518621       1 generic_scheduler.go:510] demand 0: =  {%!s(float64=5392.731535756154) %!s(float64=3.221225472e+09) %!s(float64=0.23446658851113714)}
I0323 19:40:33.518644       1 generic_scheduler.go:510] demand 1: =  {%!s(float64=10772.833723653397) %!s(float64=3.221225472e+09) %!s(float64=0.468384074941452)}
I0323 19:40:33.518656       1 generic_scheduler.go:690] shares [%!s(*schedulercache.Resource=&{46000 27477053276 2 0 0 map[]}) %!s(*schedulercache.Resource=&{46000 13754632765 2 0 0 map[]})]
I0323 19:40:33.518669       1 generic_scheduler.go:591] demand.MilliCPU: 23000, currentUsage.MilliCPU 47000, share.MilliCPU 46000
I0323 19:40:33.518675       1 generic_scheduler.go:692] Rejected pod: user2-11 podDemand &{%!s(int64=23000) %!s(int64=3221225472) %!s(int64=0) %!s(int64=0) %!s(int=0) map[]} usage &{%!s(int64=47000) %!s(int64=9663676416) %!s(int64=1) %!s(int64=0) %!s(int=0) map[]} share[1]&{%!s(int64=46000) %!s(int64=13754632765) %!s(int64=2) %!s(int64=0) %!s(int=0) map[]}
I0323 19:40:35.091614       1 factory.go:1068] [tanle] Next Pod user2-10
I0323 19:40:35.091787       1 generic_scheduler.go:510] demand 0: =  {%!s(float64=5392.731535756154) %!s(float64=3.221225472e+09) %!s(float64=0.23446658851113714)}
I0323 19:40:35.091826       1 generic_scheduler.go:510] demand 1: =  {%!s(float64=10772.833723653397) %!s(float64=3.221225472e+09) %!s(float64=0.468384074941452)}
I0323 19:40:35.091839       1 generic_scheduler.go:690] shares [%!s(*schedulercache.Resource=&{46000 27477053276 2 0 0 map[]}) %!s(*schedulercache.Resource=&{46000 13754632765 2 0 0 map[]})]
I0323 19:40:35.091858       1 generic_scheduler.go:591] demand.MilliCPU: 23000, currentUsage.MilliCPU 47000, share.MilliCPU 46000
I0323 19:40:35.091864       1 generic_scheduler.go:692] Rejected pod: user2-10 podDemand &{%!s(int64=23000) %!s(int64=3221225472) %!s(int64=0) %!s(int64=0) %!s(int=0) map[]} usage &{%!s(int64=47000) %!s(int64=9663676416) %!s(int64=1) %!s(int64=0) %!s(int=0) map[]} share[1]&{%!s(int64=46000) %!s(int64=13754632765) %!s(int64=2) %!s(int64=0) %!s(int=0) map[]}
I0323 19:40:35.522071       1 factory.go:1068] [tanle] Next Pod user2-11
I0323 19:40:35.522483       1 generic_scheduler.go:510] demand 0: =  {%!s(float64=5392.731535756154) %!s(float64=3.221225472e+09) %!s(float64=0.23446658851113714)}
I0323 19:40:35.522531       1 generic_scheduler.go:510] demand 1: =  {%!s(float64=10772.833723653397) %!s(float64=3.221225472e+09) %!s(float64=0.468384074941452)}
I0323 19:40:35.522556       1 generic_scheduler.go:690] shares [%!s(*schedulercache.Resource=&{46000 27477053276 2 0 0 map[]}) %!s(*schedulercache.Resource=&{46000 13754632765 2 0 0 map[]})]
I0323 19:40:35.522593       1 generic_scheduler.go:591] demand.MilliCPU: 23000, currentUsage.MilliCPU 47000, share.MilliCPU 46000
I0323 19:40:35.522602       1 generic_scheduler.go:692] Rejected pod: user2-11 podDemand &{%!s(int64=23000) %!s(int64=3221225472) %!s(int64=0) %!s(int64=0) %!s(int=0) map[]} usage &{%!s(int64=47000) %!s(int64=9663676416) %!s(int64=1) %!s(int64=0) %!s(int=0) map[]} share[1]&{%!s(int64=46000) %!s(int64=13754632765) %!s(int64=2) %!s(int64=0) %!s(int=0) map[]}
I0323 19:40:39.093704       1 factory.go:1068] [tanle] Next Pod user2-10
I0323 19:40:39.093886       1 generic_scheduler.go:510] demand 0: =  {%!s(float64=5392.731535756154) %!s(float64=3.221225472e+09) %!s(float64=0.23446658851113714)}
I0323 19:40:39.093923       1 generic_scheduler.go:510] demand 1: =  {%!s(float64=10772.833723653397) %!s(float64=3.221225472e+09) %!s(float64=0.468384074941452)}
I0323 19:40:39.093940       1 generic_scheduler.go:690] shares [%!s(*schedulercache.Resource=&{46000 27477053276 2 0 0 map[]}) %!s(*schedulercache.Resource=&{46000 13754632765 2 0 0 map[]})]
I0323 19:40:39.093966       1 generic_scheduler.go:591] demand.MilliCPU: 23000, currentUsage.MilliCPU 47000, share.MilliCPU 46000
I0323 19:40:39.093977       1 generic_scheduler.go:692] Rejected pod: user2-10 podDemand &{%!s(int64=23000) %!s(int64=3221225472) %!s(int64=0) %!s(int64=0) %!s(int=0) map[]} usage &{%!s(int64=47000) %!s(int64=9663676416) %!s(int64=1) %!s(int64=0) %!s(int=0) map[]} share[1]&{%!s(int64=46000) %!s(int64=13754632765) %!s(int64=2) %!s(int64=0) %!s(int=0) map[]}
I0323 19:40:39.525481       1 factory.go:1068] [tanle] Next Pod user2-11
I0323 19:40:39.525678       1 generic_scheduler.go:510] demand 0: =  {%!s(float64=5392.731535756154) %!s(float64=3.221225472e+09) %!s(float64=0.23446658851113714)}
I0323 19:40:39.525847       1 generic_scheduler.go:510] demand 1: =  {%!s(float64=10772.833723653397) %!s(float64=3.221225472e+09) %!s(float64=0.468384074941452)}
I0323 19:40:39.525945       1 generic_scheduler.go:690] shares [%!s(*schedulercache.Resource=&{46000 27477053276 2 0 0 map[]}) %!s(*schedulercache.Resource=&{46000 13754632765 2 0 0 map[]})]
I0323 19:40:39.526038       1 generic_scheduler.go:591] demand.MilliCPU: 23000, currentUsage.MilliCPU 47000, share.MilliCPU 46000
I0323 19:40:39.526142       1 generic_scheduler.go:692] Rejected pod: user2-11 podDemand &{%!s(int64=23000) %!s(int64=3221225472) %!s(int64=0) %!s(int64=0) %!s(int=0) map[]} usage &{%!s(int64=47000) %!s(int64=9663676416) %!s(int64=1) %!s(int64=0) %!s(int=0) map[]} share[1]&{%!s(int64=46000) %!s(int64=13754632765) %!s(int64=2) %!s(int64=0) %!s(int=0) map[]}
I0323 19:40:43.060424       1 factory.go:1068] [tanle] Next Pod user2-14
I0323 19:40:43.060564       1 generic_scheduler.go:510] demand 0: =  {%!s(float64=5392.731535756154) %!s(float64=3.221225472e+09) %!s(float64=0.23446658851113714)}
I0323 19:40:43.060594       1 generic_scheduler.go:510] demand 1: =  {%!s(float64=10772.833723653397) %!s(float64=3.221225472e+09) %!s(float64=0.468384074941452)}
I0323 19:40:43.060622       1 generic_scheduler.go:690] shares [%!s(*schedulercache.Resource=&{46000 27477053276 2 0 0 map[]}) %!s(*schedulercache.Resource=&{46000 13754632765 2 0 0 map[]})]
I0323 19:40:43.060642       1 generic_scheduler.go:591] demand.MilliCPU: 23000, currentUsage.MilliCPU 47000, share.MilliCPU 46000
I0323 19:40:43.060650       1 generic_scheduler.go:692] Rejected pod: user2-14 podDemand &{%!s(int64=23000) %!s(int64=3221225472) %!s(int64=0) %!s(int64=0) %!s(int=0) map[]} usage &{%!s(int64=47000) %!s(int64=9663676416) %!s(int64=1) %!s(int64=0) %!s(int=0) map[]} share[1]&{%!s(int64=46000) %!s(int64=13754632765) %!s(int64=2) %!s(int64=0) %!s(int=0) map[]}
I0323 19:40:43.077099       1 factory.go:1068] [tanle] Next Pod user2-14
I0323 19:40:43.077257       1 generic_scheduler.go:510] demand 0: =  {%!s(float64=5392.731535756154) %!s(float64=3.221225472e+09) %!s(float64=0.23446658851113714)}
I0323 19:40:43.077287       1 generic_scheduler.go:510] demand 1: =  {%!s(float64=10772.833723653397) %!s(float64=3.221225472e+09) %!s(float64=0.468384074941452)}
I0323 19:40:43.077300       1 generic_scheduler.go:690] shares [%!s(*schedulercache.Resource=&{46000 27477053276 2 0 0 map[]}) %!s(*schedulercache.Resource=&{46000 13754632765 2 0 0 map[]})]
I0323 19:40:43.077366       1 generic_scheduler.go:591] demand.MilliCPU: 23000, currentUsage.MilliCPU 47000, share.MilliCPU 46000
I0323 19:40:43.077391       1 generic_scheduler.go:692] Rejected pod: user2-14 podDemand &{%!s(int64=23000) %!s(int64=3221225472) %!s(int64=0) %!s(int64=0) %!s(int=0) map[]} usage &{%!s(int64=47000) %!s(int64=9663676416) %!s(int64=1) %!s(int64=0) %!s(int=0) map[]} share[1]&{%!s(int64=46000) %!s(int64=13754632765) %!s(int64=2) %!s(int64=0) %!s(int=0) map[]}
W0323 19:40:43.077542       1 factory.go:1226] Request for pod user2/user2-14 already in flight, abandoning
I0323 19:40:43.100351       1 factory.go:1068] [tanle] Next Pod user2-15
I0323 19:40:43.100545       1 generic_scheduler.go:510] demand 0: =  {%!s(float64=5392.731535756154) %!s(float64=3.221225472e+09) %!s(float64=0.23446658851113714)}
I0323 19:40:43.100641       1 generic_scheduler.go:510] demand 1: =  {%!s(float64=10772.833723653397) %!s(float64=3.221225472e+09) %!s(float64=0.468384074941452)}
I0323 19:40:43.100689       1 generic_scheduler.go:690] shares [%!s(*schedulercache.Resource=&{46000 27477053276 2 0 0 map[]}) %!s(*schedulercache.Resource=&{46000 13754632765 2 0 0 map[]})]
I0323 19:40:43.100740       1 generic_scheduler.go:591] demand.MilliCPU: 23000, currentUsage.MilliCPU 47000, share.MilliCPU 46000
I0323 19:40:43.100771       1 generic_scheduler.go:692] Rejected pod: user2-15 podDemand &{%!s(int64=23000) %!s(int64=3221225472) %!s(int64=0) %!s(int64=0) %!s(int=0) map[]} usage &{%!s(int64=47000) %!s(int64=9663676416) %!s(int64=1) %!s(int64=0) %!s(int=0) map[]} share[1]&{%!s(int64=46000) %!s(int64=13754632765) %!s(int64=2) %!s(int64=0) %!s(int=0) map[]}
I0323 19:40:43.490685       1 factory.go:1068] [tanle] Next Pod user2-15
I0323 19:40:43.490946       1 generic_scheduler.go:510] demand 0: =  {%!s(float64=5392.731535756154) %!s(float64=3.221225472e+09) %!s(float64=0.23446658851113714)}
I0323 19:40:43.491025       1 generic_scheduler.go:510] demand 1: =  {%!s(float64=10772.833723653397) %!s(float64=3.221225472e+09) %!s(float64=0.468384074941452)}
I0323 19:40:43.491075       1 generic_scheduler.go:690] shares [%!s(*schedulercache.Resource=&{46000 27477053276 2 0 0 map[]}) %!s(*schedulercache.Resource=&{46000 13754632765 2 0 0 map[]})]
I0323 19:40:43.491116       1 generic_scheduler.go:591] demand.MilliCPU: 23000, currentUsage.MilliCPU 47000, share.MilliCPU 46000
I0323 19:40:43.491166       1 generic_scheduler.go:692] Rejected pod: user2-15 podDemand &{%!s(int64=23000) %!s(int64=3221225472) %!s(int64=0) %!s(int64=0) %!s(int=0) map[]} usage &{%!s(int64=47000) %!s(int64=9663676416) %!s(int64=1) %!s(int64=0) %!s(int=0) map[]} share[1]&{%!s(int64=46000) %!s(int64=13754632765) %!s(int64=2) %!s(int64=0) %!s(int=0) map[]}
W0323 19:40:43.491412       1 factory.go:1226] Request for pod user2/user2-15 already in flight, abandoning
I0323 19:40:44.063060       1 factory.go:1068] [tanle] Next Pod user2-14
I0323 19:40:44.063249       1 generic_scheduler.go:510] demand 0: =  {%!s(float64=5392.731535756154) %!s(float64=3.221225472e+09) %!s(float64=0.23446658851113714)}
I0323 19:40:44.063288       1 generic_scheduler.go:510] demand 1: =  {%!s(float64=10772.833723653397) %!s(float64=3.221225472e+09) %!s(float64=0.468384074941452)}
I0323 19:40:44.063338       1 generic_scheduler.go:690] shares [%!s(*schedulercache.Resource=&{46000 27477053276 2 0 0 map[]}) %!s(*schedulercache.Resource=&{46000 13754632765 2 0 0 map[]})]
I0323 19:40:44.063368       1 generic_scheduler.go:591] demand.MilliCPU: 23000, currentUsage.MilliCPU 47000, share.MilliCPU 46000
I0323 19:40:44.063377       1 generic_scheduler.go:692] Rejected pod: user2-14 podDemand &{%!s(int64=23000) %!s(int64=3221225472) %!s(int64=0) %!s(int64=0) %!s(int=0) map[]} usage &{%!s(int64=47000) %!s(int64=9663676416) %!s(int64=1) %!s(int64=0) %!s(int=0) map[]} share[1]&{%!s(int64=46000) %!s(int64=13754632765) %!s(int64=2) %!s(int64=0) %!s(int=0) map[]}
I0323 19:40:44.103853       1 factory.go:1068] [tanle] Next Pod user2-15
I0323 19:40:44.104002       1 generic_scheduler.go:510] demand 0: =  {%!s(float64=5392.731535756154) %!s(float64=3.221225472e+09) %!s(float64=0.23446658851113714)}
I0323 19:40:44.104030       1 generic_scheduler.go:510] demand 1: =  {%!s(float64=10772.833723653397) %!s(float64=3.221225472e+09) %!s(float64=0.468384074941452)}
I0323 19:40:44.104041       1 generic_scheduler.go:690] shares [%!s(*schedulercache.Resource=&{46000 27477053276 2 0 0 map[]}) %!s(*schedulercache.Resource=&{46000 13754632765 2 0 0 map[]})]
I0323 19:40:44.104059       1 generic_scheduler.go:591] demand.MilliCPU: 23000, currentUsage.MilliCPU 47000, share.MilliCPU 46000
I0323 19:40:44.104065       1 generic_scheduler.go:692] Rejected pod: user2-15 podDemand &{%!s(int64=23000) %!s(int64=3221225472) %!s(int64=0) %!s(int64=0) %!s(int=0) map[]} usage &{%!s(int64=47000) %!s(int64=9663676416) %!s(int64=1) %!s(int64=0) %!s(int=0) map[]} share[1]&{%!s(int64=46000) %!s(int64=13754632765) %!s(int64=2) %!s(int64=0) %!s(int=0) map[]}
I0323 19:40:46.265298       1 factory.go:1068] [tanle] Next Pod user2-15
I0323 19:40:46.265408       1 generic_scheduler.go:510] demand 0: =  {%!s(float64=5392.731535756154) %!s(float64=3.221225472e+09) %!s(float64=0.23446658851113714)}
I0323 19:40:46.265433       1 generic_scheduler.go:510] demand 1: =  {%!s(float64=10772.833723653397) %!s(float64=3.221225472e+09) %!s(float64=0.468384074941452)}
I0323 19:40:46.265443       1 generic_scheduler.go:690] shares [%!s(*schedulercache.Resource=&{46000 27477053276 2 0 0 map[]}) %!s(*schedulercache.Resource=&{46000 13754632765 2 0 0 map[]})]
I0323 19:40:46.265459       1 generic_scheduler.go:591] demand.MilliCPU: 23000, currentUsage.MilliCPU 47000, share.MilliCPU 46000
I0323 19:40:46.265463       1 generic_scheduler.go:692] Rejected pod: user2-15 podDemand &{%!s(int64=23000) %!s(int64=3221225472) %!s(int64=0) %!s(int64=0) %!s(int=0) map[]} usage &{%!s(int64=47000) %!s(int64=9663676416) %!s(int64=1) %!s(int64=0) %!s(int=0) map[]} share[1]&{%!s(int64=46000) %!s(int64=13754632765) %!s(int64=2) %!s(int64=0) %!s(int=0) map[]}
I0323 19:40:46.266522       1 factory.go:1068] [tanle] Next Pod user1-3
I0323 19:40:46.266644       1 generic_scheduler.go:510] demand 0: =  {%!s(float64=5392.731535756154) %!s(float64=3.221225472e+09) %!s(float64=0.23446658851113714)}
I0323 19:40:46.266670       1 generic_scheduler.go:510] demand 1: =  {%!s(float64=10772.833723653397) %!s(float64=3.221225472e+09) %!s(float64=0.468384074941452)}
I0323 19:40:46.266717       1 generic_scheduler.go:690] shares [%!s(*schedulercache.Resource=&{46000 27477053276 2 0 0 map[]}) %!s(*schedulercache.Resource=&{46000 13754632765 2 0 0 map[]})]
I0323 19:40:46.266778       1 generic_scheduler.go:591] demand.MilliCPU: 23000, currentUsage.MilliCPU 25000, share.MilliCPU 46000
I0323 19:40:46.266820       1 generic_scheduler.go:692] Rejected pod: user1-3 podDemand &{%!s(int64=23000) %!s(int64=3221225472) %!s(int64=0) %!s(int64=0) %!s(int=0) map[]} usage &{%!s(int64=25000) %!s(int64=9663676416) %!s(int64=2) %!s(int64=0) %!s(int=0) map[]} share[1]&{%!s(int64=46000) %!s(int64=13754632765) %!s(int64=2) %!s(int64=0) %!s(int=0) map[]}
I0323 19:40:46.266981       1 factory.go:1068] [tanle] Next Pod user2-14
I0323 19:40:46.267115       1 generic_scheduler.go:510] demand 0: =  {%!s(float64=5392.731535756154) %!s(float64=3.221225472e+09) %!s(float64=0.23446658851113714)}
I0323 19:40:46.267172       1 generic_scheduler.go:510] demand 1: =  {%!s(float64=10772.833723653397) %!s(float64=3.221225472e+09) %!s(float64=0.468384074941452)}
I0323 19:40:46.267217       1 generic_scheduler.go:690] shares [%!s(*schedulercache.Resource=&{46000 27477053276 2 0 0 map[]}) %!s(*schedulercache.Resource=&{46000 13754632765 2 0 0 map[]})]
I0323 19:40:46.267259       1 generic_scheduler.go:591] demand.MilliCPU: 23000, currentUsage.MilliCPU 47000, share.MilliCPU 46000
I0323 19:40:46.267288       1 generic_scheduler.go:692] Rejected pod: user2-14 podDemand &{%!s(int64=23000) %!s(int64=3221225472) %!s(int64=0) %!s(int64=0) %!s(int=0) map[]} usage &{%!s(int64=47000) %!s(int64=9663676416) %!s(int64=1) %!s(int64=0) %!s(int=0) map[]} share[1]&{%!s(int64=46000) %!s(int64=13754632765) %!s(int64=2) %!s(int64=0) %!s(int=0) map[]}
I0323 19:40:47.096678       1 factory.go:1068] [tanle] Next Pod user2-10
I0323 19:40:47.096833       1 generic_scheduler.go:510] demand 0: =  {%!s(float64=5392.731535756154) %!s(float64=3.221225472e+09) %!s(float64=0.23446658851113714)}
I0323 19:40:47.096868       1 generic_scheduler.go:510] demand 1: =  {%!s(float64=10772.833723653397) %!s(float64=3.221225472e+09) %!s(float64=0.468384074941452)}
I0323 19:40:47.096891       1 generic_scheduler.go:690] shares [%!s(*schedulercache.Resource=&{46000 27477053276 2 0 0 map[]}) %!s(*schedulercache.Resource=&{46000 13754632765 2 0 0 map[]})]
I0323 19:40:47.096918       1 generic_scheduler.go:591] demand.MilliCPU: 23000, currentUsage.MilliCPU 47000, share.MilliCPU 46000
I0323 19:40:47.096934       1 generic_scheduler.go:692] Rejected pod: user2-10 podDemand &{%!s(int64=23000) %!s(int64=3221225472) %!s(int64=0) %!s(int64=0) %!s(int=0) map[]} usage &{%!s(int64=47000) %!s(int64=9663676416) %!s(int64=1) %!s(int64=0) %!s(int=0) map[]} share[1]&{%!s(int64=46000) %!s(int64=13754632765) %!s(int64=2) %!s(int64=0) %!s(int=0) map[]}
I0323 19:40:47.530498       1 factory.go:1068] [tanle] Next Pod user2-11
I0323 19:40:47.530656       1 generic_scheduler.go:510] demand 0: =  {%!s(float64=5392.731535756154) %!s(float64=3.221225472e+09) %!s(float64=0.23446658851113714)}
I0323 19:40:47.530689       1 generic_scheduler.go:510] demand 1: =  {%!s(float64=10772.833723653397) %!s(float64=3.221225472e+09) %!s(float64=0.468384074941452)}
I0323 19:40:47.530703       1 generic_scheduler.go:690] shares [%!s(*schedulercache.Resource=&{46000 27477053276 2 0 0 map[]}) %!s(*schedulercache.Resource=&{46000 13754632765 2 0 0 map[]})]
I0323 19:40:47.530723       1 generic_scheduler.go:591] demand.MilliCPU: 23000, currentUsage.MilliCPU 47000, share.MilliCPU 46000
I0323 19:40:47.530729       1 generic_scheduler.go:692] Rejected pod: user2-11 podDemand &{%!s(int64=23000) %!s(int64=3221225472) %!s(int64=0) %!s(int64=0) %!s(int=0) map[]} usage &{%!s(int64=47000) %!s(int64=9663676416) %!s(int64=1) %!s(int64=0) %!s(int=0) map[]} share[1]&{%!s(int64=46000) %!s(int64=13754632765) %!s(int64=2) %!s(int64=0) %!s(int=0) map[]}
I0323 19:40:50.268567       1 factory.go:1068] [tanle] Next Pod user2-15
I0323 19:40:50.268725       1 generic_scheduler.go:510] demand 0: =  {%!s(float64=5392.731535756154) %!s(float64=3.221225472e+09) %!s(float64=0.23446658851113714)}
I0323 19:40:50.268760       1 generic_scheduler.go:510] demand 1: =  {%!s(float64=10772.833723653397) %!s(float64=3.221225472e+09) %!s(float64=0.468384074941452)}
I0323 19:40:50.268778       1 generic_scheduler.go:690] shares [%!s(*schedulercache.Resource=&{46000 27477053276 2 0 0 map[]}) %!s(*schedulercache.Resource=&{46000 13754632765 2 0 0 map[]})]
I0323 19:40:50.268832       1 generic_scheduler.go:591] demand.MilliCPU: 23000, currentUsage.MilliCPU 47000, share.MilliCPU 46000
I0323 19:40:50.268843       1 generic_scheduler.go:692] Rejected pod: user2-15 podDemand &{%!s(int64=23000) %!s(int64=3221225472) %!s(int64=0) %!s(int64=0) %!s(int=0) map[]} usage &{%!s(int64=47000) %!s(int64=9663676416) %!s(int64=1) %!s(int64=0) %!s(int=0) map[]} share[1]&{%!s(int64=46000) %!s(int64=13754632765) %!s(int64=2) %!s(int64=0) %!s(int=0) map[]}
I0323 19:40:50.269458       1 factory.go:1068] [tanle] Next Pod user2-14
I0323 19:40:50.269557       1 generic_scheduler.go:510] demand 0: =  {%!s(float64=5392.731535756154) %!s(float64=3.221225472e+09) %!s(float64=0.23446658851113714)}
I0323 19:40:50.269580       1 generic_scheduler.go:510] demand 1: =  {%!s(float64=10772.833723653397) %!s(float64=3.221225472e+09) %!s(float64=0.468384074941452)}
I0323 19:40:50.269597       1 generic_scheduler.go:690] shares [%!s(*schedulercache.Resource=&{46000 27477053276 2 0 0 map[]}) %!s(*schedulercache.Resource=&{46000 13754632765 2 0 0 map[]})]
I0323 19:40:50.269616       1 generic_scheduler.go:591] demand.MilliCPU: 23000, currentUsage.MilliCPU 47000, share.MilliCPU 46000
I0323 19:40:50.269624       1 generic_scheduler.go:692] Rejected pod: user2-14 podDemand &{%!s(int64=23000) %!s(int64=3221225472) %!s(int64=0) %!s(int64=0) %!s(int=0) map[]} usage &{%!s(int64=47000) %!s(int64=9663676416) %!s(int64=1) %!s(int64=0) %!s(int=0) map[]} share[1]&{%!s(int64=46000) %!s(int64=13754632765) %!s(int64=2) %!s(int64=0) %!s(int=0) map[]}
I0323 19:40:58.274134       1 factory.go:1068] [tanle] Next Pod user2-15
I0323 19:40:58.274326       1 generic_scheduler.go:510] demand 0: =  {%!s(float64=5392.731535756154) %!s(float64=3.221225472e+09) %!s(float64=0.23446658851113714)}
I0323 19:40:58.274365       1 generic_scheduler.go:510] demand 1: =  {%!s(float64=10772.833723653397) %!s(float64=3.221225472e+09) %!s(float64=0.468384074941452)}
I0323 19:40:58.274384       1 generic_scheduler.go:690] shares [%!s(*schedulercache.Resource=&{46000 27477053276 2 0 0 map[]}) %!s(*schedulercache.Resource=&{46000 13754632765 2 0 0 map[]})]
I0323 19:40:58.274408       1 generic_scheduler.go:591] demand.MilliCPU: 23000, currentUsage.MilliCPU 47000, share.MilliCPU 46000
I0323 19:40:58.274418       1 generic_scheduler.go:692] Rejected pod: user2-15 podDemand &{%!s(int64=23000) %!s(int64=3221225472) %!s(int64=0) %!s(int64=0) %!s(int=0) map[]} usage &{%!s(int64=47000) %!s(int64=9663676416) %!s(int64=1) %!s(int64=0) %!s(int=0) map[]} share[1]&{%!s(int64=46000) %!s(int64=13754632765) %!s(int64=2) %!s(int64=0) %!s(int=0) map[]}
I0323 19:40:58.274534       1 factory.go:1068] [tanle] Next Pod user2-14
I0323 19:40:58.274634       1 generic_scheduler.go:510] demand 0: =  {%!s(float64=5392.731535756154) %!s(float64=3.221225472e+09) %!s(float64=0.23446658851113714)}
I0323 19:40:58.274662       1 generic_scheduler.go:510] demand 1: =  {%!s(float64=10772.833723653397) %!s(float64=3.221225472e+09) %!s(float64=0.468384074941452)}
I0323 19:40:58.274680       1 generic_scheduler.go:690] shares [%!s(*schedulercache.Resource=&{46000 27477053276 2 0 0 map[]}) %!s(*schedulercache.Resource=&{46000 13754632765 2 0 0 map[]})]
I0323 19:40:58.274701       1 generic_scheduler.go:591] demand.MilliCPU: 23000, currentUsage.MilliCPU 47000, share.MilliCPU 46000
I0323 19:40:58.274712       1 generic_scheduler.go:692] Rejected pod: user2-14 podDemand &{%!s(int64=23000) %!s(int64=3221225472) %!s(int64=0) %!s(int64=0) %!s(int=0) map[]} usage &{%!s(int64=47000) %!s(int64=9663676416) %!s(int64=1) %!s(int64=0) %!s(int=0) map[]} share[1]&{%!s(int64=46000) %!s(int64=13754632765) %!s(int64=2) %!s(int64=0) %!s(int=0) map[]}
I0323 19:41:03.099345       1 factory.go:1068] [tanle] Next Pod user2-10
I0323 19:41:03.099499       1 generic_scheduler.go:510] demand 0: =  {%!s(float64=5392.731535756154) %!s(float64=3.221225472e+09) %!s(float64=0.23446658851113714)}
I0323 19:41:03.099542       1 generic_scheduler.go:510] demand 1: =  {%!s(float64=10772.833723653397) %!s(float64=3.221225472e+09) %!s(float64=0.468384074941452)}
I0323 19:41:03.099562       1 generic_scheduler.go:690] shares [%!s(*schedulercache.Resource=&{46000 27477053276 2 0 0 map[]}) %!s(*schedulercache.Resource=&{46000 13754632765 2 0 0 map[]})]
I0323 19:41:03.099587       1 generic_scheduler.go:591] demand.MilliCPU: 23000, currentUsage.MilliCPU 47000, share.MilliCPU 46000
I0323 19:41:03.099598       1 generic_scheduler.go:692] Rejected pod: user2-10 podDemand &{%!s(int64=23000) %!s(int64=3221225472) %!s(int64=0) %!s(int64=0) %!s(int=0) map[]} usage &{%!s(int64=47000) %!s(int64=9663676416) %!s(int64=1) %!s(int64=0) %!s(int=0) map[]} share[1]&{%!s(int64=46000) %!s(int64=13754632765) %!s(int64=2) %!s(int64=0) %!s(int=0) map[]}
I0323 19:41:03.533285       1 factory.go:1068] [tanle] Next Pod user2-11
I0323 19:41:03.533512       1 generic_scheduler.go:510] demand 0: =  {%!s(float64=5392.731535756154) %!s(float64=3.221225472e+09) %!s(float64=0.23446658851113714)}
I0323 19:41:03.533624       1 generic_scheduler.go:510] demand 1: =  {%!s(float64=10772.833723653397) %!s(float64=3.221225472e+09) %!s(float64=0.468384074941452)}
I0323 19:41:03.533649       1 generic_scheduler.go:690] shares [%!s(*schedulercache.Resource=&{46000 27477053276 2 0 0 map[]}) %!s(*schedulercache.Resource=&{46000 13754632765 2 0 0 map[]})]
I0323 19:41:03.533675       1 generic_scheduler.go:591] demand.MilliCPU: 23000, currentUsage.MilliCPU 47000, share.MilliCPU 46000
I0323 19:41:03.533685       1 generic_scheduler.go:692] Rejected pod: user2-11 podDemand &{%!s(int64=23000) %!s(int64=3221225472) %!s(int64=0) %!s(int64=0) %!s(int=0) map[]} usage &{%!s(int64=47000) %!s(int64=9663676416) %!s(int64=1) %!s(int64=0) %!s(int=0) map[]} share[1]&{%!s(int64=46000) %!s(int64=13754632765) %!s(int64=2) %!s(int64=0) %!s(int=0) map[]}
I0323 19:41:14.277536       1 factory.go:1068] [tanle] Next Pod user2-14
I0323 19:41:14.277710       1 generic_scheduler.go:510] demand 0: =  {%!s(float64=5392.731535756154) %!s(float64=3.221225472e+09) %!s(float64=0.23446658851113714)}
I0323 19:41:14.277750       1 generic_scheduler.go:510] demand 1: =  {%!s(float64=10772.833723653397) %!s(float64=3.221225472e+09) %!s(float64=0.468384074941452)}
I0323 19:41:14.277785       1 generic_scheduler.go:690] shares [%!s(*schedulercache.Resource=&{46000 27477053276 2 0 0 map[]}) %!s(*schedulercache.Resource=&{46000 13754632765 2 0 0 map[]})]
I0323 19:41:14.277807       1 generic_scheduler.go:591] demand.MilliCPU: 23000, currentUsage.MilliCPU 47000, share.MilliCPU 46000
I0323 19:41:14.277815       1 generic_scheduler.go:692] Rejected pod: user2-14 podDemand &{%!s(int64=23000) %!s(int64=3221225472) %!s(int64=0) %!s(int64=0) %!s(int=0) map[]} usage &{%!s(int64=47000) %!s(int64=9663676416) %!s(int64=1) %!s(int64=0) %!s(int=0) map[]} share[1]&{%!s(int64=46000) %!s(int64=13754632765) %!s(int64=2) %!s(int64=0) %!s(int=0) map[]}
I0323 19:41:14.277942       1 factory.go:1068] [tanle] Next Pod user2-15
I0323 19:41:14.278055       1 generic_scheduler.go:510] demand 0: =  {%!s(float64=5392.731535756154) %!s(float64=3.221225472e+09) %!s(float64=0.23446658851113714)}
I0323 19:41:14.278077       1 generic_scheduler.go:510] demand 1: =  {%!s(float64=10772.833723653397) %!s(float64=3.221225472e+09) %!s(float64=0.468384074941452)}
I0323 19:41:14.278091       1 generic_scheduler.go:690] shares [%!s(*schedulercache.Resource=&{46000 27477053276 2 0 0 map[]}) %!s(*schedulercache.Resource=&{46000 13754632765 2 0 0 map[]})]
I0323 19:41:14.278112       1 generic_scheduler.go:591] demand.MilliCPU: 23000, currentUsage.MilliCPU 47000, share.MilliCPU 46000
I0323 19:41:14.278118       1 generic_scheduler.go:692] Rejected pod: user2-15 podDemand &{%!s(int64=23000) %!s(int64=3221225472) %!s(int64=0) %!s(int64=0) %!s(int=0) map[]} usage &{%!s(int64=47000) %!s(int64=9663676416) %!s(int64=1) %!s(int64=0) %!s(int=0) map[]} share[1]&{%!s(int64=46000) %!s(int64=13754632765) %!s(int64=2) %!s(int64=0) %!s(int=0) map[]}
I0323 19:41:18.269238       1 factory.go:1068] [tanle] Next Pod user1-3
I0323 19:41:18.269560       1 generic_scheduler.go:510] demand 0: =  {%!s(float64=5392.731535756154) %!s(float64=3.221225472e+09) %!s(float64=0.23446658851113714)}
I0323 19:41:18.269593       1 generic_scheduler.go:510] demand 1: =  {%!s(float64=10772.833723653397) %!s(float64=3.221225472e+09) %!s(float64=0.468384074941452)}
I0323 19:41:18.269605       1 generic_scheduler.go:690] shares [%!s(*schedulercache.Resource=&{46000 27477053276 2 0 0 map[]}) %!s(*schedulercache.Resource=&{46000 13754632765 2 0 0 map[]})]
I0323 19:41:18.269630       1 generic_scheduler.go:591] demand.MilliCPU: 23000, currentUsage.MilliCPU 25000, share.MilliCPU 46000
I0323 19:41:18.269638       1 generic_scheduler.go:692] Rejected pod: user1-3 podDemand &{%!s(int64=23000) %!s(int64=3221225472) %!s(int64=0) %!s(int64=0) %!s(int=0) map[]} usage &{%!s(int64=25000) %!s(int64=9663676416) %!s(int64=2) %!s(int64=0) %!s(int=0) map[]} share[1]&{%!s(int64=46000) %!s(int64=13754632765) %!s(int64=2) %!s(int64=0) %!s(int=0) map[]}
I0323 19:41:32.990253       1 factory.go:1068] [tanle] Next Pod user1-8
I0323 19:41:32.990501       1 generic_scheduler.go:510] demand 0: =  {%!s(float64=5392.731535756154) %!s(float64=3.221225472e+09) %!s(float64=0.23446658851113714)}
I0323 19:41:32.990560       1 generic_scheduler.go:510] demand 1: =  {%!s(float64=10772.833723653397) %!s(float64=3.221225472e+09) %!s(float64=0.468384074941452)}
I0323 19:41:32.990614       1 generic_scheduler.go:690] shares [%!s(*schedulercache.Resource=&{46000 27477053276 2 0 0 map[]}) %!s(*schedulercache.Resource=&{46000 13754632765 2 0 0 map[]})]
I0323 19:41:32.990642       1 generic_scheduler.go:695] Admitted pod: user1-8 podDemand &{%!s(int64=1000) %!s(int64=3221225472) %!s(int64=1) %!s(int64=0) %!s(int=0) map[]} usage &{%!s(int64=24000) %!s(int64=6442450944) %!s(int64=1) %!s(int64=0) %!s(int=0) map[]}
I0323 19:41:33.016262       1 factory.go:1068] [tanle] Next Pod user1-9
I0323 19:41:33.016434       1 generic_scheduler.go:510] demand 0: =  {%!s(float64=5392.731535756154) %!s(float64=3.221225472e+09) %!s(float64=0.23446658851113714)}
I0323 19:41:33.016466       1 generic_scheduler.go:510] demand 1: =  {%!s(float64=10772.833723653397) %!s(float64=3.221225472e+09) %!s(float64=0.468384074941452)}
I0323 19:41:33.016482       1 generic_scheduler.go:690] shares [%!s(*schedulercache.Resource=&{46000 27477053276 2 0 0 map[]}) %!s(*schedulercache.Resource=&{46000 13754632765 2 0 0 map[]})]
I0323 19:41:33.016505       1 generic_scheduler.go:692] Rejected pod: user1-9 podDemand &{%!s(int64=1000) %!s(int64=3221225472) %!s(int64=1) %!s(int64=0) %!s(int=0) map[]} usage &{%!s(int64=25000) %!s(int64=9663676416) %!s(int64=2) %!s(int64=0) %!s(int=0) map[]} share[1]&{%!s(int64=46000) %!s(int64=13754632765) %!s(int64=2) %!s(int64=0) %!s(int=0) map[]}
I0323 19:41:33.045896       1 factory.go:1068] [tanle] Next Pod user1-9
I0323 19:41:33.046035       1 generic_scheduler.go:510] demand 0: =  {%!s(float64=5392.731535756154) %!s(float64=3.221225472e+09) %!s(float64=0.23446658851113714)}
I0323 19:41:33.046063       1 generic_scheduler.go:510] demand 1: =  {%!s(float64=10772.833723653397) %!s(float64=3.221225472e+09) %!s(float64=0.468384074941452)}
I0323 19:41:33.046078       1 generic_scheduler.go:690] shares [%!s(*schedulercache.Resource=&{46000 27477053276 2 0 0 map[]}) %!s(*schedulercache.Resource=&{46000 13754632765 2 0 0 map[]})]
I0323 19:41:33.046096       1 generic_scheduler.go:692] Rejected pod: user1-9 podDemand &{%!s(int64=1000) %!s(int64=3221225472) %!s(int64=1) %!s(int64=0) %!s(int=0) map[]} usage &{%!s(int64=25000) %!s(int64=9663676416) %!s(int64=2) %!s(int64=0) %!s(int=0) map[]} share[1]&{%!s(int64=46000) %!s(int64=13754632765) %!s(int64=2) %!s(int64=0) %!s(int=0) map[]}
W0323 19:41:33.046190       1 factory.go:1226] Request for pod user1/user1-9 already in flight, abandoning
I0323 19:41:34.502914       1 factory.go:1068] [tanle] Next Pod user1-9
I0323 19:41:34.503092       1 generic_scheduler.go:510] demand 0: =  {%!s(float64=5392.731535756154) %!s(float64=3.221225472e+09) %!s(float64=0.23446658851113714)}
I0323 19:41:34.503129       1 generic_scheduler.go:510] demand 1: =  {%!s(float64=10772.833723653397) %!s(float64=3.221225472e+09) %!s(float64=0.468384074941452)}
I0323 19:41:34.503161       1 generic_scheduler.go:690] shares [%!s(*schedulercache.Resource=&{46000 27477053276 2 0 0 map[]}) %!s(*schedulercache.Resource=&{46000 13754632765 2 0 0 map[]})]
I0323 19:41:34.503188       1 generic_scheduler.go:692] Rejected pod: user1-9 podDemand &{%!s(int64=1000) %!s(int64=3221225472) %!s(int64=1) %!s(int64=0) %!s(int=0) map[]} usage &{%!s(int64=25000) %!s(int64=9663676416) %!s(int64=2) %!s(int64=0) %!s(int=0) map[]} share[1]&{%!s(int64=46000) %!s(int64=13754632765) %!s(int64=2) %!s(int64=0) %!s(int=0) map[]}
I0323 19:41:35.101916       1 factory.go:1068] [tanle] Next Pod user2-10
I0323 19:41:35.102097       1 generic_scheduler.go:510] demand 0: =  {%!s(float64=5392.731535756154) %!s(float64=3.221225472e+09) %!s(float64=0.23446658851113714)}
I0323 19:41:35.102138       1 generic_scheduler.go:510] demand 1: =  {%!s(float64=10772.833723653397) %!s(float64=3.221225472e+09) %!s(float64=0.468384074941452)}
I0323 19:41:35.102155       1 generic_scheduler.go:690] shares [%!s(*schedulercache.Resource=&{46000 27477053276 2 0 0 map[]}) %!s(*schedulercache.Resource=&{46000 13754632765 2 0 0 map[]})]
I0323 19:41:35.102184       1 generic_scheduler.go:591] demand.MilliCPU: 23000, currentUsage.MilliCPU 47000, share.MilliCPU 46000
I0323 19:41:35.102192       1 generic_scheduler.go:692] Rejected pod: user2-10 podDemand &{%!s(int64=23000) %!s(int64=3221225472) %!s(int64=0) %!s(int64=0) %!s(int=0) map[]} usage &{%!s(int64=47000) %!s(int64=9663676416) %!s(int64=1) %!s(int64=0) %!s(int=0) map[]} share[1]&{%!s(int64=46000) %!s(int64=13754632765) %!s(int64=2) %!s(int64=0) %!s(int=0) map[]}
I0323 19:41:35.740631       1 factory.go:1068] [tanle] Next Pod user2-11
I0323 19:41:35.740859       1 generic_scheduler.go:510] demand 0: =  {%!s(float64=5392.731535756154) %!s(float64=3.221225472e+09) %!s(float64=0.23446658851113714)}
I0323 19:41:35.740898       1 generic_scheduler.go:510] demand 1: =  {%!s(float64=10772.833723653397) %!s(float64=3.221225472e+09) %!s(float64=0.468384074941452)}
I0323 19:41:35.740920       1 generic_scheduler.go:690] shares [%!s(*schedulercache.Resource=&{46000 27477053276 2 0 0 map[]}) %!s(*schedulercache.Resource=&{46000 13754632765 2 0 0 map[]})]
I0323 19:41:35.740946       1 generic_scheduler.go:591] demand.MilliCPU: 23000, currentUsage.MilliCPU 47000, share.MilliCPU 46000
I0323 19:41:35.740954       1 generic_scheduler.go:692] Rejected pod: user2-11 podDemand &{%!s(int64=23000) %!s(int64=3221225472) %!s(int64=0) %!s(int64=0) %!s(int=0) map[]} usage &{%!s(int64=47000) %!s(int64=9663676416) %!s(int64=1) %!s(int64=0) %!s(int=0) map[]} share[1]&{%!s(int64=46000) %!s(int64=13754632765) %!s(int64=2) %!s(int64=0) %!s(int=0) map[]}
I0323 19:41:36.507107       1 factory.go:1068] [tanle] Next Pod user1-9
I0323 19:41:36.507293       1 generic_scheduler.go:510] demand 0: =  {%!s(float64=5392.731535756154) %!s(float64=3.221225472e+09) %!s(float64=0.23446658851113714)}
I0323 19:41:36.507322       1 generic_scheduler.go:510] demand 1: =  {%!s(float64=10772.833723653397) %!s(float64=3.221225472e+09) %!s(float64=0.468384074941452)}
I0323 19:41:36.507333       1 generic_scheduler.go:690] shares [%!s(*schedulercache.Resource=&{46000 27477053276 2 0 0 map[]}) %!s(*schedulercache.Resource=&{46000 13754632765 2 0 0 map[]})]
I0323 19:41:36.507348       1 generic_scheduler.go:692] Rejected pod: user1-9 podDemand &{%!s(int64=1000) %!s(int64=3221225472) %!s(int64=1) %!s(int64=0) %!s(int=0) map[]} usage &{%!s(int64=25000) %!s(int64=9663676416) %!s(int64=2) %!s(int64=0) %!s(int=0) map[]} share[1]&{%!s(int64=46000) %!s(int64=13754632765) %!s(int64=2) %!s(int64=0) %!s(int=0) map[]}
I0323 19:41:40.767484       1 factory.go:1068] [tanle] Next Pod user1-9
I0323 19:41:40.767672       1 generic_scheduler.go:510] demand 0: =  {%!s(float64=5392.731535756154) %!s(float64=3.221225472e+09) %!s(float64=0.23446658851113714)}
I0323 19:41:40.767726       1 generic_scheduler.go:510] demand 1: =  {%!s(float64=10772.833723653397) %!s(float64=3.221225472e+09) %!s(float64=0.468384074941452)}
I0323 19:41:40.767753       1 generic_scheduler.go:690] shares [%!s(*schedulercache.Resource=&{46000 27477053276 2 0 0 map[]}) %!s(*schedulercache.Resource=&{46000 13754632765 2 0 0 map[]})]
I0323 19:41:40.767795       1 generic_scheduler.go:692] Rejected pod: user1-9 podDemand &{%!s(int64=1000) %!s(int64=3221225472) %!s(int64=1) %!s(int64=0) %!s(int=0) map[]} usage &{%!s(int64=25000) %!s(int64=9663676416) %!s(int64=2) %!s(int64=0) %!s(int=0) map[]} share[1]&{%!s(int64=46000) %!s(int64=13754632765) %!s(int64=2) %!s(int64=0) %!s(int=0) map[]}
I0323 19:41:46.505172       1 factory.go:1068] [tanle] Next Pod user2-14
I0323 19:41:46.505356       1 generic_scheduler.go:510] demand 0: =  {%!s(float64=5392.731535756154) %!s(float64=3.221225472e+09) %!s(float64=0.23446658851113714)}
I0323 19:41:46.505400       1 generic_scheduler.go:510] demand 1: =  {%!s(float64=10772.833723653397) %!s(float64=3.221225472e+09) %!s(float64=0.468384074941452)}
I0323 19:41:46.505421       1 generic_scheduler.go:690] shares [%!s(*schedulercache.Resource=&{46000 27477053276 2 0 0 map[]}) %!s(*schedulercache.Resource=&{46000 13754632765 2 0 0 map[]})]
I0323 19:41:46.505447       1 generic_scheduler.go:591] demand.MilliCPU: 23000, currentUsage.MilliCPU 24000, share.MilliCPU 46000
I0323 19:41:46.505456       1 generic_scheduler.go:692] Rejected pod: user2-14 podDemand &{%!s(int64=23000) %!s(int64=3221225472) %!s(int64=0) %!s(int64=0) %!s(int=0) map[]} usage &{%!s(int64=24000) %!s(int64=6442450944) %!s(int64=1) %!s(int64=0) %!s(int=0) map[]} share[1]&{%!s(int64=46000) %!s(int64=13754632765) %!s(int64=2) %!s(int64=0) %!s(int=0) map[]}
I0323 19:41:46.505601       1 factory.go:1068] [tanle] Next Pod user2-15
I0323 19:41:46.505761       1 generic_scheduler.go:510] demand 0: =  {%!s(float64=5392.731535756154) %!s(float64=3.221225472e+09) %!s(float64=0.23446658851113714)}
I0323 19:41:46.505796       1 generic_scheduler.go:510] demand 1: =  {%!s(float64=10772.833723653397) %!s(float64=3.221225472e+09) %!s(float64=0.468384074941452)}
I0323 19:41:46.505815       1 generic_scheduler.go:690] shares [%!s(*schedulercache.Resource=&{46000 27477053276 2 0 0 map[]}) %!s(*schedulercache.Resource=&{46000 13754632765 2 0 0 map[]})]
I0323 19:41:46.505836       1 generic_scheduler.go:591] demand.MilliCPU: 23000, currentUsage.MilliCPU 24000, share.MilliCPU 46000
I0323 19:41:46.505855       1 generic_scheduler.go:692] Rejected pod: user2-15 podDemand &{%!s(int64=23000) %!s(int64=3221225472) %!s(int64=0) %!s(int64=0) %!s(int=0) map[]} usage &{%!s(int64=24000) %!s(int64=6442450944) %!s(int64=1) %!s(int64=0) %!s(int=0) map[]} share[1]&{%!s(int64=46000) %!s(int64=13754632765) %!s(int64=2) %!s(int64=0) %!s(int=0) map[]}
I0323 19:41:48.769968       1 factory.go:1068] [tanle] Next Pod user1-9
I0323 19:41:48.770143       1 generic_scheduler.go:510] demand 0: =  {%!s(float64=5392.731535756154) %!s(float64=3.221225472e+09) %!s(float64=0.23446658851113714)}
I0323 19:41:48.770182       1 generic_scheduler.go:510] demand 1: =  {%!s(float64=10772.833723653397) %!s(float64=3.221225472e+09) %!s(float64=0.468384074941452)}
I0323 19:41:48.770200       1 generic_scheduler.go:690] shares [%!s(*schedulercache.Resource=&{46000 27477053276 2 0 0 map[]}) %!s(*schedulercache.Resource=&{46000 13754632765 2 0 0 map[]})]
I0323 19:41:48.770222       1 generic_scheduler.go:695] Admitted pod: user1-9 podDemand &{%!s(int64=1000) %!s(int64=3221225472) %!s(int64=1) %!s(int64=0) %!s(int=0) map[]} usage &{%!s(int64=24000) %!s(int64=6442450944) %!s(int64=1) %!s(int64=0) %!s(int=0) map[]}
I0323 19:41:52.802869       1 factory.go:1068] [tanle] Next Pod user2-17
I0323 19:41:52.803079       1 generic_scheduler.go:510] demand 0: =  {%!s(float64=5392.731535756154) %!s(float64=3.221225472e+09) %!s(float64=0.23446658851113714)}
I0323 19:41:52.803116       1 generic_scheduler.go:510] demand 1: =  {%!s(float64=10772.833723653397) %!s(float64=3.221225472e+09) %!s(float64=0.468384074941452)}
I0323 19:41:52.803130       1 generic_scheduler.go:690] shares [%!s(*schedulercache.Resource=&{46000 27477053276 2 0 0 map[]}) %!s(*schedulercache.Resource=&{46000 13754632765 2 0 0 map[]})]
I0323 19:41:52.803149       1 generic_scheduler.go:695] Admitted pod: user2-17 podDemand &{%!s(int64=1000) %!s(int64=3221225472) %!s(int64=1) %!s(int64=0) %!s(int=0) map[]} usage &{%!s(int64=24000) %!s(int64=6442450944) %!s(int64=1) %!s(int64=0) %!s(int=0) map[]}
I0323 19:41:53.509003       1 factory.go:1068] [tanle] Next Pod user2-16
I0323 19:41:53.509176       1 generic_scheduler.go:510] demand 0: =  {%!s(float64=5392.731535756154) %!s(float64=3.221225472e+09) %!s(float64=0.23446658851113714)}
I0323 19:41:53.509225       1 generic_scheduler.go:510] demand 1: =  {%!s(float64=10772.833723653397) %!s(float64=3.221225472e+09) %!s(float64=0.468384074941452)}
I0323 19:41:53.509243       1 generic_scheduler.go:690] shares [%!s(*schedulercache.Resource=&{46000 27477053276 2 0 0 map[]}) %!s(*schedulercache.Resource=&{46000 13754632765 2 0 0 map[]})]
I0323 19:41:53.509265       1 generic_scheduler.go:692] Rejected pod: user2-16 podDemand &{%!s(int64=1000) %!s(int64=3221225472) %!s(int64=1) %!s(int64=0) %!s(int=0) map[]} usage &{%!s(int64=25000) %!s(int64=9663676416) %!s(int64=2) %!s(int64=0) %!s(int=0) map[]} share[1]&{%!s(int64=46000) %!s(int64=13754632765) %!s(int64=2) %!s(int64=0) %!s(int=0) map[]}
I0323 19:41:54.020448       1 factory.go:1068] [tanle] Next Pod user2-16
I0323 19:41:54.020620       1 generic_scheduler.go:510] demand 0: =  {%!s(float64=5392.731535756154) %!s(float64=3.221225472e+09) %!s(float64=0.23446658851113714)}
I0323 19:41:54.020664       1 generic_scheduler.go:510] demand 1: =  {%!s(float64=10772.833723653397) %!s(float64=3.221225472e+09) %!s(float64=0.468384074941452)}
I0323 19:41:54.020685       1 generic_scheduler.go:690] shares [%!s(*schedulercache.Resource=&{46000 27477053276 2 0 0 map[]}) %!s(*schedulercache.Resource=&{46000 13754632765 2 0 0 map[]})]
I0323 19:41:54.020714       1 generic_scheduler.go:692] Rejected pod: user2-16 podDemand &{%!s(int64=1000) %!s(int64=3221225472) %!s(int64=1) %!s(int64=0) %!s(int=0) map[]} usage &{%!s(int64=25000) %!s(int64=9663676416) %!s(int64=2) %!s(int64=0) %!s(int=0) map[]} share[1]&{%!s(int64=46000) %!s(int64=13754632765) %!s(int64=2) %!s(int64=0) %!s(int=0) map[]}
W0323 19:41:54.020873       1 factory.go:1226] Request for pod user2/user2-16 already in flight, abandoning
I0323 19:41:54.753099       1 factory.go:1068] [tanle] Next Pod user2-16
I0323 19:41:54.753271       1 generic_scheduler.go:510] demand 0: =  {%!s(float64=5392.731535756154) %!s(float64=3.221225472e+09) %!s(float64=0.23446658851113714)}
I0323 19:41:54.753305       1 generic_scheduler.go:510] demand 1: =  {%!s(float64=10772.833723653397) %!s(float64=3.221225472e+09) %!s(float64=0.468384074941452)}
I0323 19:41:54.753322       1 generic_scheduler.go:690] shares [%!s(*schedulercache.Resource=&{46000 27477053276 2 0 0 map[]}) %!s(*schedulercache.Resource=&{46000 13754632765 2 0 0 map[]})]
I0323 19:41:54.753347       1 generic_scheduler.go:695] Admitted pod: user2-16 podDemand &{%!s(int64=1000) %!s(int64=3221225472) %!s(int64=1) %!s(int64=0) %!s(int=0) map[]} usage &{%!s(int64=24000) %!s(int64=6442450944) %!s(int64=1) %!s(int64=0) %!s(int=0) map[]}
